Workbook

Sheet Listas
A1: A | B1: Asistencia
A2: H | B2: Feriado
A3: DR | B3: D. Remunerado
A4: DNR | B4: No Remunerado
A5: F | B5: Falta
A6: N/A | B6: No Remunerado
A7: A/H | B7: Feriado laborado

Sheet Presentación
B1: Días sin planilla | F1: Días con planilla
A2: Nombre | B2: Asistido sin planilla | C2: Basico sin planilla | D2: Viaticos | E2: Total sin planilla (A) | F2: Asistidos planilla | G2: Dominical | H2: Basico mes | I2: Ingreso Quincena | J2: Asignacion familiar | K2: Horas Extras | L2: Bono asistencia | M2: Remuneración Bruta | N2: Descuento Comedor | O2: Descuento AFP | P2: Remuneración Neta (B) | Q2: Movilidad (C) | R2: Viaticos (D) | S2: Total a pagar (A+B+C+D)
A3: FARROÑAN YOVERA LUIS ALBERTO | B3: =+VLOOKUP($A$3,'Planilla Mensual'!$D:$BC,15,FALSE) -> 80 | C3: =+VLOOKUP($A$3,'Planilla Mensual'!$D:$BC,14,FALSE) -> 1300 | E3: =+(C3+D3)*B3 -> 104000 | F3: =+VLOOKUP($A$3,'Planilla Mensual'!$D:$BC,18,FALSE) -> 2 | G3: =+VLOOKUP($A$3,'Planilla Mensual'!$D:$BC,19,FALSE) -> 10 | H3: =+VLOOKUP($A$3,'Planilla Mensual'!$D:$BC,13,FALSE) -> SI | I3: =+H3/30*(G3+F3) -> #VALUE! | J3: =+VLOOKUP($A$3,'Planilla Mensual'!$D:$BC,27,FALSE) -> 476.66667 | K3: =+VLOOKUP($A$3,'Planilla Mensual'!$D:$BC,30,FALSE) -> 100 | L3: =+VLOOKUP($A$3,'Planilla Mensual'!$D:$BC,29,FALSE) -> 0 | M3: =+SUM(I3:L3) -> #VALUE! | N3: =+SUMIF('Planilla Mensual'!$D:$D,Presentación!$A$3,'Planilla Mensual'!AQ:AQ) -> 280 | O3: =+SUMIF('Planilla Mensual'!$D:$D,Presentación!$A$3,'Planilla Mensual'!AR:AR)-N3 -> 85.63505 | P3: =+M3-O3-N3 -> #VALUE! | Q3: =+VLOOKUP($A$3,'Planilla Mensual'!$D:$BC,32,FALSE) -> 753.16667 | R3: =+VLOOKUP($A$3,'Planilla Mensual'!$D:$BC,33,FALSE) -> 80 | S3: =+R3+Q3+P3+E3 -> #VALUE!
M9: =1300/206 -> 6.3106796
I10: Sueldo Bruto | J10: 2700 | M10: =+M9*1.25 -> 7.8883495
I11: AFP | J11: 190 | M11: =+M9*1.35 -> 8.5194175
I12: Alimentación | J12: =30*26 -> 780
I13: Sueldo Neto | J13: =+J10-J11-J12 -> 1730
I14: Quincena | J14: =+J13/2 -> 865
M15: =25*8 -> 200
M16: =25*30 -> 750

Sheet Planilla Mensual
M1: Periodo | S1: Sin planilla | V1: Planilla | AJ1: No remunerativo | AL1: Aportes del trabajador | AP1: Adelantos y descuentos | AU1: Aporte empleador
A2: Valor HE | B2: TIPO | C2: DNI | D2: Apellidos y nombres | E2: F. Nacimiento | F2: Puesto | G2: AFP/ONP | H2: CUSPP | I2: Banco | J2: Cuenta | K2: CCI | L2: F. Ingreso | M2: F. INICIO | N2: F.FIN | O2: Periodo | P2: Asig Familiar (SI/NO) | Q2: Basico | R2: Basico sin planilla | S2: Asistencia | T2: Descanso pagado | U2: No remunerado | V2: Dias Trab | W2: Días descanso pagado | X2: Feriado | Y2: Feriado laborado | Z2: Dias no laborados | AA2: Falta Descuento bono | AB2: TOTAL | AC2: Horas extras | AD2: Monto basico | AE2: Monto Asig | AF2: Feriado laborado | AG2: Bono asistencia | AH2: Bono Horas | AI2: Rem Bruta | AJ2: Movilidad | AK2: Viaticos | AL2: AFP (10%) | AM2: Seg. AFP (1.37%) | AN2: ONP | AO2: Renta 5ta | AP2: Otros Descuentos | AQ2: Adelantos viaticos | AR2: Total descuentos | AS2: Neto | AT2: Total No Rem | AU2: EsSalud (9%) | AV2: Total a Pagar Planilla | AX2: Extra mes | AY2: Extra pagar | AZ2: Basico Sin planilla | BA2: Viaticos sin planilla | BB2: Hora Extra | BC2: Total Trabajador | BD2: Costo Empresa
B3: PLANILLA | C3: 42878934 | D3: REQUELME BACON CESAR DAVID | E3: 31058 | F3: Operador de Maquinaria Agricola N3 | G3: SPP INTEGRA | H3: 610561CRBUO0 | I3: BCP | J3: 57016231766077 | L3: 46128 | M3: 46128 | N3: 46142 | O3: =+TEXT(M3,"mmmm")&" - "&YEAR(M3)&MONTH(M3) -> Abril - 20264 | P3: SI | Q3: 1300 | S3: 0 | T3: 0 | U3: 0 | V3: 9 | W3: 5 | X3: =+COUNTIFS('BD Asistencia'!$E:$E,"F",'BD Asistencia'!$C:$C,'Planilla Mensual'!$D3,'BD Asistencia'!$D:$D,">="&'Planilla Mensual'!M3,'BD Asistencia'!$D:$D,"<="&'Planilla Mensual'!N3) -> 0 | Y3: =+COUNTIFS('BD Asistencia'!$E:$E,"F/A",'BD Asistencia'!$C:$C,'Planilla Mensual'!$D3,'BD Asistencia'!$D:$D,">="&'Planilla Mensual'!M3,'BD Asistencia'!$D:$D,"<="&'Planilla Mensual'!N3) -> 0 | Z3: 1 | AB3: =+SUM(S3:Z3) -> 15 | AD3: =+Q3/30*SUM(V3:Y3) -> 606.66667 | AE3: =IF(P3="SI",113,0) -> 113 | AF3: =+(Q3/30*Y3)*2 -> 0 | AG3: 200 | AI3: =+SUM(AD3:AG3) -> 919.66667 | AJ3: =+V3*IF(RIGHT(F3,2)="N3",16,IF(RIGHT(F3,2)="N2",8,4)) -> 144 | AK3: =V3*30 -> 270 | AL3: =IF(G3="ONP",0,AI3*0.1) -> 91.966667 | AM3: =IF(G3="ONP",0,AI3*1.37%) -> 12.599433 | AN3: =+IF(G3="ONP",AI3*0.13,0) -> 0 | AO3: 0 | AP3: 250 | AQ3: 140 | AS3: =AI3-SUM(AL3:AQ3) -> 425.10057 | AT3: =AJ3+AK3 -> 414 | AU3: =IF(AI3*0.09<1130*0.09,1130*0.09,AI3*0.09) -> 101.7 | AV3: =AS3+AT3 -> 839.10057 | AX3: =+IF(RIGHT(F3,2)="N3",300,0) -> 300 | AY3: 150 | AZ3: =+R3*S3 -> 0 | BA3: =+S3*30 -> 0 | BC3: =+AY3+AV3+AZ3+BA3 -> 989.10057 | BD3: =AI3+AU3+AT3+AY3+AZ3+BA3 -> 1585.3667
A4: 15 | B4: PLANILLA | C4: 42878934 | D4: REQUELME BACON CESAR DAVID | E4: 31058 | F4: Operador de Maquinaria Agricola N3 | G4: SPP INTEGRA | H4: 610561CRBUO0 | I4: BCP | J4: 57016231766077 | L4: 46128 | M4: 46143 | N4: 46157 | O4: =+TEXT(M4,"mmmm")&" - "&YEAR(M4)&MONTH(M4) -> Mayo - 20265 | P4: SI | Q4: 1300 | S4: =+COUNTIFS('BD Asistencia'!$E:$E,"A",'BD Asistencia'!$C:$C,'Planilla Mensual'!$D4,'BD Asistencia'!$D:$D,"<"&'Planilla Mensual'!L4) -> 0 | T4: =+COUNTIFS('BD Asistencia'!$E:$E,"DR",'BD Asistencia'!$C:$C,'Planilla Mensual'!$D4,'BD Asistencia'!$D:$D,"<"&L4) -> 0 | U4: =+COUNTIFS('BD Asistencia'!$H:$H,"NO REMUNERADO",'BD Asistencia'!$C:$C,'Planilla Mensual'!$D4,'BD Asistencia'!$D:$D,"<"&L4) -> 0 | V4: =+COUNTIFS('BD Asistencia'!$E:$E,"A",'BD Asistencia'!$C:$C,'Planilla Mensual'!$D4,'BD Asistencia'!$D:$D,">="&'Planilla Mensual'!M4,'BD Asistencia'!$D:$D,"<="&'Planilla Mensual'!N4)-S4 -> 13 | W4: =+COUNTIFS('BD Asistencia'!$E:$E,"DR",'BD Asistencia'!$C:$C,'Planilla Mensual'!$D4,'BD Asistencia'!$D:$D,">="&'Planilla Mensual'!M4,'BD Asistencia'!$D:$D,"<="&'Planilla Mensual'!N4)-T4 -> 1 | X4: =+COUNTIFS('BD Asistencia'!$E:$E,"h",'BD Asistencia'!$C:$C,'Planilla Mensual'!$D4,'BD Asistencia'!$D:$D,">="&'Planilla Mensual'!M4,'BD Asistencia'!$D:$D,"<="&'Planilla Mensual'!N4) -> 1 | Y4: =+COUNTIFS('BD Asistencia'!$E:$E,"h/A",'BD Asistencia'!$C:$C,'Planilla Mensual'!$D4,'BD Asistencia'!$D:$D,">="&'Planilla Mensual'!M4,'BD Asistencia'!$D:$D,"<="&'Planilla Mensual'!N4) -> 0 | Z4: =+COUNTIFS('BD Asistencia'!$H:$H,"NO REMUNERADO",'BD Asistencia'!$C:$C,'Planilla Mensual'!$D4,'BD Asistencia'!$D:$D,">="&'Planilla Mensual'!M4,'BD Asistencia'!$D:$D,"<="&'Planilla Mensual'!N4)-U4 -> 0 | AA4: =+COUNTIFS('BD Asistencia'!$E:$E,"F",'BD Asistencia'!$C:$C,'Planilla Mensual'!$D4,'BD Asistencia'!$D:$D,">="&'Planilla Mensual'!M4,'BD Asistencia'!$D:$D,"<="&'Planilla Mensual'!N4) -> 0 | AB4: =+SUM(S4:AA4) -> 15 | AC4: 6 | AD4: =+Q4/30*SUM(V4:Y4) -> 650 | AE4: =IF(P4="SI",113/2,0) -> 56.5 | AF4: =+(Q4/30*Y4)*2 -> 0 | AG4: 200 | AH4: =+AC4*A4 -> 90 | AI4: =+SUM(AD4:AH4) -> 996.5 | AJ4: =+V4*IF(RIGHT(F4,2)="N3",16,IF(RIGHT(F4,2)="N2",8,4)) -> 208 | AK4: =V4*30 -> 390 | AL4: =IF(G4="ONP",0,AI4*0.1) -> 99.65 | AM4: =IF(G4="ONP",0,AI4*1.37%) -> 13.65205 | AN4: =+IF(G4="ONP",AI4*0.13,0) -> 0 | AO4: 0 | AP4: 250 | AQ4: 0 | AR4: =+SUM(AL4:AQ4) -> 363.30205 | AS4: =AI4-SUM(AL4:AQ4) -> 633.19795 | AT4: =AJ4+AK4 -> 598 | AV4: =AS4+AT4 -> 1231.1979 | AX4: =+IF(RIGHT(F4,2)="N3",300,0) -> 300 | AY4: =+AX4/30*SUM(V4:Y4) -> 150 | AZ4: =+R4*S4 -> 0 | BA4: =+S4*30 -> 0 | BC4: =+AY4+AV4+AZ4+BA4+BB4 -> 1381.1979 | BD4: =AI4+AU4+AT4+AY4+AZ4+BA4+BB4 -> 1744.5 | BE4: =(BC4+AQ4)/(V4+S4) -> 106.246 | BF4: =+BE4*26 -> 2762.3959 | BG4: =(AV4+AY4+SUM(AL4:AQ4))/(V4+W4) -> 124.60714 | BH4: =+(AZ4+BA4)/(S4+T4) -> #DIV/0! | BI4: =+BD4/V4 -> 134.19231 | BJ4: =180*2 -> 360 | BK4: =+BC4-BJ4 -> 1021.1979
A5: 15 | B5: PLANILLA | C5: 70751973 | D5: CONCEPCIÓN ZEVALLOS ARMANDO | E5: 34913 | F5: Operador de Maquinaria Agricola N3 | G5: ONP | I5: BCP | J5: 57071021755000 | L5: 46146 | M5: 46143 | N5: 46157 | O5: =+TEXT(M5,"mmmm")&" - "&YEAR(M5)&MONTH(M5) -> Mayo - 20265 | P5: SI | Q5: 1300 | R5: 110 | S5: =+COUNTIFS('BD Asistencia'!$E:$E,"A",'BD Asistencia'!$C:$C,'Planilla Mensual'!$D5,'BD Asistencia'!$D:$D,"<"&'Planilla Mensual'!L5) -> 2 | T5: =+COUNTIFS('BD Asistencia'!$E:$E,"DR",'BD Asistencia'!$C:$C,'Planilla Mensual'!$D5,'BD Asistencia'!$D:$D,"<"&L5) -> 0 | U5: =+COUNTIFS('BD Asistencia'!$H:$H,"NO REMUNERADO",'BD Asistencia'!$C:$C,'Planilla Mensual'!$D5,'BD Asistencia'!$D:$D,"<"&L5) -> 1 | V5: =+COUNTIFS('BD Asistencia'!$E:$E,"A",'BD Asistencia'!$C:$C,'Planilla Mensual'!$D5,'BD Asistencia'!$D:$D,">="&'Planilla Mensual'!M5,'BD Asistencia'!$D:$D,"<="&'Planilla Mensual'!N5)-S5 -> 11 | W5: =+COUNTIFS('BD Asistencia'!$E:$E,"DR",'BD Asistencia'!$C:$C,'Planilla Mensual'!$D5,'BD Asistencia'!$D:$D,">="&'Planilla Mensual'!M5,'BD Asistencia'!$D:$D,"<="&'Planilla Mensual'!N5)-T5 -> 1 | X5: =+COUNTIFS('BD Asistencia'!$E:$E,"h",'BD Asistencia'!$C:$C,'Planilla Mensual'!$D5,'BD Asistencia'!$D:$D,">="&'Planilla Mensual'!M5,'BD Asistencia'!$D:$D,"<="&'Planilla Mensual'!N5) -> 0 | Y5: =+COUNTIFS('BD Asistencia'!$E:$E,"h/A",'BD Asistencia'!$C:$C,'Planilla Mensual'!$D5,'BD Asistencia'!$D:$D,">="&'Planilla Mensual'!M5,'BD Asistencia'!$D:$D,"<="&'Planilla Mensual'!N5) -> 0 | Z5: =+COUNTIFS('BD Asistencia'!$H:$H,"NO REMUNERADO",'BD Asistencia'!$C:$C,'Planilla Mensual'!$D5,'BD Asistencia'!$D:$D,">="&'Planilla Mensual'!M5,'BD Asistencia'!$D:$D,"<="&'Planilla Mensual'!N5)-U5 -> 0 | AA5: =+COUNTIFS('BD Asistencia'!$E:$E,"F",'BD Asistencia'!$C:$C,'Planilla Mensual'!$D5,'BD Asistencia'!$D:$D,">="&'Planilla Mensual'!M5,'BD Asistencia'!$D:$D,"<="&'Planilla Mensual'!N5) -> 0 | AB5: =+SUM(S5:AA5) -> 15 | AC5: 0.8 | AD5: =+Q5/30*SUM(V5:Y5) -> 520 | AE5: =IF(P5="SI",113/2,0) -> 56.5 | AF5: =+(Q5/30*Y5)*2 -> 0 | AG5: 200 | AH5: =+AC5*A5 -> 12 | AI5: =+SUM(AD5:AH5) -> 788.5 | AJ5: =+V5*IF(RIGHT(F5,2)="N3",16,IF(RIGHT(F5,2)="N2",8,4)) -> 176 | AK5: =V5*30 -> 330 | AL5: =IF(G5="ONP",0,AI5*0.1) -> 0 | AM5: =IF(G5="ONP",0,AI5*1.37%) -> 0 | AN5: =+IF(G5="ONP",AI5*0.13,0) -> 102.505 | AO5: 0 | AQ5: 0 | AR5: =+SUM(AL5:AQ5) -> 102.505 | AS5: =AI5-SUM(AL5:AQ5) -> 685.995 | AT5: =AJ5+AK5 -> 506 | AV5: =AS5+AT5 -> 1191.995 | AX5: =+IF(RIGHT(F5,2)="N3",300,0) -> 300 | AY5: =+AX5/30*SUM(V5:Y5) -> 120 | AZ5: =+R5*S5 -> 220 | BA5: =+S5*30 -> 60 | BC5: =+AY5+AV5+AZ5+BA5+BB5 -> 1591.995 | BD5: =AI5+AU5+AT5+AY5+AZ5+BA5+BB5 -> 1694.5 | BE5: =(BC5+AQ5)/(V5+S5) -> 122.46115 | BF5: =+BE5*26 -> 3183.99 | BG5: =(AV5+AY5+SUM(AL5:AQ5))/V5 -> 128.59091 | BH5: =+(AZ5+BA5)/(S5+T5) -> 140 | BI5: =+BD5/V5 -> 154.04545 | BJ5: =180*2 -> 360 | BK5: =+BC5-BJ5 -> 1231.995
A6: 15 | B6: PLANILLA | C6: 75792147 | D6: TERRONES JARA FREDY | E6: 38228 | F6: Operador de Maquinaria Agricola N3 | G6: SPP INTEGRA | H6: 682261FTJRA0 | I6: BCP | J6: 57098711252088 | L6: 46146 | M6: 46143 | N6: 46157 | O6: =+TEXT(M6,"mmmm")&" - "&YEAR(M6)&MONTH(M6) -> Mayo - 20265 | P6: NO | Q6: 1300 | R6: 120 | S6: =+COUNTIFS('BD Asistencia'!$E:$E,"A",'BD Asistencia'!$C:$C,'Planilla Mensual'!$D6,'BD Asistencia'!$D:$D,"<"&'Planilla Mensual'!L6) -> 1 | T6: =+COUNTIFS('BD Asistencia'!$E:$E,"DR",'BD Asistencia'!$C:$C,'Planilla Mensual'!$D6,'BD Asistencia'!$D:$D,"<"&L6) -> 0 | U6: =+COUNTIFS('BD Asistencia'!$H:$H,"NO REMUNERADO",'BD Asistencia'!$C:$C,'Planilla Mensual'!$D6,'BD Asistencia'!$D:$D,"<"&L6) -> 2 | V6: 11 | W6: =+COUNTIFS('BD Asistencia'!$E:$E,"DR",'BD Asistencia'!$C:$C,'Planilla Mensual'!$D6,'BD Asistencia'!$D:$D,">="&'Planilla Mensual'!M6,'BD Asistencia'!$D:$D,"<="&'Planilla Mensual'!N6)-T6 -> 1 | X6: =+COUNTIFS('BD Asistencia'!$E:$E,"h",'BD Asistencia'!$C:$C,'Planilla Mensual'!$D6,'BD Asistencia'!$D:$D,">="&'Planilla Mensual'!M6,'BD Asistencia'!$D:$D,"<="&'Planilla Mensual'!N6) -> 0 | Y6: =+COUNTIFS('BD Asistencia'!$E:$E,"h/A",'BD Asistencia'!$C:$C,'Planilla Mensual'!$D6,'BD Asistencia'!$D:$D,">="&'Planilla Mensual'!M6,'BD Asistencia'!$D:$D,"<="&'Planilla Mensual'!N6) -> 0 | Z6: =+COUNTIFS('BD Asistencia'!$H:$H,"NO REMUNERADO",'BD Asistencia'!$C:$C,'Planilla Mensual'!$D6,'BD Asistencia'!$D:$D,">="&'Planilla Mensual'!M6,'BD Asistencia'!$D:$D,"<="&'Planilla Mensual'!N6)-U6 -> 0 | AA6: =+COUNTIFS('BD Asistencia'!$E:$E,"F",'BD Asistencia'!$C:$C,'Planilla Mensual'!$D6,'BD Asistencia'!$D:$D,">="&'Planilla Mensual'!M6,'BD Asistencia'!$D:$D,"<="&'Planilla Mensual'!N6) -> 0 | AB6: =+SUM(S6:AA6) -> 15 | AC6: 6.3 | AD6: =+Q6/30*SUM(V6:Y6) -> 520 | AE6: =IF(P6="SI",113/2,0) -> 0 | AF6: =+(Q6/30*Y6)*2 -> 0 | AG6: 200 | AH6: =+AC6*A6 -> 94.5 | AI6: =+SUM(AD6:AH6) -> 814.5 | AJ6: =+V6*IF(RIGHT(F6,2)="N3",16,IF(RIGHT(F6,2)="N2",8,4)) -> 176 | AK6: =V6*30 -> 330 | AL6: =IF(G6="ONP",0,AI6*0.1) -> 81.45 | AM6: =IF(G6="ONP",0,AI6*1.37%) -> 11.15865 | AN6: =+IF(G6="ONP",AI6*0.13,0) -> 0 | AO6: 0 | AQ6: 0 | AR6: =+SUM(AL6:AQ6) -> 92.60865 | AS6: =AI6-SUM(AL6:AQ6) -> 721.89135 | AT6: =AJ6+AK6 -> 506 | AV6: =AS6+AT6 -> 1227.8913 | AX6: =+IF(RIGHT(F6,2)="N3",300,0) -> 300 | AY6: =+AX6/30*SUM(V6:Y6) -> 120 | AZ6: =+R6*S6 -> 120 | BA6: =+S6*30 -> 30 | BC6: =+AY6+AV6+AZ6+BA6+BB6 -> 1497.8913 | BD6: =AI6+AU6+AT6+AY6+AZ6+BA6+BB6 -> 1590.5 | BE6: =(BC6+AQ6)/(V6+S6) -> 124.82428 | BF6: =+BE6*26 -> 3245.4313 | BG6: =(AV6+AY6+SUM(AL6:AQ6))/V6 -> 130.95455 | BH6: =+(AZ6+BA6)/(S6+T6) -> 150 | BI6: =+BD6/V6 -> 144.59091 | BJ6: =180*2 -> 360 | BK6: =+BC6-BJ6 -> 1137.8913
A7: 15 | B7: PLANILLA | C7: 74242456 | D7: MONTOYA NAMOC JORGE LUIS | E7: 37386 | F7: Operador de Maquinaria Agricola N3 | G7: SPP INTEGRA | H7: 673841JMNTO4 | I7: BCP | J7: 57016070300081 | L7: 46146 | M7: 46143 | N7: 46157 | O7: =+TEXT(M7,"mmmm")&" - "&YEAR(M7)&MONTH(M7) -> Mayo - 20265 | P7: NO | Q7: 1300 | R7: 110 | S7: =+COUNTIFS('BD Asistencia'!$E:$E,"A",'BD Asistencia'!$C:$C,'Planilla Mensual'!$D7,'BD Asistencia'!$D:$D,"<"&'Planilla Mensual'!L7) -> 2 | T7: =+COUNTIFS('BD Asistencia'!$E:$E,"DR",'BD Asistencia'!$C:$C,'Planilla Mensual'!$D7,'BD Asistencia'!$D:$D,"<"&L7) -> 0 | U7: =+COUNTIFS('BD Asistencia'!$H:$H,"NO REMUNERADO",'BD Asistencia'!$C:$C,'Planilla Mensual'!$D7,'BD Asistencia'!$D:$D,"<"&L7) -> 1 | V7: =+COUNTIFS('BD Asistencia'!$E:$E,"A",'BD Asistencia'!$C:$C,'Planilla Mensual'!$D7,'BD Asistencia'!$D:$D,">="&'Planilla Mensual'!M7,'BD Asistencia'!$D:$D,"<="&'Planilla Mensual'!N7)-S7 -> 11 | W7: =+COUNTIFS('BD Asistencia'!$E:$E,"DR",'BD Asistencia'!$C:$C,'Planilla Mensual'!$D7,'BD Asistencia'!$D:$D,">="&'Planilla Mensual'!M7,'BD Asistencia'!$D:$D,"<="&'Planilla Mensual'!N7)-T7 -> 1 | X7: =+COUNTIFS('BD Asistencia'!$E:$E,"h",'BD Asistencia'!$C:$C,'Planilla Mensual'!$D7,'BD Asistencia'!$D:$D,">="&'Planilla Mensual'!M7,'BD Asistencia'!$D:$D,"<="&'Planilla Mensual'!N7) -> 0 | Y7: =+COUNTIFS('BD Asistencia'!$E:$E,"h/A",'BD Asistencia'!$C:$C,'Planilla Mensual'!$D7,'BD Asistencia'!$D:$D,">="&'Planilla Mensual'!M7,'BD Asistencia'!$D:$D,"<="&'Planilla Mensual'!N7) -> 0 | Z7: =+COUNTIFS('BD Asistencia'!$H:$H,"NO REMUNERADO",'BD Asistencia'!$C:$C,'Planilla Mensual'!$D7,'BD Asistencia'!$D:$D,">="&'Planilla Mensual'!M7,'BD Asistencia'!$D:$D,"<="&'Planilla Mensual'!N7)-U7 -> 0 | AA7: =+COUNTIFS('BD Asistencia'!$E:$E,"F",'BD Asistencia'!$C:$C,'Planilla Mensual'!$D7,'BD Asistencia'!$D:$D,">="&'Planilla Mensual'!M7,'BD Asistencia'!$D:$D,"<="&'Planilla Mensual'!N7) -> 0 | AB7: =+SUM(S7:AA7) -> 15 | AC7: 0.8 | AD7: =+Q7/30*SUM(V7:Y7) -> 520 | AE7: =IF(P7="SI",113/2,0) -> 0 | AF7: =+(Q7/30*Y7)*2 -> 0 | AG7: 200 | AH7: =+AC7*A7 -> 12 | AI7: =+SUM(AD7:AH7) -> 732 | AJ7: =+V7*IF(RIGHT(F7,2)="N3",16,IF(RIGHT(F7,2)="N2",8,4)) -> 176 | AK7: =V7*30 -> 330 | AL7: =IF(G7="ONP",0,AI7*0.1) -> 73.2 | AM7: =IF(G7="ONP",0,AI7*1.37%) -> 10.0284 | AN7: =+IF(G7="ONP",AI7*0.13,0) -> 0 | AO7: 0 | AQ7: 0 | AR7: =+SUM(AL7:AQ7) -> 83.2284 | AS7: =AI7-SUM(AL7:AQ7) -> 648.7716 | AT7: =AJ7+AK7 -> 506 | AV7: =AS7+AT7 -> 1154.7716 | AX7: =+IF(RIGHT(F7,2)="N3",300,0) -> 300 | AY7: =+AX7/30*SUM(V7:Y7) -> 120 | AZ7: =+R7*S7 -> 220 | BA7: =+S7*30 -> 60 | BC7: =+AY7+AV7+AZ7+BA7+BB7 -> 1554.7716 | BD7: =AI7+AU7+AT7+AY7+AZ7+BA7+BB7 -> 1638 | BE7: =(BC7+AQ7)/(V7+S7) -> 119.59782 | BF7: =+BE7*26 -> 3109.5432 | BG7: =(AV7+AY7+SUM(AL7:AQ7))/V7 -> 123.45455 | BH7: =+(AZ7+BA7)/(S7+T7) -> 140 | BI7: =+BD7/V7 -> 148.90909 | BJ7: =180*2 -> 360 | BK7: =+BC7-BJ7 -> 1194.7716
A8: 15 | B8: PLANILLA | C8: 48787545 | D8: DIAZ DIAZ JUNNIOR | E8: 34609 | F8: Operador de Maquinaria Agricola N3 | G8: SPP PRIMA | H8: 646071JDDZZ4 | I8: BCP | J8: 30071590047060 | L8: 46146 | M8: 46143 | N8: 46157 | O8: =+TEXT(M8,"mmmm")&" - "&YEAR(M8)&MONTH(M8) -> Mayo - 20265 | P8: SI | Q8: 1300 | R8: 100 | S8: =+COUNTIFS('BD Asistencia'!$E:$E,"A",'BD Asistencia'!$C:$C,'Planilla Mensual'!$D8,'BD Asistencia'!$D:$D,"<"&'Planilla Mensual'!L8) -> 1 | T8: =+COUNTIFS('BD Asistencia'!$E:$E,"DR",'BD Asistencia'!$C:$C,'Planilla Mensual'!$D8,'BD Asistencia'!$D:$D,"<"&L8) -> 0 | U8: =+COUNTIFS('BD Asistencia'!$H:$H,"NO REMUNERADO",'BD Asistencia'!$C:$C,'Planilla Mensual'!$D8,'BD Asistencia'!$D:$D,"<"&L8) -> 2 | V8: 11 | W8: =+COUNTIFS('BD Asistencia'!$E:$E,"DR",'BD Asistencia'!$C:$C,'Planilla Mensual'!$D8,'BD Asistencia'!$D:$D,">="&'Planilla Mensual'!M8,'BD Asistencia'!$D:$D,"<="&'Planilla Mensual'!N8)-T8 -> 1 | X8: =+COUNTIFS('BD Asistencia'!$E:$E,"h",'BD Asistencia'!$C:$C,'Planilla Mensual'!$D8,'BD Asistencia'!$D:$D,">="&'Planilla Mensual'!M8,'BD Asistencia'!$D:$D,"<="&'Planilla Mensual'!N8) -> 0 | Y8: =+COUNTIFS('BD Asistencia'!$E:$E,"h/A",'BD Asistencia'!$C:$C,'Planilla Mensual'!$D8,'BD Asistencia'!$D:$D,">="&'Planilla Mensual'!M8,'BD Asistencia'!$D:$D,"<="&'Planilla Mensual'!N8) -> 0 | Z8: =+COUNTIFS('BD Asistencia'!$H:$H,"NO REMUNERADO",'BD Asistencia'!$C:$C,'Planilla Mensual'!$D8,'BD Asistencia'!$D:$D,">="&'Planilla Mensual'!M8,'BD Asistencia'!$D:$D,"<="&'Planilla Mensual'!N8)-U8 -> 0 | AA8: =+COUNTIFS('BD Asistencia'!$E:$E,"F",'BD Asistencia'!$C:$C,'Planilla Mensual'!$D8,'BD Asistencia'!$D:$D,">="&'Planilla Mensual'!M8,'BD Asistencia'!$D:$D,"<="&'Planilla Mensual'!N8) -> 0 | AB8: =+SUM(S8:AA8) -> 15 | AC8: 4.5 | AD8: =+Q8/30*SUM(V8:Y8) -> 520 | AE8: =IF(P8="SI",113/2,0) -> 56.5 | AF8: =+(Q8/30*Y8)*2 -> 0 | AG8: 200 | AH8: =+AC8*A8 -> 67.5 | AI8: =+SUM(AD8:AH8) -> 844 | AJ8: =+V8*IF(RIGHT(F8,2)="N3",16,IF(RIGHT(F8,2)="N2",8,4)) -> 176 | AK8: =V8*30 -> 330 | AL8: =IF(G8="ONP",0,AI8*0.1) -> 84.4 | AM8: =IF(G8="ONP",0,AI8*1.37%) -> 11.5628 | AN8: =+IF(G8="ONP",AI8*0.13,0) -> 0 | AO8: 0 | AQ8: 0 | AR8: =+SUM(AL8:AQ8) -> 95.9628 | AS8: =AI8-SUM(AL8:AQ8) -> 748.0372 | AT8: =AJ8+AK8 -> 506 | AV8: =AS8+AT8 -> 1254.0372 | AX8: =+IF(RIGHT(F8,2)="N3",300,0) -> 300 | AY8: =+AX8/30*SUM(V8:Y8) -> 120 | AZ8: =+R8*S8 -> 100 | BA8: =+S8*30 -> 30 | BC8: =+AY8+AV8+AZ8+BA8+BB8 -> 1504.0372 | BD8: =AI8+AU8+AT8+AY8+AZ8+BA8+BB8 -> 1600 | BE8: =(BC8+AQ8)/(V8+S8) -> 125.33643 | BF8: =+BE8*26 -> 3258.7473 | BG8: =(AV8+AY8+SUM(AL8:AQ8))/V8 -> 133.63636 | BH8: =+(AZ8+BA8)/(S8+T8) -> 130 | BI8: =+BD8/V8 -> 145.45455 | BJ8: =180*2 -> 360 | BK8: =+BC8-BJ8 -> 1144.0372
A9: 15 | B9: PLANILLA | C9: 73814026 | D9: SIFUENTES PAREDES EDUARDO JAVIER | E9: 36718 | F9: Operador de Maquinaria Agricola N1 | G9: SPP INTEGRA | H9: 667161ESPUE1 | I9: BCP | J9: 19277856288012 | L9: 46146 | M9: 46143 | N9: 46157 | O9: =+TEXT(M9,"mmmm")&" - "&YEAR(M9)&MONTH(M9) -> Mayo - 20265 | P9: SI | Q9: 1200 | R9: 80 | S9: =+COUNTIFS('BD Asistencia'!$E:$E,"A",'BD Asistencia'!$C:$C,'Planilla Mensual'!$D9,'BD Asistencia'!$D:$D,"<"&'Planilla Mensual'!L9) -> 2 | T9: =+COUNTIFS('BD Asistencia'!$E:$E,"DR",'BD Asistencia'!$C:$C,'Planilla Mensual'!$D9,'BD Asistencia'!$D:$D,"<"&L9) -> 0 | U9: =+COUNTIFS('BD Asistencia'!$H:$H,"NO REMUNERADO",'BD Asistencia'!$C:$C,'Planilla Mensual'!$D9,'BD Asistencia'!$D:$D,"<"&L9) -> 1 | V9: =+COUNTIFS('BD Asistencia'!$E:$E,"A",'BD Asistencia'!$C:$C,'Planilla Mensual'!$D9,'BD Asistencia'!$D:$D,">="&'Planilla Mensual'!M9,'BD Asistencia'!$D:$D,"<="&'Planilla Mensual'!N9)-S9 -> 11 | W9: =+COUNTIFS('BD Asistencia'!$E:$E,"DR",'BD Asistencia'!$C:$C,'Planilla Mensual'!$D9,'BD Asistencia'!$D:$D,">="&'Planilla Mensual'!M9,'BD Asistencia'!$D:$D,"<="&'Planilla Mensual'!N9)-T9 -> 1 | X9: =+COUNTIFS('BD Asistencia'!$E:$E,"h",'BD Asistencia'!$C:$C,'Planilla Mensual'!$D9,'BD Asistencia'!$D:$D,">="&'Planilla Mensual'!M9,'BD Asistencia'!$D:$D,"<="&'Planilla Mensual'!N9) -> 0 | Y9: =+COUNTIFS('BD Asistencia'!$E:$E,"h/A",'BD Asistencia'!$C:$C,'Planilla Mensual'!$D9,'BD Asistencia'!$D:$D,">="&'Planilla Mensual'!M9,'BD Asistencia'!$D:$D,"<="&'Planilla Mensual'!N9) -> 0 | Z9: =+COUNTIFS('BD Asistencia'!$H:$H,"NO REMUNERADO",'BD Asistencia'!$C:$C,'Planilla Mensual'!$D9,'BD Asistencia'!$D:$D,">="&'Planilla Mensual'!M9,'BD Asistencia'!$D:$D,"<="&'Planilla Mensual'!N9)-U9 -> 0 | AA9: =+COUNTIFS('BD Asistencia'!$E:$E,"F",'BD Asistencia'!$C:$C,'Planilla Mensual'!$D9,'BD Asistencia'!$D:$D,">="&'Planilla Mensual'!M9,'BD Asistencia'!$D:$D,"<="&'Planilla Mensual'!N9) -> 0 | AB9: =+SUM(S9:AA9) -> 15 | AD9: =+Q9/30*SUM(V9:Y9) -> 480 | AE9: =IF(P9="SI",113/2,0) -> 56.5 | AF9: =+(Q9/30*Y9)*2 -> 0 | AG9: 200 | AH9: =+AC9*A9 -> 0 | AI9: =+SUM(AD9:AH9) -> 736.5 | AJ9: =+V9*IF(RIGHT(F9,2)="N3",16,IF(RIGHT(F9,2)="N2",8,4)) -> 44 | AK9: =V9*30 -> 330 | AL9: =IF(G9="ONP",0,AI9*0.1) -> 73.65 | AM9: =IF(G9="ONP",0,AI9*1.37%) -> 10.09005 | AN9: =+IF(G9="ONP",AI9*0.13,0) -> 0 | AO9: 0 | AQ9: 0 | AR9: =+SUM(AL9:AQ9) -> 83.74005 | AS9: =AI9-SUM(AL9:AQ9) -> 652.75995 | AT9: =AJ9+AK9 -> 374 | AV9: =AS9+AT9 -> 1026.76 | AX9: =+IF(RIGHT(F9,2)="N3",300,0) -> 0 | AY9: =+AX9/30*SUM(V9:Y9) -> 0 | AZ9: =+R9*(S9+T9) -> 160 | BA9: =+S9*30 -> 60 | BC9: =+AY9+AV9+AZ9+BA9+BB9 -> 1246.76 | BD9: =AI9+AU9+AT9+AY9+AZ9+BA9+BB9 -> 1330.5 | BE9: =(BC9+AQ9)/(V9+S9) -> 95.904612 | BF9: =+BE9*26 -> 2493.5199 | BG9: =(AV9+AY9+SUM(AL9:AQ9))/V9 -> 100.95455 | BH9: =+(AZ9+BA9)/(S9+T9) -> 110 | BI9: =+BD9/V9 -> 120.95455 | BJ9: =180*2 -> 360 | BK9: =+BC9-BJ9 -> 886.75995
A10: 15 | B10: PLANILLA | C10: 80780158 | D10: TERRONES JARA LEYDER | E10: 39304 | F10: Operador de Maquinaria Agricola N1 | G10: ONP | I10: BCP | J10: 45016550233040 | L10: 46146 | M10: 46143 | N10: 46157 | O10: =+TEXT(M10,"mmmm")&" - "&YEAR(M10)&MONTH(M10) -> Mayo - 20265 | P10: NO | Q10: 1200 | R10: 80 | S10: =+COUNTIFS('BD Asistencia'!$E:$E,"A",'BD Asistencia'!$C:$C,'Planilla Mensual'!$D10,'BD Asistencia'!$D:$D,"<"&'Planilla Mensual'!L10) -> 1 | T10: =+COUNTIFS('BD Asistencia'!$E:$E,"DR",'BD Asistencia'!$C:$C,'Planilla Mensual'!$D10,'BD Asistencia'!$D:$D,"<"&L10) -> 0 | U10: =+COUNTIFS('BD Asistencia'!$H:$H,"NO REMUNERADO",'BD Asistencia'!$C:$C,'Planilla Mensual'!$D10,'BD Asistencia'!$D:$D,"<"&L10) -> 2 | V10: 11 | W10: =+COUNTIFS('BD Asistencia'!$E:$E,"DR",'BD Asistencia'!$C:$C,'Planilla Mensual'!$D10,'BD Asistencia'!$D:$D,">="&'Planilla Mensual'!M10,'BD Asistencia'!$D:$D,"<="&'Planilla Mensual'!N10)-T10 -> 1 | X10: =+COUNTIFS('BD Asistencia'!$E:$E,"h",'BD Asistencia'!$C:$C,'Planilla Mensual'!$D10,'BD Asistencia'!$D:$D,">="&'Planilla Mensual'!M10,'BD Asistencia'!$D:$D,"<="&'Planilla Mensual'!N10) -> 0 | Y10: =+COUNTIFS('BD Asistencia'!$E:$E,"h/A",'BD Asistencia'!$C:$C,'Planilla Mensual'!$D10,'BD Asistencia'!$D:$D,">="&'Planilla Mensual'!M10,'BD Asistencia'!$D:$D,"<="&'Planilla Mensual'!N10) -> 0 | Z10: =+COUNTIFS('BD Asistencia'!$H:$H,"NO REMUNERADO",'BD Asistencia'!$C:$C,'Planilla Mensual'!$D10,'BD Asistencia'!$D:$D,">="&'Planilla Mensual'!M10,'BD Asistencia'!$D:$D,"<="&'Planilla Mensual'!N10)-U10 -> 0 | AA10: =+COUNTIFS('BD Asistencia'!$E:$E,"F",'BD Asistencia'!$C:$C,'Planilla Mensual'!$D10,'BD Asistencia'!$D:$D,">="&'Planilla Mensual'!M10,'BD Asistencia'!$D:$D,"<="&'Planilla Mensual'!N10) -> 0 | AB10: =+SUM(S10:AA10) -> 15 | AD10: =+Q10/30*SUM(V10:Y10) -> 480 | AE10: =IF(P10="SI",113/2,0) -> 0 | AF10: =+(Q10/30*Y10)*2 -> 0 | AG10: 200 | AH10: =+AC10*A10 -> 0 | AI10: =+SUM(AD10:AH10) -> 680 | AJ10: =+V10*IF(RIGHT(F10,2)="N3",16,IF(RIGHT(F10,2)="N2",8,4)) -> 44 | AK10: =V10*30 -> 330 | AL10: =IF(G10="ONP",0,AI10*0.1) -> 0 | AM10: =IF(G10="ONP",0,AI10*1.37%) -> 0 | AN10: =+IF(G10="ONP",AI10*0.13,0) -> 88.4 | AO10: 0 | AP10: 75 | AQ10: 0 | AR10: =+SUM(AL10:AQ10) -> 163.4 | AS10: =AI10-SUM(AL10:AQ10) -> 516.6 | AT10: =AJ10+AK10 -> 374 | AV10: =AS10+AT10 -> 890.6 | AX10: =+IF(RIGHT(F10,2)="N3",300,0) -> 0 | AY10: =+AX10/30*SUM(V10:Y10) -> 0 | AZ10: =+R10*(S10+T10) -> 80 | BA10: =+S10*30 -> 30 | BC10: =+AY10+AV10+AZ10+BA10+BB10 -> 1000.6 | BD10: =AI10+AU10+AT10+AY10+AZ10+BA10+BB10 -> 1164 | BE10: =(BC10+AQ10)/(V10+S10) -> 83.383333 | BF10: =+BE10*26 -> 2167.9667 | BG10: =(AV10+AY10+SUM(AL10:AQ10))/V10 -> 95.818182 | BH10: =+(AZ10+BA10)/(S10+T10) -> 110 | BI10: =+BD10/V10 -> 105.81818 | BJ10: =180*2 -> 360 | BK10: =+BC10-BJ10 -> 640.6
A11: 10 | B11: PLANILLA | C11: 73322149 | D11: CALLE HUAMAN LEODAN JOEL | E11: 35920 | F11: Operador de Maquinaria Agricola N3 | G11: SPP PRIMA | H11: 659181LCHLM9 | I11: SCOTIABANK | J11: 8330769627 | K11: 00972420833076962762 | L11: 46146 | M11: 46143 | N11: 46157 | O11: =+TEXT(M11,"mmmm")&" - "&YEAR(M11)&MONTH(M11) -> Mayo - 20265 | P11: SI | Q11: 1300 | R11: 100 | S11: =+COUNTIFS('BD Asistencia'!$E:$E,"A",'BD Asistencia'!$C:$C,'Planilla Mensual'!$D11,'BD Asistencia'!$D:$D,"<"&'Planilla Mensual'!L11) -> 1 | T11: =+COUNTIFS('BD Asistencia'!$E:$E,"DR",'BD Asistencia'!$C:$C,'Planilla Mensual'!$D11,'BD Asistencia'!$D:$D,"<"&L11) -> 0 | U11: =+COUNTIFS('BD Asistencia'!$H:$H,"NO REMUNERADO",'BD Asistencia'!$C:$C,'Planilla Mensual'!$D11,'BD Asistencia'!$D:$D,"<"&L11) -> 2 | V11: =+COUNTIFS('BD Asistencia'!$E:$E,"A",'BD Asistencia'!$C:$C,'Planilla Mensual'!$D11,'BD Asistencia'!$D:$D,">="&'Planilla Mensual'!M11,'BD Asistencia'!$D:$D,"<="&'Planilla Mensual'!N11)-S11 -> 11 | W11: =+COUNTIFS('BD Asistencia'!$E:$E,"DR",'BD Asistencia'!$C:$C,'Planilla Mensual'!$D11,'BD Asistencia'!$D:$D,">="&'Planilla Mensual'!M11,'BD Asistencia'!$D:$D,"<="&'Planilla Mensual'!N11)-T11 -> 1 | X11: =+COUNTIFS('BD Asistencia'!$E:$E,"h",'BD Asistencia'!$C:$C,'Planilla Mensual'!$D11,'BD Asistencia'!$D:$D,">="&'Planilla Mensual'!M11,'BD Asistencia'!$D:$D,"<="&'Planilla Mensual'!N11) -> 0 | Y11: =+COUNTIFS('BD Asistencia'!$E:$E,"h/A",'BD Asistencia'!$C:$C,'Planilla Mensual'!$D11,'BD Asistencia'!$D:$D,">="&'Planilla Mensual'!M11,'BD Asistencia'!$D:$D,"<="&'Planilla Mensual'!N11) -> 0 | Z11: =+COUNTIFS('BD Asistencia'!$H:$H,"NO REMUNERADO",'BD Asistencia'!$C:$C,'Planilla Mensual'!$D11,'BD Asistencia'!$D:$D,">="&'Planilla Mensual'!M11,'BD Asistencia'!$D:$D,"<="&'Planilla Mensual'!N11)-U11 -> 0 | AA11: =+COUNTIFS('BD Asistencia'!$E:$E,"F",'BD Asistencia'!$C:$C,'Planilla Mensual'!$D11,'BD Asistencia'!$D:$D,">="&'Planilla Mensual'!M11,'BD Asistencia'!$D:$D,"<="&'Planilla Mensual'!N11) -> 0 | AB11: =+SUM(S11:AA11) -> 15 | AC11: 5.5 | AD11: =+Q11/30*SUM(V11:Y11) -> 520 | AE11: =IF(P11="SI",113/2,0) -> 56.5 | AF11: =+(Q11/30*Y11)*2 -> 0 | AG11: 200 | AH11: =+AC11*A11 -> 55 | AI11: =+SUM(AD11:AH11) -> 831.5 | AJ11: =+V11*IF(RIGHT(F11,2)="N3",16,IF(RIGHT(F11,2)="N2",8,4)) -> 176 | AK11: =V11*30 -> 330 | AL11: =IF(G11="ONP",0,AI11*0.1) -> 83.15 | AM11: =IF(G11="ONP",0,AI11*1.37%) -> 11.39155 | AN11: =+IF(G11="ONP",AI11*0.13,0) -> 0 | AO11: 0 | AQ11: 40 | AR11: =+SUM(AL11:AQ11) -> 134.54155 | AS11: =AI11-SUM(AL11:AQ11) -> 696.95845 | AT11: =AJ11+AK11 -> 506 | AV11: =AS11+AT11 -> 1202.9585 | AX11: =+IF(RIGHT(F11,2)="N3",300,0) -> 300 | AY11: =+AX11/30*SUM(V11:Y11) -> 120 | AZ11: =+R11*(S11+T11) -> 100 | BA11: 0 | BC11: =+AY11+AV11+AZ11+BA11+BB11 -> 1422.9585 | BD11: =AI11+AU11+AT11+AY11+AZ11+BA11+BB11 -> 1557.5 | BE11: =(BC11+AQ11)/(V11+S11) -> 121.9132 | BF11: =+BE11*26 -> 3169.7433 | BG11: =(AV11+AY11+SUM(AL11:AQ11))/V11 -> 132.5 | BH11: =+(AZ11+BA11)/(S11+T11) -> 100 | BI11: =+BD11/V11 -> 141.59091
A12: 10 | B12: PLANILLA | C12: 76768818 | D12: MANAYAY TANTARICO JHONATAN WILFER | E12: 37200 | F12: Operador de Maquinaria Agricola N2 | G12: SPP INTEGRA | H12: 671981JMTAT4 | I12: BCP | J12: 30500970418007 | L12: 46146 | M12: 46143 | N12: 46157 | O12: =+TEXT(M12,"mmmm")&" - "&YEAR(M12)&MONTH(M12) -> Mayo - 20265 | P12: NO | Q12: 1300 | R12: 80 | S12: =+COUNTIFS('BD Asistencia'!$E:$E,"A",'BD Asistencia'!$C:$C,'Planilla Mensual'!$D12,'BD Asistencia'!$D:$D,"<"&'Planilla Mensual'!L12) -> 1 | T12: =+COUNTIFS('BD Asistencia'!$E:$E,"DR",'BD Asistencia'!$C:$C,'Planilla Mensual'!$D12,'BD Asistencia'!$D:$D,"<"&L12) -> 0 | U12: =+COUNTIFS('BD Asistencia'!$H:$H,"NO REMUNERADO",'BD Asistencia'!$C:$C,'Planilla Mensual'!$D12,'BD Asistencia'!$D:$D,"<"&L12) -> 2 | V12: =+COUNTIFS('BD Asistencia'!$E:$E,"A",'BD Asistencia'!$C:$C,'Planilla Mensual'!$D12,'BD Asistencia'!$D:$D,">="&'Planilla Mensual'!M12,'BD Asistencia'!$D:$D,"<="&'Planilla Mensual'!N12)-S12 -> 11 | W12: =+COUNTIFS('BD Asistencia'!$E:$E,"DR",'BD Asistencia'!$C:$C,'Planilla Mensual'!$D12,'BD Asistencia'!$D:$D,">="&'Planilla Mensual'!M12,'BD Asistencia'!$D:$D,"<="&'Planilla Mensual'!N12)-T12 -> 1 | X12: =+COUNTIFS('BD Asistencia'!$E:$E,"h",'BD Asistencia'!$C:$C,'Planilla Mensual'!$D12,'BD Asistencia'!$D:$D,">="&'Planilla Mensual'!M12,'BD Asistencia'!$D:$D,"<="&'Planilla Mensual'!N12) -> 0 | Y12: =+COUNTIFS('BD Asistencia'!$E:$E,"h/A",'BD Asistencia'!$C:$C,'Planilla Mensual'!$D12,'BD Asistencia'!$D:$D,">="&'Planilla Mensual'!M12,'BD Asistencia'!$D:$D,"<="&'Planilla Mensual'!N12) -> 0 | Z12: =+COUNTIFS('BD Asistencia'!$H:$H,"NO REMUNERADO",'BD Asistencia'!$C:$C,'Planilla Mensual'!$D12,'BD Asistencia'!$D:$D,">="&'Planilla Mensual'!M12,'BD Asistencia'!$D:$D,"<="&'Planilla Mensual'!N12)-U12 -> 0 | AA12: =+COUNTIFS('BD Asistencia'!$E:$E,"F",'BD Asistencia'!$C:$C,'Planilla Mensual'!$D12,'BD Asistencia'!$D:$D,">="&'Planilla Mensual'!M12,'BD Asistencia'!$D:$D,"<="&'Planilla Mensual'!N12) -> 0 | AB12: =+SUM(S12:AA12) -> 15 | AC12: 3 | AD12: =+Q12/30*SUM(V12:Y12) -> 520 | AE12: =IF(P12="SI",113/2,0) -> 0 | AF12: =+(Q12/30*Y12)*2 -> 0 | AG12: 200 | AH12: =+AC12*A12 -> 30 | AI12: =+SUM(AD12:AH12) -> 750 | AJ12: =+V12*IF(RIGHT(F12,2)="N3",16,IF(RIGHT(F12,2)="N2",8,4)) -> 88 | AK12: =V12*30 -> 330 | AL12: =IF(G12="ONP",0,AI12*0.1) -> 75 | AM12: =IF(G12="ONP",0,AI12*1.37%) -> 10.275 | AN12: =+IF(G12="ONP",AI12*0.13,0) -> 0 | AO12: 0 | AQ12: 300 | AR12: =+SUM(AL12:AQ12) -> 385.275 | AS12: =AI12-SUM(AL12:AQ12) -> 364.725 | AT12: =AJ12+AK12 -> 418 | AV12: =AS12+AT12 -> 782.725 | AX12: =+IF(RIGHT(F12,2)="N3",300,0) -> 0 | AY12: =+AX12/30*SUM(V12:Y12) -> 0 | AZ12: =+R12*(S12+T12) -> 80 | BA12: 0 | BC12: =+AY12+AV12+AZ12+BA12+BB12 -> 862.725 | BD12: =AI12+AU12+AT12+AY12+AZ12+BA12+BB12 -> 1248 | BE12: =(BC12+AQ12)/(V12+S12) -> 96.89375 | BF12: =+BE12*26 -> 2519.2375 | BG12: =(AV12+AY12+SUM(AL12:AQ12))/V12 -> 106.18182 | BH12: =+(AZ12+BA12)/(S12+T12) -> 80 | BI12: =+BD12/V12 -> 113.45455
A13: 10 | B13: PLANILLA | C13: 41758826 | D13: FARROÑAN YOVERA LUIS ALBERTO | E13: 30279 | F13: Operador de Maquinaria Agricola N2 | G13: SPP PRIMA | H13: 602771LFYRE8 | I13: BCP | J13: 30513491010070 | L13: 46146 | M13: 46143 | N13: 46157 | O13: =+TEXT(M13,"mmmm")&" - "&YEAR(M13)&MONTH(M13) -> Mayo - 20265 | P13: SI | Q13: 1300 | R13: 80 | S13: =+COUNTIFS('BD Asistencia'!$E:$E,"A",'BD Asistencia'!$C:$C,'Planilla Mensual'!$D13,'BD Asistencia'!$D:$D,"<"&'Planilla Mensual'!L13) -> 1 | T13: =+COUNTIFS('BD Asistencia'!$E:$E,"DR",'BD Asistencia'!$C:$C,'Planilla Mensual'!$D13,'BD Asistencia'!$D:$D,"<"&L13) -> 0 | U13: =+COUNTIFS('BD Asistencia'!$H:$H,"NO REMUNERADO",'BD Asistencia'!$C:$C,'Planilla Mensual'!$D13,'BD Asistencia'!$D:$D,"<"&L13) -> 2 | V13: =+COUNTIFS('BD Asistencia'!$E:$E,"A",'BD Asistencia'!$C:$C,'Planilla Mensual'!$D13,'BD Asistencia'!$D:$D,">="&'Planilla Mensual'!M13,'BD Asistencia'!$D:$D,"<="&'Planilla Mensual'!N13)-S13 -> 10 | W13: =+COUNTIFS('BD Asistencia'!$E:$E,"DR",'BD Asistencia'!$C:$C,'Planilla Mensual'!$D13,'BD Asistencia'!$D:$D,">="&'Planilla Mensual'!M13,'BD Asistencia'!$D:$D,"<="&'Planilla Mensual'!N13)-T13 -> 1 | X13: =+COUNTIFS('BD Asistencia'!$E:$E,"h",'BD Asistencia'!$C:$C,'Planilla Mensual'!$D13,'BD Asistencia'!$D:$D,">="&'Planilla Mensual'!M13,'BD Asistencia'!$D:$D,"<="&'Planilla Mensual'!N13) -> 0 | Y13: =+COUNTIFS('BD Asistencia'!$E:$E,"h/A",'BD Asistencia'!$C:$C,'Planilla Mensual'!$D13,'BD Asistencia'!$D:$D,">="&'Planilla Mensual'!M13,'BD Asistencia'!$D:$D,"<="&'Planilla Mensual'!N13) -> 0 | Z13: =+COUNTIFS('BD Asistencia'!$H:$H,"NO REMUNERADO",'BD Asistencia'!$C:$C,'Planilla Mensual'!$D13,'BD Asistencia'!$D:$D,">="&'Planilla Mensual'!M13,'BD Asistencia'!$D:$D,"<="&'Planilla Mensual'!N13)-U13 -> 0 | AA13: =+COUNTIFS('BD Asistencia'!$E:$E,"F",'BD Asistencia'!$C:$C,'Planilla Mensual'!$D13,'BD Asistencia'!$D:$D,">="&'Planilla Mensual'!M13,'BD Asistencia'!$D:$D,"<="&'Planilla Mensual'!N13) -> 1 | AB13: =+SUM(S13:AA13) -> 15 | AC13: 12 | AD13: =+Q13/30*SUM(V13:Y13) -> 476.66667 | AE13: =IF(P13="SI",113/2,0) -> 56.5 | AF13: =+(Q13/30*Y13)*2 -> 0 | AG13: 100 | AH13: =+AC13*A13 -> 120 | AI13: =+SUM(AD13:AH13) -> 753.16667 | AJ13: =+V13*IF(RIGHT(F13,2)="N3",16,IF(RIGHT(F13,2)="N2",8,4)) -> 80 | AK13: =V13*30 -> 300 | AL13: =IF(G13="ONP",0,AI13*0.1) -> 75.316667 | AM13: =IF(G13="ONP",0,AI13*1.37%) -> 10.318383 | AN13: =+IF(G13="ONP",AI13*0.13,0) -> 0 | AO13: 0 | AQ13: 280 | AR13: =+SUM(AL13:AQ13) -> 365.63505 | AS13: =AI13-SUM(AL13:AQ13) -> 387.53162 | AT13: =AJ13+AK13 -> 380 | AV13: =AS13+AT13 -> 767.53162 | AX13: =+IF(RIGHT(F13,2)="N3",300,0) -> 0 | AY13: =+AX13/30*SUM(V13:Y13) -> 0 | AZ13: =+R13*(S13+T13) -> 80 | BA13: 0 | BC13: =+AY13+AV13+AZ13+BA13+BB13 -> 847.53162 | BD13: =AI13+AU13+AT13+AY13+AZ13+BA13+BB13 -> 1213.1667 | BE13: =(BC13+AQ13)/(V13+S13) -> 102.50287 | BF13: =+BE13*26 -> 2665.0747 | BG13: =(AV13+AY13+SUM(AL13:AQ13))/V13 -> 113.31667 | BH13: =+(AZ13+BA13)/(S13+T13) -> 80 | BI13: =+BD13/V13 -> 121.31667
A14: 10 | B14: PLANILLA | C14: 71983929 | D14: CHUICA ADANAQUE ANDERSON XAVIER | E14: 33973 | F14: Operador de Maquinaria Agricola N3 | G14: ONP | I14: BCP | J14: 47525665591096 | L14: 46146 | M14: 46143 | N14: 46157 | O14: =+TEXT(M14,"mmmm")&" - "&YEAR(M14)&MONTH(M14) -> Mayo - 20265 | P14: SI | Q14: 1300 | S14: =+COUNTIFS('BD Asistencia'!$E:$E,"A",'BD Asistencia'!$C:$C,'Planilla Mensual'!$D14,'BD Asistencia'!$D:$D,"<"&'Planilla Mensual'!L14) -> 0 | T14: =+COUNTIFS('BD Asistencia'!$E:$E,"DR",'BD Asistencia'!$C:$C,'Planilla Mensual'!$D14,'BD Asistencia'!$D:$D,"<"&L14) -> 0 | U14: =+COUNTIFS('BD Asistencia'!$H:$H,"NO REMUNERADO",'BD Asistencia'!$C:$C,'Planilla Mensual'!$D14,'BD Asistencia'!$D:$D,"<"&L14) -> 3 | V14: =+COUNTIFS('BD Asistencia'!$E:$E,"A",'BD Asistencia'!$C:$C,'Planilla Mensual'!$D14,'BD Asistencia'!$D:$D,">="&'Planilla Mensual'!M14,'BD Asistencia'!$D:$D,"<="&'Planilla Mensual'!N14)-S14 -> 11 | W14: =+COUNTIFS('BD Asistencia'!$E:$E,"DR",'BD Asistencia'!$C:$C,'Planilla Mensual'!$D14,'BD Asistencia'!$D:$D,">="&'Planilla Mensual'!M14,'BD Asistencia'!$D:$D,"<="&'Planilla Mensual'!N14)-T14 -> 1 | X14: =+COUNTIFS('BD Asistencia'!$E:$E,"h",'BD Asistencia'!$C:$C,'Planilla Mensual'!$D14,'BD Asistencia'!$D:$D,">="&'Planilla Mensual'!M14,'BD Asistencia'!$D:$D,"<="&'Planilla Mensual'!N14) -> 0 | Y14: =+COUNTIFS('BD Asistencia'!$E:$E,"h/A",'BD Asistencia'!$C:$C,'Planilla Mensual'!$D14,'BD Asistencia'!$D:$D,">="&'Planilla Mensual'!M14,'BD Asistencia'!$D:$D,"<="&'Planilla Mensual'!N14) -> 0 | Z14: =+COUNTIFS('BD Asistencia'!$H:$H,"NO REMUNERADO",'BD Asistencia'!$C:$C,'Planilla Mensual'!$D14,'BD Asistencia'!$D:$D,">="&'Planilla Mensual'!M14,'BD Asistencia'!$D:$D,"<="&'Planilla Mensual'!N14)-U14 -> 0 | AA14: =+COUNTIFS('BD Asistencia'!$E:$E,"F",'BD Asistencia'!$C:$C,'Planilla Mensual'!$D14,'BD Asistencia'!$D:$D,">="&'Planilla Mensual'!M14,'BD Asistencia'!$D:$D,"<="&'Planilla Mensual'!N14) -> 0 | AB14: =+SUM(S14:AA14) -> 15 | AC14: 4.05 | AD14: =+Q14/30*SUM(V14:Y14) -> 520 | AE14: =IF(P14="SI",113/2,0) -> 56.5 | AF14: =+(Q14/30*Y14)*2 -> 0 | AG14: 200 | AH14: =+AC14*A14 -> 40.5 | AI14: =+SUM(AD14:AH14) -> 817 | AJ14: =+V14*IF(RIGHT(F14,2)="N3",16,IF(RIGHT(F14,2)="N2",8,4)) -> 176 | AK14: =V14*30 -> 330 | AL14: =IF(G14="ONP",0,AI14*0.1) -> 0 | AM14: =IF(G14="ONP",0,AI14*1.37%) -> 0 | AN14: =+IF(G14="ONP",AI14*0.13,0) -> 106.21 | AO14: 0 | AQ14: =180+120 -> 300 | AR14: =+SUM(AL14:AQ14) -> 406.21 | AS14: =AI14-SUM(AL14:AQ14) -> 410.79 | AT14: =AJ14+AK14 -> 506 | AV14: =AS14+AT14 -> 916.79 | AX14: =+IF(RIGHT(F14,2)="N3",300,0) -> 300 | AY14: =+AX14/30*SUM(V14:Y14) -> 120 | AZ14: =+R14*(S14+T14) -> 0 | BA14: 0 | BC14: =+AY14+AV14+AZ14+BA14+BB14 -> 1036.79 | BD14: =AI14+AU14+AT14+AY14+AZ14+BA14+BB14 -> 1443 | BE14: =(BC14+AQ14)/(V14+S14) -> 121.52636 | BF14: =+BE14*26 -> 3159.6855 | BG14: =(AV14+AY14+SUM(AL14:AQ14))/V14 -> 131.18182 | BH14: =+(AZ14+BA14)/(S14+T14) -> #DIV/0! | BI14: =+BD14/V14 -> 131.18182
A15: 10 | B15: PLANILLA | C15: 45952951 | D15: GARCIA RAMOS SEGUNDO MIGUEL | E15: 32777 | F15: Operador de Maquinaria Agricola N3 | G15: SPP PRIMA | H15: 627751SGRCO7 | I15: BCP | J15: 47531606418032 | L15: 46146 | M15: 46143 | N15: 46157 | O15: =+TEXT(M15,"mmmm")&" - "&YEAR(M15)&MONTH(M15) -> Mayo - 20265 | P15: SI | Q15: 1300 | S15: =+COUNTIFS('BD Asistencia'!$E:$E,"A",'BD Asistencia'!$C:$C,'Planilla Mensual'!$D15,'BD Asistencia'!$D:$D,"<"&'Planilla Mensual'!L15) -> 0 | T15: =+COUNTIFS('BD Asistencia'!$E:$E,"DR",'BD Asistencia'!$C:$C,'Planilla Mensual'!$D15,'BD Asistencia'!$D:$D,"<"&L15) -> 0 | U15: =+COUNTIFS('BD Asistencia'!$H:$H,"NO REMUNERADO",'BD Asistencia'!$C:$C,'Planilla Mensual'!$D15,'BD Asistencia'!$D:$D,"<"&L15) -> 3 | V15: =+COUNTIFS('BD Asistencia'!$E:$E,"A",'BD Asistencia'!$C:$C,'Planilla Mensual'!$D15,'BD Asistencia'!$D:$D,">="&'Planilla Mensual'!M15,'BD Asistencia'!$D:$D,"<="&'Planilla Mensual'!N15)-S15 -> 11 | W15: =+COUNTIFS('BD Asistencia'!$E:$E,"DR",'BD Asistencia'!$C:$C,'Planilla Mensual'!$D15,'BD Asistencia'!$D:$D,">="&'Planilla Mensual'!M15,'BD Asistencia'!$D:$D,"<="&'Planilla Mensual'!N15)-T15 -> 1 | X15: =+COUNTIFS('BD Asistencia'!$E:$E,"h",'BD Asistencia'!$C:$C,'Planilla Mensual'!$D15,'BD Asistencia'!$D:$D,">="&'Planilla Mensual'!M15,'BD Asistencia'!$D:$D,"<="&'Planilla Mensual'!N15) -> 0 | Y15: =+COUNTIFS('BD Asistencia'!$E:$E,"h/A",'BD Asistencia'!$C:$C,'Planilla Mensual'!$D15,'BD Asistencia'!$D:$D,">="&'Planilla Mensual'!M15,'BD Asistencia'!$D:$D,"<="&'Planilla Mensual'!N15) -> 0 | Z15: =+COUNTIFS('BD Asistencia'!$H:$H,"NO REMUNERADO",'BD Asistencia'!$C:$C,'Planilla Mensual'!$D15,'BD Asistencia'!$D:$D,">="&'Planilla Mensual'!M15,'BD Asistencia'!$D:$D,"<="&'Planilla Mensual'!N15)-U15 -> 0 | AA15: =+COUNTIFS('BD Asistencia'!$E:$E,"F",'BD Asistencia'!$C:$C,'Planilla Mensual'!$D15,'BD Asistencia'!$D:$D,">="&'Planilla Mensual'!M15,'BD Asistencia'!$D:$D,"<="&'Planilla Mensual'!N15) -> 0 | AB15: =+SUM(S15:AA15) -> 15 | AC15: 4.8 | AD15: =+Q15/30*SUM(V15:Y15) -> 520 | AE15: =IF(P15="SI",113/2,0) -> 56.5 | AF15: =+(Q15/30*Y15)*2 -> 0 | AG15: 200 | AH15: =+AC15*A15 -> 48 | AI15: =+SUM(AD15:AH15) -> 824.5 | AJ15: =+V15*IF(RIGHT(F15,2)="N3",16,IF(RIGHT(F15,2)="N2",8,4)) -> 176 | AK15: =V15*30 -> 330 | AL15: =IF(G15="ONP",0,AI15*0.1) -> 82.45 | AM15: =IF(G15="ONP",0,AI15*1.37%) -> 11.29565 | AN15: =+IF(G15="ONP",AI15*0.13,0) -> 0 | AO15: 0 | AQ15: =180+20 -> 200 | AR15: =+SUM(AL15:AQ15) -> 293.74565 | AS15: =AI15-SUM(AL15:AQ15) -> 530.75435 | AT15: =AJ15+AK15 -> 506 | AV15: =AS15+AT15 -> 1036.7543 | AX15: 300 | AY15: =+AX15/30*SUM(V15:Y15) -> 120 | AZ15: =+R15*(S15+T15) -> 0 | BA15: 0 | BC15: =+AY15+AV15+AZ15+BA15+BB15 -> 1156.7543 | BD15: =AI15+AU15+AT15+AY15+AZ15+BA15+BB15 -> 1450.5 | BE15: =(BC15+AQ15)/(V15+S15) -> 123.3413 | BF15: =+BE15*26 -> 3206.8739 | BG15: =(AV15+AY15+SUM(AL15:AQ15))/V15 -> 131.86364 | BH15: =+(AZ15+BA15)/(S15+T15) -> #DIV/0! | BI15: =+BD15/V15 -> 131.86364
A16: 10 | B16: PLANILLA | C16: 48187021 | D16: CARLOS ROQUE JUNIOR ABEL | E16: 34283 | F16: Operador de Maquinaria Agricola N3 | G16: SPP INTEGRA | H16: 342811JCRLU0 | I16: BCP | J16: 41599043973014 | L16: 46146 | M16: 46143 | N16: 46157 | O16: =+TEXT(M16,"mmmm")&" - "&YEAR(M16)&MONTH(M16) -> Mayo - 20265 | P16: SI | Q16: 1300 | S16: =+COUNTIFS('BD Asistencia'!$E:$E,"A",'BD Asistencia'!$C:$C,'Planilla Mensual'!$D16,'BD Asistencia'!$D:$D,"<"&'Planilla Mensual'!L16) -> 0 | T16: =+COUNTIFS('BD Asistencia'!$E:$E,"DR",'BD Asistencia'!$C:$C,'Planilla Mensual'!$D16,'BD Asistencia'!$D:$D,"<"&L16) -> 0 | U16: =+COUNTIFS('BD Asistencia'!$H:$H,"NO REMUNERADO",'BD Asistencia'!$C:$C,'Planilla Mensual'!$D16,'BD Asistencia'!$D:$D,"<"&L16) -> 3 | V16: =+COUNTIFS('BD Asistencia'!$E:$E,"A",'BD Asistencia'!$C:$C,'Planilla Mensual'!$D16,'BD Asistencia'!$D:$D,">="&'Planilla Mensual'!M16,'BD Asistencia'!$D:$D,"<="&'Planilla Mensual'!N16)-S16 -> 10 | W16: =+COUNTIFS('BD Asistencia'!$E:$E,"DR",'BD Asistencia'!$C:$C,'Planilla Mensual'!$D16,'BD Asistencia'!$D:$D,">="&'Planilla Mensual'!M16,'BD Asistencia'!$D:$D,"<="&'Planilla Mensual'!N16)-T16 -> 1 | X16: =+COUNTIFS('BD Asistencia'!$E:$E,"h",'BD Asistencia'!$C:$C,'Planilla Mensual'!$D16,'BD Asistencia'!$D:$D,">="&'Planilla Mensual'!M16,'BD Asistencia'!$D:$D,"<="&'Planilla Mensual'!N16) -> 0 | Y16: =+COUNTIFS('BD Asistencia'!$E:$E,"h/A",'BD Asistencia'!$C:$C,'Planilla Mensual'!$D16,'BD Asistencia'!$D:$D,">="&'Planilla Mensual'!M16,'BD Asistencia'!$D:$D,"<="&'Planilla Mensual'!N16) -> 0 | Z16: =+COUNTIFS('BD Asistencia'!$H:$H,"NO REMUNERADO",'BD Asistencia'!$C:$C,'Planilla Mensual'!$D16,'BD Asistencia'!$D:$D,">="&'Planilla Mensual'!M16,'BD Asistencia'!$D:$D,"<="&'Planilla Mensual'!N16)-U16 -> 1 | AA16: =+COUNTIFS('BD Asistencia'!$E:$E,"F",'BD Asistencia'!$C:$C,'Planilla Mensual'!$D16,'BD Asistencia'!$D:$D,">="&'Planilla Mensual'!M16,'BD Asistencia'!$D:$D,"<="&'Planilla Mensual'!N16) -> 0 | AB16: =+SUM(S16:AA16) -> 15 | AC16: 8.5 | AD16: =+Q16/30*SUM(V16:Y16) -> 476.66667 | AE16: =IF(P16="SI",113/2,0) -> 56.5 | AF16: =+(Q16/30*Y16)*2 -> 0 | AG16: 200 | AH16: =+AC16*A16 -> 85 | AI16: =+SUM(AD16:AH16) -> 818.16667 | AJ16: =+V16*IF(RIGHT(F16,2)="N3",16,IF(RIGHT(F16,2)="N2",8,4)) -> 160 | AK16: =V16*30 -> 300 | AL16: =IF(G16="ONP",0,AI16*0.1) -> 81.816667 | AM16: =IF(G16="ONP",0,AI16*1.37%) -> 11.208883 | AN16: =+IF(G16="ONP",AI16*0.13,0) -> 0 | AO16: 0 | AQ16: =180+20 -> 200 | AR16: =+SUM(AL16:AQ16) -> 293.02555 | AS16: =AI16-SUM(AL16:AQ16) -> 525.14112 | AT16: =AJ16+AK16 -> 460 | AV16: =AS16+AT16 -> 985.14112 | AX16: =+IF(RIGHT(F16,2)="N3",300,0) -> 300 | AY16: =+AX16/30*SUM(V16:Y16) -> 110 | AZ16: =+R16*(S16+T16) -> 0 | BA16: 0 | BC16: =+AY16+AV16+AZ16+BA16+BB16 -> 1095.1411 | BD16: =AI16+AU16+AT16+AY16+AZ16+BA16+BB16 -> 1388.1667 | BE16: =(BC16+AQ16)/(V16+S16) -> 129.51411 | BF16: =+BE16*26 -> 3367.3669 | BG16: =(AV16+AY16+SUM(AL16:AQ16))/V16 -> 138.81667 | BH16: =+(AZ16+BA16)/(S16+T16) -> #DIV/0! | BI16: =+BD16/V16 -> 138.81667
A17: 10 | B17: PLANILLA | C17: 77709008 | D17: CRUZ VARGAS MARCO ANTONIO | E17: 35588 | F17: Operador de Maquinaria Agricola N3 | G17: SPP INTEGRA | H17: 655861MCVZG3 | I17: BCP | J17: 57073429072032 | L17: 46146 | M17: 46143 | N17: 46157 | O17: =+TEXT(M17,"mmmm")&" - "&YEAR(M17)&MONTH(M17) -> Mayo - 20265 | P17: SI | Q17: 1300 | S17: =+COUNTIFS('BD Asistencia'!$E:$E,"A",'BD Asistencia'!$C:$C,'Planilla Mensual'!$D17,'BD Asistencia'!$D:$D,"<"&'Planilla Mensual'!L17) -> 0 | T17: =+COUNTIFS('BD Asistencia'!$E:$E,"DR",'BD Asistencia'!$C:$C,'Planilla Mensual'!$D17,'BD Asistencia'!$D:$D,"<"&L17) -> 0 | U17: =+COUNTIFS('BD Asistencia'!$H:$H,"NO REMUNERADO",'BD Asistencia'!$C:$C,'Planilla Mensual'!$D17,'BD Asistencia'!$D:$D,"<"&L17) -> 3 | V17: 7 | W17: 1 | X17: =+COUNTIFS('BD Asistencia'!$E:$E,"h",'BD Asistencia'!$C:$C,'Planilla Mensual'!$D17,'BD Asistencia'!$D:$D,">="&'Planilla Mensual'!M17,'BD Asistencia'!$D:$D,"<="&'Planilla Mensual'!N17) -> 0 | Y17: =+COUNTIFS('BD Asistencia'!$E:$E,"h/A",'BD Asistencia'!$C:$C,'Planilla Mensual'!$D17,'BD Asistencia'!$D:$D,">="&'Planilla Mensual'!M17,'BD Asistencia'!$D:$D,"<="&'Planilla Mensual'!N17) -> 0 | Z17: 4 | AA17: =+COUNTIFS('BD Asistencia'!$E:$E,"F",'BD Asistencia'!$C:$C,'Planilla Mensual'!$D17,'BD Asistencia'!$D:$D,">="&'Planilla Mensual'!M17,'BD Asistencia'!$D:$D,"<="&'Planilla Mensual'!N17) -> 0 | AB17: =+SUM(S17:AA17) -> 15 | AD17: =+Q17/30*SUM(V17:Y17) -> 346.66667 | AE17: =IF(P17="SI",113/2,0) -> 56.5 | AF17: =+(Q17/30*Y17)*2 -> 0 | AG17: 0 | AH17: =+AC17*A17 -> 0 | AI17: =+SUM(AD17:AH17) -> 403.16667 | AJ17: =+V17*IF(RIGHT(F17,2)="N3",16,IF(RIGHT(F17,2)="N2",8,4)) -> 112 | AK17: =V17*30 -> 210 | AL17: =IF(G17="ONP",0,AI17*0.1) -> 40.316667 | AM17: =IF(G17="ONP",0,AI17*1.37%) -> 5.5233833 | AN17: =+IF(G17="ONP",AI17*0.13,0) -> 0 | AO17: 0 | AQ17: =30+64 -> 94 | AR17: =+SUM(AL17:AQ17) -> 139.84005 | AS17: =AI17-SUM(AL17:AQ17) -> 263.32662 | AT17: =AJ17+AK17 -> 322 | AV17: =AS17+AT17 -> 585.32662 | AX17: =+IF(RIGHT(F17,2)="N3",300,0) -> 300 | AY17: =+AX17/30*SUM(V17:Y17) -> 80 | AZ17: =+R17*(S17+T17) -> 0 | BA17: 0 | BC17: =+AY17+AV17+AZ17+BA17+BB17 -> 665.32662 | BD17: =AI17+AU17+AT17+AY17+AZ17+BA17+BB17 -> 805.16667 | BE17: =(BC17+AQ17)/(V17+S17) -> 108.47523 | BF17: =+BE17*26 -> 2820.356 | BG17: =(AV17+AY17+SUM(AL17:AQ17))/V17 -> 115.02381 | BH17: =+(AZ17+BA17)/(S17+T17) -> #DIV/0! | BI17: =+BD17/V17 -> 115.02381
A18: 10 | B18: PLANILLA | C18: 77236592 | D18: BERNA TANTARICO BENJAMIN | E18: 34712 | F18: Operador de Maquinaria Agricola N2 | G18: SPP HABITAT | H18: 647101BBTNT4 | I18: BCP | J18: 30593206658025 | L18: 46153 | M18: 46143 | N18: 46157 | O18: =+TEXT(M18,"mmmm")&" - "&YEAR(M18)&MONTH(M18) -> Mayo - 20265 | P18: NO | Q18: 1300 | R18: 80 | S18: =+COUNTIFS('BD Asistencia'!$E:$E,"A",'BD Asistencia'!$C:$C,'Planilla Mensual'!$D18,'BD Asistencia'!$D:$D,"<"&'Planilla Mensual'!L18) -> 1 | T18: =+COUNTIFS('BD Asistencia'!$E:$E,"DR",'BD Asistencia'!$C:$C,'Planilla Mensual'!$D18,'BD Asistencia'!$D:$D,"<"&L18) -> 0 | U18: =+COUNTIFS('BD Asistencia'!$H:$H,"NO REMUNERADO",'BD Asistencia'!$C:$C,'Planilla Mensual'!$D18,'BD Asistencia'!$D:$D,"<"&L18) -> 9 | V18: 5 | W18: =+COUNTIFS('BD Asistencia'!$E:$E,"DR",'BD Asistencia'!$C:$C,'Planilla Mensual'!$D18,'BD Asistencia'!$D:$D,">="&'Planilla Mensual'!M18,'BD Asistencia'!$D:$D,"<="&'Planilla Mensual'!N18)-T18 -> 0 | X18: =+COUNTIFS('BD Asistencia'!$E:$E,"h",'BD Asistencia'!$C:$C,'Planilla Mensual'!$D18,'BD Asistencia'!$D:$D,">="&'Planilla Mensual'!M18,'BD Asistencia'!$D:$D,"<="&'Planilla Mensual'!N18) -> 0 | Y18: =+COUNTIFS('BD Asistencia'!$E:$E,"h/A",'BD Asistencia'!$C:$C,'Planilla Mensual'!$D18,'BD Asistencia'!$D:$D,">="&'Planilla Mensual'!M18,'BD Asistencia'!$D:$D,"<="&'Planilla Mensual'!N18) -> 0 | Z18: =+COUNTIFS('BD Asistencia'!$H:$H,"NO REMUNERADO",'BD Asistencia'!$C:$C,'Planilla Mensual'!$D18,'BD Asistencia'!$D:$D,">="&'Planilla Mensual'!M18,'BD Asistencia'!$D:$D,"<="&'Planilla Mensual'!N18)-U18 -> 0 | AA18: =+COUNTIFS('BD Asistencia'!$E:$E,"F",'BD Asistencia'!$C:$C,'Planilla Mensual'!$D18,'BD Asistencia'!$D:$D,">="&'Planilla Mensual'!M18,'BD Asistencia'!$D:$D,"<="&'Planilla Mensual'!N18) -> 0 | AB18: =+SUM(S18:AA18) -> 15 | AC18: 7 | AD18: =+Q18/30*SUM(V18:Y18) -> 216.66667 | AE18: =IF(P18="SI",113/2,0) -> 0 | AF18: =+(Q18/30*Y18)*2 -> 0 | AG18: 100 | AH18: =+AC18*A18 -> 70 | AI18: =+SUM(AD18:AH18) -> 386.66667 | AJ18: =+V18*IF(RIGHT(F18,2)="N3",16,IF(RIGHT(F18,2)="N2",8,4)) -> 40 | AK18: =V18*30 -> 150 | AL18: =IF(G18="ONP",0,AI18*0.1) -> 38.666667 | AM18: =IF(G18="ONP",0,AI18*1.37%) -> 5.2973333 | AN18: =+IF(G18="ONP",AI18*0.13,0) -> 0 | AO18: 0 | AQ18: 140 | AR18: =+SUM(AL18:AQ18) -> 183.964 | AS18: =AI18-SUM(AL18:AQ18) -> 202.70267 | AT18: =AJ18+AK18 -> 190 | AV18: =AS18+AT18 -> 392.70267 | AX18: =+IF(RIGHT(F18,2)="N3",300,0) -> 0 | AY18: =+AX18/30*SUM(V18:Y18) -> 0 | AZ18: =+R18*(S18+T18) -> 80 | BA18: 0 | BC18: =+AY18+AV18+AZ18+BA18+BB18 -> 472.70267 | BD18: =AI18+AU18+AT18+AY18+AZ18+BA18+BB18 -> 656.66667 | BE18: =(BC18+AQ18)/(V18+S18) -> 102.11711 | BF18: =+BE18*26 -> 2655.0449 | BG18: =(AV18+AY18+SUM(AL18:AQ18))/V18 -> 115.33333 | BH18: =+(AZ18+BA18)/(S18+T18) -> 80 | BI18: =+BD18/V18 -> 131.33333
A19: 10 | B19: PLANILLA | C19: 70828937 | D19: HERNANDEZ GOMEZ LUIS JHONATAN | E19: 36383 | F19: Operador de Maquinaria Agricola N3 | G19: SPP PRIMA | H19: 663811LHGNE7 | I19: BCP | J19: 47515071114006 | L19: 46153 | M19: 46143 | N19: 46157 | O19: =+TEXT(M19,"mmmm")&" - "&YEAR(M19)&MONTH(M19) -> Mayo - 20265 | P19: SI | Q19: 1300 | S19: =+COUNTIFS('BD Asistencia'!$E:$E,"A",'BD Asistencia'!$C:$C,'Planilla Mensual'!$D19,'BD Asistencia'!$D:$D,"<"&'Planilla Mensual'!L19) -> 0 | T19: =+COUNTIFS('BD Asistencia'!$E:$E,"DR",'BD Asistencia'!$C:$C,'Planilla Mensual'!$D19,'BD Asistencia'!$D:$D,"<"&L19) -> 0 | U19: =+COUNTIFS('BD Asistencia'!$H:$H,"NO REMUNERADO",'BD Asistencia'!$C:$C,'Planilla Mensual'!$D19,'BD Asistencia'!$D:$D,"<"&L19) -> 10 | V19: =+COUNTIFS('BD Asistencia'!$E:$E,"A",'BD Asistencia'!$C:$C,'Planilla Mensual'!$D19,'BD Asistencia'!$D:$D,">="&'Planilla Mensual'!M19,'BD Asistencia'!$D:$D,"<="&'Planilla Mensual'!N19)-S19 -> 5 | W19: =+COUNTIFS('BD Asistencia'!$E:$E,"DR",'BD Asistencia'!$C:$C,'Planilla Mensual'!$D19,'BD Asistencia'!$D:$D,">="&'Planilla Mensual'!M19,'BD Asistencia'!$D:$D,"<="&'Planilla Mensual'!N19)-T19 -> 0 | X19: =+COUNTIFS('BD Asistencia'!$E:$E,"h",'BD Asistencia'!$C:$C,'Planilla Mensual'!$D19,'BD Asistencia'!$D:$D,">="&'Planilla Mensual'!M19,'BD Asistencia'!$D:$D,"<="&'Planilla Mensual'!N19) -> 0 | Y19: =+COUNTIFS('BD Asistencia'!$E:$E,"h/A",'BD Asistencia'!$C:$C,'Planilla Mensual'!$D19,'BD Asistencia'!$D:$D,">="&'Planilla Mensual'!M19,'BD Asistencia'!$D:$D,"<="&'Planilla Mensual'!N19) -> 0 | Z19: =+COUNTIFS('BD Asistencia'!$H:$H,"NO REMUNERADO",'BD Asistencia'!$C:$C,'Planilla Mensual'!$D19,'BD Asistencia'!$D:$D,">="&'Planilla Mensual'!M19,'BD Asistencia'!$D:$D,"<="&'Planilla Mensual'!N19)-U19 -> 0 | AA19: =+COUNTIFS('BD Asistencia'!$E:$E,"F",'BD Asistencia'!$C:$C,'Planilla Mensual'!$D19,'BD Asistencia'!$D:$D,">="&'Planilla Mensual'!M19,'BD Asistencia'!$D:$D,"<="&'Planilla Mensual'!N19) -> 0 | AB19: =+SUM(S19:AA19) -> 15 | AD19: =+Q19/30*SUM(V19:Y19) -> 216.66667 | AE19: =IF(P19="SI",113/2,0) -> 56.5 | AF19: =+(Q19/30*Y19)*2 -> 0 | AG19: 100 | AH19: =+AC19*A19 -> 0 | AI19: =+SUM(AD19:AH19) -> 373.16667 | AJ19: =+V19*IF(RIGHT(F19,2)="N3",16,IF(RIGHT(F19,2)="N2",8,4)) -> 80 | AK19: =V19*30 -> 150 | AL19: =IF(G19="ONP",0,AI19*0.1) -> 37.316667 | AM19: =IF(G19="ONP",0,AI19*1.37%) -> 5.1123833 | AN19: =+IF(G19="ONP",AI19*0.13,0) -> 0 | AO19: 0 | AQ19: 80 | AR19: =+SUM(AL19:AQ19) -> 122.42905 | AS19: =AI19-SUM(AL19:AQ19) -> 250.73762 | AT19: =AJ19+AK19 -> 230 | AV19: =AS19+AT19 -> 480.73762 | AX19: =+IF(RIGHT(F19,2)="N3",300,0) -> 300 | AY19: =+AX19/30*SUM(V19:Y19) -> 50 | AZ19: =+R19*(S19+T19) -> 0 | BA19: 0 | BC19: =+AY19+AV19+AZ19+BA19+BB19 -> 530.73762 | BD19: =AI19+AU19+AT19+AY19+AZ19+BA19+BB19 -> 653.16667 | BE19: =(BC19+AQ19)/(V19+S19) -> 122.14752 | BF19: =+BE19*26 -> 3175.8356 | BG19: =(AV19+AY19+SUM(AL19:AQ19))/V19 -> 130.63333 | BH19: =+(AZ19+BA19)/(S19+T19) -> #DIV/0! | BI19: =+BD19/V19 -> 130.63333
A20: 10 | B20: PENDIENTE | C20: 43070165 | D20: CURO PAZ FELIPE | E20: 45784 | I20: BCP | J20: 57098472871099 | L20: 46158 | M20: 46143 | N20: 46157 | O20: =+TEXT(M20,"mmmm")&" - "&YEAR(M20)&MONTH(M20) -> Mayo - 20265 | P20: SI | R20: 90 | S20: =+COUNTIFS('BD Asistencia'!$E:$E,"A",'BD Asistencia'!$C:$C,'Planilla Mensual'!$D20,'BD Asistencia'!$D:$D,"<"&'Planilla Mensual'!L20) -> 12 | T20: =+COUNTIFS('BD Asistencia'!$E:$E,"DR",'BD Asistencia'!$C:$C,'Planilla Mensual'!$D20,'BD Asistencia'!$D:$D,"<"&L20) -> 3 | U20: =+COUNTIFS('BD Asistencia'!$H:$H,"NO REMUNERADO",'BD Asistencia'!$C:$C,'Planilla Mensual'!$D20,'BD Asistencia'!$D:$D,"<"&L20) -> 0 | V20: =+COUNTIFS('BD Asistencia'!$E:$E,"A",'BD Asistencia'!$C:$C,'Planilla Mensual'!$D20,'BD Asistencia'!$D:$D,">="&'Planilla Mensual'!M20,'BD Asistencia'!$D:$D,"<="&'Planilla Mensual'!N20)-S20 -> 0 | W20: =+COUNTIFS('BD Asistencia'!$E:$E,"DR",'BD Asistencia'!$C:$C,'Planilla Mensual'!$D20,'BD Asistencia'!$D:$D,">="&'Planilla Mensual'!M20,'BD Asistencia'!$D:$D,"<="&'Planilla Mensual'!N20)-T20 -> 0 | X20: =+COUNTIFS('BD Asistencia'!$E:$E,"h",'BD Asistencia'!$C:$C,'Planilla Mensual'!$D20,'BD Asistencia'!$D:$D,">="&'Planilla Mensual'!M20,'BD Asistencia'!$D:$D,"<="&'Planilla Mensual'!N20) -> 0 | Y20: =+COUNTIFS('BD Asistencia'!$E:$E,"h/A",'BD Asistencia'!$C:$C,'Planilla Mensual'!$D20,'BD Asistencia'!$D:$D,">="&'Planilla Mensual'!M20,'BD Asistencia'!$D:$D,"<="&'Planilla Mensual'!N20) -> 0 | Z20: =+COUNTIFS('BD Asistencia'!$H:$H,"NO REMUNERADO",'BD Asistencia'!$C:$C,'Planilla Mensual'!$D20,'BD Asistencia'!$D:$D,">="&'Planilla Mensual'!M20,'BD Asistencia'!$D:$D,"<="&'Planilla Mensual'!N20)-U20 -> 0 | AA20: =+COUNTIFS('BD Asistencia'!$E:$E,"F",'BD Asistencia'!$C:$C,'Planilla Mensual'!$D20,'BD Asistencia'!$D:$D,">="&'Planilla Mensual'!M20,'BD Asistencia'!$D:$D,"<="&'Planilla Mensual'!N20) -> 0 | AB20: =+SUM(S20:AA20) -> 15 | AR20: =+SUM(AL20:AQ20) -> 0 | AS20: =AI20-SUM(AL20:AQ20) -> 0 | AT20: =AJ20+AK20 -> 0 | AV20: =AS20+AT20 -> 0 | AZ20: =+R20*(S20+T20) -> 1350 | BB20: =+AC20*A20 -> 0 | BC20: =+AY20+AV20+AZ20+BA20+BB20 -> 1350 | BD20: =AI20+AU20+AT20+AY20+AZ20+BA20+BB20 -> 1350 | BG20: =(AV20+AY20+SUM(AL20:AQ20))/V20 -> #DIV/0! | BH20: =+(AZ20+BA20)/(S20+T20) -> 90 | BI20: =25+15 -> 40
A21: 18 | B21: PENDIENTE | C21: 47665126 | D21: GARCIA RAMOS JOSE ISMAEL | E21: 33994 | I21: BCP | J21: 47538222882029 | L21: 46158 | M21: 46143 | N21: 46157 | O21: =+TEXT(M21,"mmmm")&" - "&YEAR(M21)&MONTH(M21) -> Mayo - 20265 | P21: SI | R21: 80 | S21: =+COUNTIFS('BD Asistencia'!$E:$E,"A",'BD Asistencia'!$C:$C,'Planilla Mensual'!$D21,'BD Asistencia'!$D:$D,"<"&'Planilla Mensual'!L21) -> 14 | T21: =+COUNTIFS('BD Asistencia'!$E:$E,"DR",'BD Asistencia'!$C:$C,'Planilla Mensual'!$D21,'BD Asistencia'!$D:$D,"<"&L21) -> 1 | U21: =+COUNTIFS('BD Asistencia'!$H:$H,"NO REMUNERADO",'BD Asistencia'!$C:$C,'Planilla Mensual'!$D21,'BD Asistencia'!$D:$D,"<"&L21) -> 0 | V21: =+COUNTIFS('BD Asistencia'!$E:$E,"A",'BD Asistencia'!$C:$C,'Planilla Mensual'!$D21,'BD Asistencia'!$D:$D,">="&'Planilla Mensual'!M21,'BD Asistencia'!$D:$D,"<="&'Planilla Mensual'!N21)-S21 -> 0 | W21: =+COUNTIFS('BD Asistencia'!$E:$E,"DR",'BD Asistencia'!$C:$C,'Planilla Mensual'!$D21,'BD Asistencia'!$D:$D,">="&'Planilla Mensual'!M21,'BD Asistencia'!$D:$D,"<="&'Planilla Mensual'!N21)-T21 -> 0 | X21: =+COUNTIFS('BD Asistencia'!$E:$E,"h",'BD Asistencia'!$C:$C,'Planilla Mensual'!$D21,'BD Asistencia'!$D:$D,">="&'Planilla Mensual'!M21,'BD Asistencia'!$D:$D,"<="&'Planilla Mensual'!N21) -> 0 | Y21: =+COUNTIFS('BD Asistencia'!$E:$E,"h/A",'BD Asistencia'!$C:$C,'Planilla Mensual'!$D21,'BD Asistencia'!$D:$D,">="&'Planilla Mensual'!M21,'BD Asistencia'!$D:$D,"<="&'Planilla Mensual'!N21) -> 0 | Z21: =+COUNTIFS('BD Asistencia'!$H:$H,"NO REMUNERADO",'BD Asistencia'!$C:$C,'Planilla Mensual'!$D21,'BD Asistencia'!$D:$D,">="&'Planilla Mensual'!M21,'BD Asistencia'!$D:$D,"<="&'Planilla Mensual'!N21)-U21 -> 0 | AA21: =+COUNTIFS('BD Asistencia'!$E:$E,"F",'BD Asistencia'!$C:$C,'Planilla Mensual'!$D21,'BD Asistencia'!$D:$D,">="&'Planilla Mensual'!M21,'BD Asistencia'!$D:$D,"<="&'Planilla Mensual'!N21) -> 0 | AB21: =+SUM(S21:AA21) -> 15 | AC21: 3 | AR21: =+SUM(AL21:AQ21) -> 0 | AS21: =AI21-SUM(AL21:AQ21) -> 0 | AT21: =AJ21+AK21 -> 0 | AV21: =AS21+AT21 -> 0 | AZ21: =+R21*(S21+T21) -> 1200 | BB21: =+AC21*A21 -> 54 | BC21: =+AY21+AV21+AZ21+BA21+BB21 -> 1254 | BD21: =AI21+AU21+AT21+AY21+AZ21+BA21+BB21 -> 1254 | BG21: =(AV21+AY21+SUM(AL21:AQ21))/V21 -> #DIV/0! | BH21: =+(AZ21+BA21)/(S21+T21) -> 80
A22: 10 | B22: PENDIENTE | C22: 8123707 | D22: GOLINDANO MARQUEZ JUAN CARLOS | E22: 32714 | I22: BCP | J22: 57007918639078 | L22: 46158 | M22: 46143 | N22: 46157 | O22: =+TEXT(M22,"mmmm")&" - "&YEAR(M22)&MONTH(M22) -> Mayo - 20265 | P22: SI | R22: 80 | S22: =+COUNTIFS('BD Asistencia'!$E:$E,"A",'BD Asistencia'!$C:$C,'Planilla Mensual'!$D22,'BD Asistencia'!$D:$D,"<"&'Planilla Mensual'!L22) -> 7 | T22: =+COUNTIFS('BD Asistencia'!$E:$E,"DR",'BD Asistencia'!$C:$C,'Planilla Mensual'!$D22,'BD Asistencia'!$D:$D,"<"&L22) -> 4 | U22: =+COUNTIFS('BD Asistencia'!$H:$H,"NO REMUNERADO",'BD Asistencia'!$C:$C,'Planilla Mensual'!$D22,'BD Asistencia'!$D:$D,"<"&L22) -> 4 | V22: =+COUNTIFS('BD Asistencia'!$E:$E,"A",'BD Asistencia'!$C:$C,'Planilla Mensual'!$D22,'BD Asistencia'!$D:$D,">="&'Planilla Mensual'!M22,'BD Asistencia'!$D:$D,"<="&'Planilla Mensual'!N22)-S22 -> 0 | W22: =+COUNTIFS('BD Asistencia'!$E:$E,"DR",'BD Asistencia'!$C:$C,'Planilla Mensual'!$D22,'BD Asistencia'!$D:$D,">="&'Planilla Mensual'!M22,'BD Asistencia'!$D:$D,"<="&'Planilla Mensual'!N22)-T22 -> 0 | X22: =+COUNTIFS('BD Asistencia'!$E:$E,"h",'BD Asistencia'!$C:$C,'Planilla Mensual'!$D22,'BD Asistencia'!$D:$D,">="&'Planilla Mensual'!M22,'BD Asistencia'!$D:$D,"<="&'Planilla Mensual'!N22) -> 0 | Y22: =+COUNTIFS('BD Asistencia'!$E:$E,"h/A",'BD Asistencia'!$C:$C,'Planilla Mensual'!$D22,'BD Asistencia'!$D:$D,">="&'Planilla Mensual'!M22,'BD Asistencia'!$D:$D,"<="&'Planilla Mensual'!N22) -> 0 | Z22: =+COUNTIFS('BD Asistencia'!$H:$H,"NO REMUNERADO",'BD Asistencia'!$C:$C,'Planilla Mensual'!$D22,'BD Asistencia'!$D:$D,">="&'Planilla Mensual'!M22,'BD Asistencia'!$D:$D,"<="&'Planilla Mensual'!N22)-U22 -> 0 | AA22: =+COUNTIFS('BD Asistencia'!$E:$E,"F",'BD Asistencia'!$C:$C,'Planilla Mensual'!$D22,'BD Asistencia'!$D:$D,">="&'Planilla Mensual'!M22,'BD Asistencia'!$D:$D,"<="&'Planilla Mensual'!N22) -> 0 | AB22: =+SUM(S22:AA22) -> 15 | AR22: =+SUM(AL22:AQ22) -> 0 | AS22: =AI22-SUM(AL22:AQ22) -> 0 | AT22: =AJ22+AK22 -> 0 | AV22: =AS22+AT22 -> 0 | AZ22: =+R22*(S22+T22) -> 880 | BB22: =+AC22*A22 -> 0 | BC22: =+AY22+AV22+AZ22+BA22+BB22 -> 880 | BD22: =AI22+AU22+AT22+AY22+AZ22+BA22+BB22 -> 880 | BG22: =(AV22+AY22+SUM(AL22:AQ22))/V22 -> #DIV/0! | BH22: =+(AZ22+BA22)/(S22+T22) -> 80
A23: 10 | B23: PENDIENTE | D23: YUNCA ALFARO JOSE LUIS | I23: BBVA | J23: 1100300200308710 | L23: 46158 | M23: 46143 | N23: 46157 | O23: =+TEXT(M23,"mmmm")&" - "&YEAR(M23)&MONTH(M23) -> Mayo - 20265 | R23: 100 | S23: =+COUNTIFS('BD Asistencia'!$E:$E,"A",'BD Asistencia'!$C:$C,'Planilla Mensual'!$D23,'BD Asistencia'!$D:$D,"<"&'Planilla Mensual'!L23) -> 2 | T23: =+COUNTIFS('BD Asistencia'!$E:$E,"DR",'BD Asistencia'!$C:$C,'Planilla Mensual'!$D23,'BD Asistencia'!$D:$D,"<"&L23) -> 0 | U23: =+COUNTIFS('BD Asistencia'!$H:$H,"NO REMUNERADO",'BD Asistencia'!$C:$C,'Planilla Mensual'!$D23,'BD Asistencia'!$D:$D,"<"&L23) -> 13 | V23: =+COUNTIFS('BD Asistencia'!$E:$E,"A",'BD Asistencia'!$C:$C,'Planilla Mensual'!$D23,'BD Asistencia'!$D:$D,">="&'Planilla Mensual'!M23,'BD Asistencia'!$D:$D,"<="&'Planilla Mensual'!N23)-S23 -> 0 | W23: =+COUNTIFS('BD Asistencia'!$E:$E,"DR",'BD Asistencia'!$C:$C,'Planilla Mensual'!$D23,'BD Asistencia'!$D:$D,">="&'Planilla Mensual'!M23,'BD Asistencia'!$D:$D,"<="&'Planilla Mensual'!N23)-T23 -> 0 | X23: =+COUNTIFS('BD Asistencia'!$E:$E,"h",'BD Asistencia'!$C:$C,'Planilla Mensual'!$D23,'BD Asistencia'!$D:$D,">="&'Planilla Mensual'!M23,'BD Asistencia'!$D:$D,"<="&'Planilla Mensual'!N23) -> 0 | Y23: =+COUNTIFS('BD Asistencia'!$E:$E,"h/A",'BD Asistencia'!$C:$C,'Planilla Mensual'!$D23,'BD Asistencia'!$D:$D,">="&'Planilla Mensual'!M23,'BD Asistencia'!$D:$D,"<="&'Planilla Mensual'!N23) -> 0 | Z23: =+COUNTIFS('BD Asistencia'!$H:$H,"NO REMUNERADO",'BD Asistencia'!$C:$C,'Planilla Mensual'!$D23,'BD Asistencia'!$D:$D,">="&'Planilla Mensual'!M23,'BD Asistencia'!$D:$D,"<="&'Planilla Mensual'!N23)-U23 -> 0 | AA23: =+COUNTIFS('BD Asistencia'!$E:$E,"F",'BD Asistencia'!$C:$C,'Planilla Mensual'!$D23,'BD Asistencia'!$D:$D,">="&'Planilla Mensual'!M23,'BD Asistencia'!$D:$D,"<="&'Planilla Mensual'!N23) -> 0 | AB23: =+SUM(S23:AA23) -> 15 | AC23: 1 | AR23: =+SUM(AL23:AQ23) -> 0 | AS23: =AI23-SUM(AL23:AQ23) -> 0 | AT23: =AJ23+AK23 -> 0 | AV23: =AS23+AT23 -> 0 | AZ23: =+R23*(S23+T23) -> 200 | BB23: =+AC23*A23 -> 10 | BC23: =+AY23+AV23+AZ23+BA23+BB23 -> 210 | BD23: =AI23+AU23+AT23+AY23+AZ23+BA23+BB23 -> 210 | BG23: =(AV23+AY23+SUM(AL23:AQ23))/V23 -> #DIV/0! | BH23: =+(AZ23+BA23)/(S23+T23) -> 100
