Workbook

Sheet Planilla Mensual
M1: Periodo | S1: Sin planilla | V1: Planilla | AK1: No remunerativo | AM1: Aportes del trabajador | AQ1: Adelantos y descuentos | AW1: Aporte empleador
A2: Valor HE | B2: TIPO | C2: DNI | D2: Apellidos y nombres | E2: F. Nacimiento | F2: Puesto | G2: AFP/ONP | H2: CUSPP | I2: Banco | J2: Cuenta | K2: CCI | L2: F. Ingreso | M2: F. INICIO | N2: F.FIN | O2: Periodo | P2: Asig Familiar (SI/NO) | Q2: Basico | R2: Basico sin planilla | S2: Asistencia | T2: Descanso pagado | U2: No remunerado | V2: Dias Trab | W2: Vacaciones | X2: Días descanso pagado | Y2: Feriado | Z2: Feriado laborado | AA2: Dias no laborados | AB2: Falta Descuento bono | AC2: TOTAL | AD2: Horas extras | AE2: Monto basico | AF2: Monto Asig | AG2: Feriado laborado | AH2: Bono asistencia | AI2: Bono Horas | AJ2: Rem Bruta | AK2: Movilidad | AL2: Viaticos | AM2: AFP (10%) | AN2: Seg. AFP (1.37%) | AO2: ONP | AP2: Renta 5ta | AQ2: Otros Descuentos | AR2: Adelantos viaticos | AS2: Adelanto quincena | AT2: Total descuentos | AU2: Neto | AV2: Total No Rem | AW2: EsSalud (9%) | AX2: Total a Pagar Planilla | AY2: F. Cese | AZ2: Correo | BB2: Extra mes | BC2: Extra pagar | BD2: Basico Sin planilla | BE2: Viaticos sin planilla | BF2: Hora Extra | BG2: Total 1Q | BH2: Adelanto quincena sin planilla | BI2: Total Trabajador | BJ2: Costo Empresa
B3: PLANILLA | C3: 42878934 | D3: REQUELME BACON CESAR DAVID | E3: 31058 | F3: Operador de Maquinaria Agricola N3 | G3: SPP INTEGRA | H3: 610561CRBUO0 | I3: BCP | J3: 57016231766077 | L3: 46128 | M3: 46128 | N3: 46142 | O3: =+TEXT(M3,"mmmm")&" - "&YEAR(M3)&MONTH(M3) -> Abril - 20264 | P3: SI | Q3: 1300 | S3: 0 | T3: 0 | U3: 0 | V3: 9 | X3: 5 | Y3: =+COUNTIFS('[1]BD Asistencia'!$E:$E,"F",'[1]BD Asistencia'!$C:$C,'Planilla Mensual'!$D3,'[1]BD Asistencia'!$D:$D,">="&'Planilla Mensual'!M3,'[1]BD Asistencia'!$D:$D,"<="&'Planilla Mensual'!N3) -> 0 | Z3: =+COUNTIFS('[1]BD Asistencia'!$E:$E,"F/A",'[1]BD Asistencia'!$C:$C,'Planilla Mensual'!$D3,'[1]BD Asistencia'!$D:$D,">="&'Planilla Mensual'!M3,'[1]BD Asistencia'!$D:$D,"<="&'Planilla Mensual'!N3) -> 0 | AA3: 1 | AC3: =+SUM(S3:AA3) -> 15 | AE3: =+Q3/30*SUM(V3:Z3) -> 606.66667 | AF3: =IF(P3="SI",113,0) -> 113 | AG3: =+(Q3/30*Z3)*2 -> 0 | AH3: 200 | AJ3: =+SUM(AE3:AH3) -> 919.66667 | AK3: =+V3*IF(RIGHT(F3,2)="N3",16,IF(RIGHT(F3,2)="N2",8,4)) -> 144 | AL3: =V3*30 -> 270 | AM3: =IF(G3="ONP",0,AJ3*0.1) -> 91.966667 | AN3: =IF(G3="ONP",0,AJ3*1.37%) -> 12.599433 | AO3: =+IF(G3="ONP",AJ3*0.13,0) -> 0 | AP3: 0 | AQ3: 250 | AR3: 140 | AS3: 0 | AT3: =+SUM(AM3:AS3) -> 494.5661 | AU3: =AJ3-SUM(AM3:AS3) -> 425.10057 | AV3: =AK3+AL3 -> 414 | AW3: =IF(AJ3*0.09<1130*0.09,1130*0.09,AJ3*0.09) -> 101.7 | AX3: =AU3+AV3 -> 839.10057 | AZ3: cesarrequelmeb@gmail.com | BB3: =+IF(RIGHT(F3,2)="N3",300,0) -> 300 | BC3: 150 | BD3: =+R3*S3 -> 0 | BE3: =+S3*30 -> 0 | BG3: 989.10057 | BH3: =+BG3-AS3 -> 989.10057 | BI3: =+BC3+AX3+BD3+BE3+BF3-BH3 -> 0 | BJ3: =AJ3+AW3+AV3+BC3+BD3+BE3 -> 1585.3667 | BK3: =+BJ3/(V3+S3+X3) -> 113.24048 | BL3: =+BK3-25 -> 88.240476
A4: 15 | B4: PLANILLA | C4: 42878934 | D4: REQUELME BACON CESAR DAVID | E4: 31058 | F4: Operador de Maquinaria Agricola N3 | G4: SPP INTEGRA | H4: 610561CRBUO0 | I4: BCP | J4: 57016231766077 | L4: 46128 | M4: 46143 | N4: 46172 | O4: =+TEXT(M4,"mmmm")&" - "&YEAR(M4)&MONTH(M4) -> Mayo - 20265 | P4: SI | Q4: 1300 | S4: =+COUNTIFS('[1]BD Asistencia'!$E:$E,"A",'[1]BD Asistencia'!$C:$C,'Planilla Mensual'!$D4,'[1]BD Asistencia'!$D:$D,"<"&'Planilla Mensual'!L4) -> 0 | T4: =+COUNTIFS('[1]BD Asistencia'!$E:$E,"DR",'[1]BD Asistencia'!$C:$C,'Planilla Mensual'!$D4,'[1]BD Asistencia'!$D:$D,"<"&L4) -> 0 | U4: =+COUNTIFS('[1]BD Asistencia'!$H:$H,"NO REMUNERADO",'[1]BD Asistencia'!$C:$C,'Planilla Mensual'!$D4,'[1]BD Asistencia'!$D:$D,"<"&L4) -> #VALUE! | V4: =+COUNTIFS('[1]BD Asistencia'!$E:$E,"A",'[1]BD Asistencia'!$C:$C,'Planilla Mensual'!$D4,'[1]BD Asistencia'!$D:$D,">="&'Planilla Mensual'!M4,'[1]BD Asistencia'!$D:$D,"<="&'Planilla Mensual'!N4)-S4 -> 18 | W4: =+COUNTIFS('[1]BD Asistencia'!$E:$E,"V",'[1]BD Asistencia'!$C:$C,'Planilla Mensual'!$D4,'[1]BD Asistencia'!$D:$D,">="&'Planilla Mensual'!M4,'[1]BD Asistencia'!$D:$D,"<="&'Planilla Mensual'!N4) -> 7 | X4: =+COUNTIFS('[1]BD Asistencia'!$E:$E,"DR",'[1]BD Asistencia'!$C:$C,'Planilla Mensual'!$D4,'[1]BD Asistencia'!$D:$D,">="&'Planilla Mensual'!M4,'[1]BD Asistencia'!$D:$D,"<="&'Planilla Mensual'!N4)-T4 -> 4 | Y4: =+COUNTIFS('[1]BD Asistencia'!$E:$E,"h",'[1]BD Asistencia'!$C:$C,'Planilla Mensual'!$D4,'[1]BD Asistencia'!$D:$D,">="&'Planilla Mensual'!M4,'[1]BD Asistencia'!$D:$D,"<="&'Planilla Mensual'!N4) -> 1 | Z4: =+COUNTIFS('[1]BD Asistencia'!$E:$E,"h/A",'[1]BD Asistencia'!$C:$C,'Planilla Mensual'!$D4,'[1]BD Asistencia'!$D:$D,">="&'Planilla Mensual'!M4,'[1]BD Asistencia'!$D:$D,"<="&'Planilla Mensual'!N4) -> 0 | AA4: =+COUNTIFS('[1]BD Asistencia'!$H:$H,"NO REMUNERADO",'[1]BD Asistencia'!$C:$C,'Planilla Mensual'!$D4,'[1]BD Asistencia'!$D:$D,">="&'Planilla Mensual'!M4,'[1]BD Asistencia'!$D:$D,"<="&'Planilla Mensual'!N4)-U4 -> #VALUE! | AB4: =+COUNTIFS('[1]BD Asistencia'!$E:$E,"F",'[1]BD Asistencia'!$C:$C,'Planilla Mensual'!$D4,'[1]BD Asistencia'!$D:$D,">="&'Planilla Mensual'!M4,'[1]BD Asistencia'!$D:$D,"<="&'Planilla Mensual'!N4) -> 0 | AC4: =+SUM(S4:AB4) -> #VALUE! | AD4: 5 | AE4: =+Q4/30*SUM(V4:Z4) -> 1300 | AF4: =IF(P4="SI",113,0) -> 113 | AG4: =+(Q4/30*Z4)*2 -> 0 | AH4: 400 | AI4: =+AD4*A4 -> 75 | AJ4: =+SUM(AE4:AI4) -> 1888 | AK4: =+V4*IF(RIGHT(F4,2)="N3",16,IF(RIGHT(F4,2)="N2",8,4)) -> 288 | AL4: =V4*30 -> 540 | AM4: =IF(G4="ONP",0,AJ4*0.1) -> 188.8 | AN4: =IF(G4="ONP",0,AJ4*1.37%) -> 25.8656 | AO4: =+IF(G4="ONP",AJ4*0.13,0) -> 0 | AP4: 0 | AQ4: 500 | AR4: 0 | AS4: 1231.1979 | AT4: =+SUM(AM4:AS4) -> 1945.8636 | AU4: =AJ4-SUM(AM4:AS4) -> -57.86355 | AV4: =AK4+AL4 -> 828 | AW4: =IF(AJ4*0.09<1130*0.09,1130*0.09,AJ4*0.09) -> 169.92 | AX4: =AU4+AV4 -> 770.13645 | AZ4: cesarrequelmeb@gmail.com | BB4: =+IF(RIGHT(F4,2)="N3",300,0) -> 300 | BC4: =+BB4/30*SUM(V4:Z4) -> 300 | BD4: =+R4*S4 -> 0 | BE4: =+S4*30 -> 0 | BG4: 1381.1979 | BH4: =+BG4-AS4 -> 150 | BI4: =+BC4+AX4+BD4+BE4+BF4-BH4 -> 920.13645 | BJ4: =AJ4+AW4+AV4+BC4+BD4+BE4+BF4 -> 3185.92 | BK4: =+BJ4/(V4+S4+X4) -> 144.81455 | BL4: =+BK4-25 -> 119.81455
A5: 15 | B5: PLANILLA | C5: 70751973 | D5: CONCEPCIÓN ZEVALLOS ARMANDO | E5: 34913 | F5: Operador de Maquinaria Agricola N3 | G5: ONP | I5: BCP | J5: 57071021755000 | L5: 46146 | M5: 46143 | N5: 46172 | O5: =+TEXT(M5,"mmmm")&" - "&YEAR(M5)&MONTH(M5) -> Mayo - 20265 | P5: SI | Q5: 1300 | R5: 110 | S5: =+COUNTIFS('[1]BD Asistencia'!$E:$E,"A",'[1]BD Asistencia'!$C:$C,'Planilla Mensual'!$D5,'[1]BD Asistencia'!$D:$D,"<"&'Planilla Mensual'!L5) -> 2 | T5: =+COUNTIFS('[1]BD Asistencia'!$E:$E,"DR",'[1]BD Asistencia'!$C:$C,'Planilla Mensual'!$D5,'[1]BD Asistencia'!$D:$D,"<"&L5) -> 0 | U5: =+COUNTIFS('[1]BD Asistencia'!$H:$H,"NO REMUNERADO",'[1]BD Asistencia'!$C:$C,'Planilla Mensual'!$D5,'[1]BD Asistencia'!$D:$D,"<"&L5) -> #VALUE! | V5: =+COUNTIFS('[1]BD Asistencia'!$E:$E,"A",'[1]BD Asistencia'!$C:$C,'Planilla Mensual'!$D5,'[1]BD Asistencia'!$D:$D,">="&'Planilla Mensual'!M5,'[1]BD Asistencia'!$D:$D,"<="&'Planilla Mensual'!N5)-S5 -> 24 | W5: =+COUNTIFS('[1]BD Asistencia'!$E:$E,"V",'[1]BD Asistencia'!$C:$C,'Planilla Mensual'!$D5,'[1]BD Asistencia'!$D:$D,">="&'Planilla Mensual'!M5,'[1]BD Asistencia'!$D:$D,"<="&'Planilla Mensual'!N5) -> 0 | X5: =+COUNTIFS('[1]BD Asistencia'!$E:$E,"DR",'[1]BD Asistencia'!$C:$C,'Planilla Mensual'!$D5,'[1]BD Asistencia'!$D:$D,">="&'Planilla Mensual'!M5,'[1]BD Asistencia'!$D:$D,"<="&'Planilla Mensual'!N5)-T5 -> 3 | Y5: =+COUNTIFS('[1]BD Asistencia'!$E:$E,"h",'[1]BD Asistencia'!$C:$C,'Planilla Mensual'!$D5,'[1]BD Asistencia'!$D:$D,">="&'Planilla Mensual'!M5,'[1]BD Asistencia'!$D:$D,"<="&'Planilla Mensual'!N5) -> 0 | Z5: =+COUNTIFS('[1]BD Asistencia'!$E:$E,"h/A",'[1]BD Asistencia'!$C:$C,'Planilla Mensual'!$D5,'[1]BD Asistencia'!$D:$D,">="&'Planilla Mensual'!M5,'[1]BD Asistencia'!$D:$D,"<="&'Planilla Mensual'!N5) -> 0 | AA5: =+COUNTIFS('[1]BD Asistencia'!$H:$H,"NO REMUNERADO",'[1]BD Asistencia'!$C:$C,'Planilla Mensual'!$D5,'[1]BD Asistencia'!$D:$D,">="&'Planilla Mensual'!M5,'[1]BD Asistencia'!$D:$D,"<="&'Planilla Mensual'!N5)-U5 -> #VALUE! | AB5: =+COUNTIFS('[1]BD Asistencia'!$E:$E,"F",'[1]BD Asistencia'!$C:$C,'Planilla Mensual'!$D5,'[1]BD Asistencia'!$D:$D,">="&'Planilla Mensual'!M5,'[1]BD Asistencia'!$D:$D,"<="&'Planilla Mensual'!N5) -> 0 | AC5: =+SUM(S5:AB5) -> #VALUE! | AD5: 3.1 | AE5: =+Q5/30*SUM(V5:Z5) -> 1170 | AF5: =IF(P5="SI",113,0) -> 113 | AG5: =+(Q5/30*Z5)*2 -> 0 | AH5: 400 | AI5: =+AD5*A5 -> 46.5 | AJ5: =+SUM(AE5:AI5) -> 1729.5 | AK5: =+V5*IF(RIGHT(F5,2)="N3",16,IF(RIGHT(F5,2)="N2",8,4)) -> 384 | AL5: =V5*30 -> 720 | AM5: =IF(G5="ONP",0,AJ5*0.1) -> 0 | AN5: =IF(G5="ONP",0,AJ5*1.37%) -> 0 | AO5: =+IF(G5="ONP",AJ5*0.13,0) -> 224.835 | AP5: 0 | AR5: 0 | AS5: 1191.995 | AT5: =+SUM(AM5:AS5) -> 1416.83 | AU5: =AJ5-SUM(AM5:AS5) -> 312.67 | AV5: =AK5+AL5 -> 1104 | AW5: =IF(AJ5*0.09<1130*0.09,1130*0.09,AJ5*0.09) -> 155.655 | AX5: =AU5+AV5 -> 1416.67 | AZ5: Armancz9091@gmail.com | BB5: =+IF(RIGHT(F5,2)="N3",300,0) -> 300 | BC5: =+BB5/30*SUM(V5:Z5) -> 270 | BD5: =+R5*S5 -> 220 | BE5: =+S5*30 -> 60 | BG5: 1591.995 | BH5: =+BG5-AS5 -> 400 | BI5: =+BC5+AX5+BD5+BE5+BF5-BH5 -> 1566.67 | BJ5: =AJ5+AW5+AV5+BC5+BD5+BE5+BF5 -> 3539.155 | BK5: =+BJ5/(V5+S5) -> 136.12135 | BL5: =+BK5-30 -> 106.12135
A6: 15 | B6: PLANILLA | C6: 75792147 | D6: TERRONES JARA FREDY | E6: 38228 | F6: Operador de Maquinaria Agricola N3 | G6: SPP INTEGRA | H6: 682261FTJRA0 | I6: BCP | J6: 57098711252088 | L6: 46146 | M6: 46143 | N6: 46173 | O6: =+TEXT(M6,"mmmm")&" - "&YEAR(M6)&MONTH(M6) -> Mayo - 20265 | P6: NO | Q6: 1300 | R6: 120 | S6: =+COUNTIFS('[1]BD Asistencia'!$E:$E,"A",'[1]BD Asistencia'!$C:$C,'Planilla Mensual'!$D6,'[1]BD Asistencia'!$D:$D,"<"&'Planilla Mensual'!L6) -> 1 | T6: =+COUNTIFS('[1]BD Asistencia'!$E:$E,"DR",'[1]BD Asistencia'!$C:$C,'Planilla Mensual'!$D6,'[1]BD Asistencia'!$D:$D,"<"&L6) -> 0 | U6: =+COUNTIFS('[1]BD Asistencia'!$H:$H,"NO REMUNERADO",'[1]BD Asistencia'!$C:$C,'Planilla Mensual'!$D6,'[1]BD Asistencia'!$D:$D,"<"&L6) -> #VALUE! | V6: =+COUNTIFS('[1]BD Asistencia'!$E:$E,"A",'[1]BD Asistencia'!$C:$C,'Planilla Mensual'!$D6,'[1]BD Asistencia'!$D:$D,">="&'Planilla Mensual'!M6,'[1]BD Asistencia'!$D:$D,"<="&'Planilla Mensual'!N6)-S6 -> 24 | W6: =+COUNTIFS('[1]BD Asistencia'!$E:$E,"V",'[1]BD Asistencia'!$C:$C,'Planilla Mensual'!$D6,'[1]BD Asistencia'!$D:$D,">="&'Planilla Mensual'!M6,'[1]BD Asistencia'!$D:$D,"<="&'Planilla Mensual'!N6) -> 0 | X6: =+COUNTIFS('[1]BD Asistencia'!$E:$E,"DR",'[1]BD Asistencia'!$C:$C,'Planilla Mensual'!$D6,'[1]BD Asistencia'!$D:$D,">="&'Planilla Mensual'!M6,'[1]BD Asistencia'!$D:$D,"<="&'Planilla Mensual'!N6)-T6 -> 3 | Y6: =+COUNTIFS('[1]BD Asistencia'!$E:$E,"h",'[1]BD Asistencia'!$C:$C,'Planilla Mensual'!$D6,'[1]BD Asistencia'!$D:$D,">="&'Planilla Mensual'!M6,'[1]BD Asistencia'!$D:$D,"<="&'Planilla Mensual'!N6) -> 0 | Z6: =+COUNTIFS('[1]BD Asistencia'!$E:$E,"h/A",'[1]BD Asistencia'!$C:$C,'Planilla Mensual'!$D6,'[1]BD Asistencia'!$D:$D,">="&'Planilla Mensual'!M6,'[1]BD Asistencia'!$D:$D,"<="&'Planilla Mensual'!N6) -> 1 | AA6: =+COUNTIFS('[1]BD Asistencia'!$H:$H,"NO REMUNERADO",'[1]BD Asistencia'!$C:$C,'Planilla Mensual'!$D6,'[1]BD Asistencia'!$D:$D,">="&'Planilla Mensual'!M6,'[1]BD Asistencia'!$D:$D,"<="&'Planilla Mensual'!N6)-U6 -> #VALUE! | AB6: =+COUNTIFS('[1]BD Asistencia'!$E:$E,"F",'[1]BD Asistencia'!$C:$C,'Planilla Mensual'!$D6,'[1]BD Asistencia'!$D:$D,">="&'Planilla Mensual'!M6,'[1]BD Asistencia'!$D:$D,"<="&'Planilla Mensual'!N6) -> 0 | AC6: =+SUM(S6:AB6) -> #VALUE! | AD6: 8.3 | AE6: =+Q6/30*SUM(V6:Z6) -> 1213.3333 | AF6: =IF(P6="SI",113,0) -> 0 | AG6: =+(Q6/30*Z6)*2 -> 86.666667 | AH6: 400 | AI6: =+AD6*A6 -> 124.5 | AJ6: =+SUM(AE6:AI6) -> 1824.5 | AK6: =+V6*IF(RIGHT(F6,2)="N3",16,IF(RIGHT(F6,2)="N2",8,4)) -> 384 | AL6: =V6*30 -> 720 | AM6: =IF(G6="ONP",0,AJ6*0.1) -> 182.45 | AN6: =IF(G6="ONP",0,AJ6*1.37%) -> 24.99565 | AO6: =+IF(G6="ONP",AJ6*0.13,0) -> 0 | AP6: 0 | AR6: 0 | AS6: 1227.8913 | AT6: =+SUM(AM6:AS6) -> 1435.337 | AU6: =AJ6-SUM(AM6:AS6) -> 389.163 | AV6: =AK6+AL6 -> 1104 | AW6: =IF(AJ6*0.09<1130*0.09,1130*0.09,AJ6*0.09) -> 164.205 | AX6: =AU6+AV6 -> 1493.163 | AZ6: Fredyterrones4@gmail.com | BB6: =+IF(RIGHT(F6,2)="N3",300,0) -> 300 | BC6: =+BB6/30*SUM(V6:Z6) -> 280 | BD6: =+R6*S6 -> 120 | BE6: =+S6*30 -> 30 | BG6: 1497.8913 | BH6: =+BG6-AS6 -> 270 | BI6: =+BC6+AX6+BD6+BE6+BF6-BH6 -> 1653.163 | BJ6: =AJ6+AW6+AV6+BC6+BD6+BE6+BF6 -> 3522.705 | BK6: =+BJ6/(V6+S6) -> 140.9082 | BL6: =+BK6-30 -> 110.9082
A7: 15 | B7: PLANILLA | C7: 74242456 | D7: MONTOYA NAMOC JORGE LUIS | E7: 37386 | F7: Operador de Maquinaria Agricola N3 | G7: SPP INTEGRA | H7: 673841JMNTO4 | I7: BCP | J7: 57016070300081 | L7: 46146 | M7: 46143 | N7: 46172 | O7: =+TEXT(M7,"mmmm")&" - "&YEAR(M7)&MONTH(M7) -> Mayo - 20265 | P7: NO | Q7: 1300 | R7: 110 | S7: =+COUNTIFS('[1]BD Asistencia'!$E:$E,"A",'[1]BD Asistencia'!$C:$C,'Planilla Mensual'!$D7,'[1]BD Asistencia'!$D:$D,"<"&'Planilla Mensual'!L7) -> 2 | T7: =+COUNTIFS('[1]BD Asistencia'!$E:$E,"DR",'[1]BD Asistencia'!$C:$C,'Planilla Mensual'!$D7,'[1]BD Asistencia'!$D:$D,"<"&L7) -> 0 | U7: =+COUNTIFS('[1]BD Asistencia'!$H:$H,"NO REMUNERADO",'[1]BD Asistencia'!$C:$C,'Planilla Mensual'!$D7,'[1]BD Asistencia'!$D:$D,"<"&L7) -> #VALUE! | V7: =+COUNTIFS('[1]BD Asistencia'!$E:$E,"A",'[1]BD Asistencia'!$C:$C,'Planilla Mensual'!$D7,'[1]BD Asistencia'!$D:$D,">="&'Planilla Mensual'!M7,'[1]BD Asistencia'!$D:$D,"<="&'Planilla Mensual'!N7)-S7 -> 24 | W7: =+COUNTIFS('[1]BD Asistencia'!$E:$E,"V",'[1]BD Asistencia'!$C:$C,'Planilla Mensual'!$D7,'[1]BD Asistencia'!$D:$D,">="&'Planilla Mensual'!M7,'[1]BD Asistencia'!$D:$D,"<="&'Planilla Mensual'!N7) -> 0 | X7: =+COUNTIFS('[1]BD Asistencia'!$E:$E,"DR",'[1]BD Asistencia'!$C:$C,'Planilla Mensual'!$D7,'[1]BD Asistencia'!$D:$D,">="&'Planilla Mensual'!M7,'[1]BD Asistencia'!$D:$D,"<="&'Planilla Mensual'!N7)-T7 -> 3 | Y7: =+COUNTIFS('[1]BD Asistencia'!$E:$E,"h",'[1]BD Asistencia'!$C:$C,'Planilla Mensual'!$D7,'[1]BD Asistencia'!$D:$D,">="&'Planilla Mensual'!M7,'[1]BD Asistencia'!$D:$D,"<="&'Planilla Mensual'!N7) -> 0 | Z7: =+COUNTIFS('[1]BD Asistencia'!$E:$E,"h/A",'[1]BD Asistencia'!$C:$C,'Planilla Mensual'!$D7,'[1]BD Asistencia'!$D:$D,">="&'Planilla Mensual'!M7,'[1]BD Asistencia'!$D:$D,"<="&'Planilla Mensual'!N7) -> 0 | AA7: =+COUNTIFS('[1]BD Asistencia'!$H:$H,"NO REMUNERADO",'[1]BD Asistencia'!$C:$C,'Planilla Mensual'!$D7,'[1]BD Asistencia'!$D:$D,">="&'Planilla Mensual'!M7,'[1]BD Asistencia'!$D:$D,"<="&'Planilla Mensual'!N7)-U7 -> #VALUE! | AB7: =+COUNTIFS('[1]BD Asistencia'!$E:$E,"F",'[1]BD Asistencia'!$C:$C,'Planilla Mensual'!$D7,'[1]BD Asistencia'!$D:$D,">="&'Planilla Mensual'!M7,'[1]BD Asistencia'!$D:$D,"<="&'Planilla Mensual'!N7) -> 0 | AC7: =+SUM(S7:AB7) -> #VALUE! | AD7: 4.1 | AE7: =+Q7/30*SUM(V7:Z7) -> 1170 | AF7: =IF(P7="SI",113,0) -> 0 | AG7: =+(Q7/30*Z7)*2 -> 0 | AH7: 400 | AI7: =+AD7*A7 -> 61.5 | AJ7: =+SUM(AE7:AI7) -> 1631.5 | AK7: =+V7*IF(RIGHT(F7,2)="N3",16,IF(RIGHT(F7,2)="N2",8,4)) -> 384 | AL7: =V7*30 -> 720 | AM7: =IF(G7="ONP",0,AJ7*0.1) -> 163.15 | AN7: =IF(G7="ONP",0,AJ7*1.37%) -> 22.35155 | AO7: =+IF(G7="ONP",AJ7*0.13,0) -> 0 | AP7: 0 | AR7: 0 | AS7: 1154.7716 | AT7: =+SUM(AM7:AS7) -> 1340.2731 | AU7: =AJ7-SUM(AM7:AS7) -> 291.22685 | AV7: =AK7+AL7 -> 1104 | AW7: =IF(AJ7*0.09<1130*0.09,1130*0.09,AJ7*0.09) -> 146.835 | AX7: =AU7+AV7 -> 1395.2269 | AZ7: jorgemontoyanamoc@gmail.com | BB7: =+IF(RIGHT(F7,2)="N3",300,0) -> 300 | BC7: =+BB7/30*SUM(V7:Z7) -> 270 | BD7: =+R7*S7 -> 220 | BE7: =+S7*30 -> 60 | BG7: 1554.7716 | BH7: =+BG7-AS7 -> 400 | BI7: =+BC7+AX7+BD7+BE7+BF7-BH7 -> 1545.2269 | BJ7: =AJ7+AW7+AV7+BC7+BD7+BE7+BF7 -> 3432.335 | BK7: =+BJ7/(V7+S7) -> 132.01288 | BL7: =+BK7-30 -> 102.01288
A8: 15 | B8: PLANILLA | C8: 48787545 | D8: DIAZ DIAZ JUNNIOR | E8: 34609 | F8: Operador de Maquinaria Agricola N3 | G8: SPP PRIMA | H8: 646071JDDZZ4 | I8: BCP | J8: 30071590047060 | L8: 46146 | M8: 46143 | N8: 46172 | O8: =+TEXT(M8,"mmmm")&" - "&YEAR(M8)&MONTH(M8) -> Mayo - 20265 | P8: SI | Q8: 1300 | R8: 100 | S8: =+COUNTIFS('[1]BD Asistencia'!$E:$E,"A",'[1]BD Asistencia'!$C:$C,'Planilla Mensual'!$D8,'[1]BD Asistencia'!$D:$D,"<"&'Planilla Mensual'!L8) -> 1 | T8: =+COUNTIFS('[1]BD Asistencia'!$E:$E,"DR",'[1]BD Asistencia'!$C:$C,'Planilla Mensual'!$D8,'[1]BD Asistencia'!$D:$D,"<"&L8) -> 0 | U8: =+COUNTIFS('[1]BD Asistencia'!$H:$H,"NO REMUNERADO",'[1]BD Asistencia'!$C:$C,'Planilla Mensual'!$D8,'[1]BD Asistencia'!$D:$D,"<"&L8) -> #VALUE! | V8: =+COUNTIFS('[1]BD Asistencia'!$E:$E,"A",'[1]BD Asistencia'!$C:$C,'Planilla Mensual'!$D8,'[1]BD Asistencia'!$D:$D,">="&'Planilla Mensual'!M8,'[1]BD Asistencia'!$D:$D,"<="&'Planilla Mensual'!N8)-S8 -> 24 | W8: =+COUNTIFS('[1]BD Asistencia'!$E:$E,"V",'[1]BD Asistencia'!$C:$C,'Planilla Mensual'!$D8,'[1]BD Asistencia'!$D:$D,">="&'Planilla Mensual'!M8,'[1]BD Asistencia'!$D:$D,"<="&'Planilla Mensual'!N8) -> 0 | X8: =+COUNTIFS('[1]BD Asistencia'!$E:$E,"DR",'[1]BD Asistencia'!$C:$C,'Planilla Mensual'!$D8,'[1]BD Asistencia'!$D:$D,">="&'Planilla Mensual'!M8,'[1]BD Asistencia'!$D:$D,"<="&'Planilla Mensual'!N8)-T8 -> 3 | Y8: =+COUNTIFS('[1]BD Asistencia'!$E:$E,"h",'[1]BD Asistencia'!$C:$C,'Planilla Mensual'!$D8,'[1]BD Asistencia'!$D:$D,">="&'Planilla Mensual'!M8,'[1]BD Asistencia'!$D:$D,"<="&'Planilla Mensual'!N8) -> 0 | Z8: =+COUNTIFS('[1]BD Asistencia'!$E:$E,"h/A",'[1]BD Asistencia'!$C:$C,'Planilla Mensual'!$D8,'[1]BD Asistencia'!$D:$D,">="&'Planilla Mensual'!M8,'[1]BD Asistencia'!$D:$D,"<="&'Planilla Mensual'!N8) -> 0 | AA8: =+COUNTIFS('[1]BD Asistencia'!$H:$H,"NO REMUNERADO",'[1]BD Asistencia'!$C:$C,'Planilla Mensual'!$D8,'[1]BD Asistencia'!$D:$D,">="&'Planilla Mensual'!M8,'[1]BD Asistencia'!$D:$D,"<="&'Planilla Mensual'!N8)-U8 -> #VALUE! | AB8: =+COUNTIFS('[1]BD Asistencia'!$E:$E,"F",'[1]BD Asistencia'!$C:$C,'Planilla Mensual'!$D8,'[1]BD Asistencia'!$D:$D,">="&'Planilla Mensual'!M8,'[1]BD Asistencia'!$D:$D,"<="&'Planilla Mensual'!N8) -> 0 | AC8: =+SUM(S8:AB8) -> #VALUE! | AD8: 13.9 | AE8: =+Q8/30*SUM(V8:Z8) -> 1170 | AF8: =IF(P8="SI",113,0) -> 113 | AG8: =+(Q8/30*Z8)*2 -> 0 | AH8: 400 | AI8: =+AD8*A8 -> 208.5 | AJ8: =+SUM(AE8:AI8) -> 1891.5 | AK8: =+V8*IF(RIGHT(F8,2)="N3",16,IF(RIGHT(F8,2)="N2",8,4)) -> 384 | AL8: =V8*30 -> 720 | AM8: =IF(G8="ONP",0,AJ8*0.1) -> 189.15 | AN8: =IF(G8="ONP",0,AJ8*1.37%) -> 25.91355 | AO8: =+IF(G8="ONP",AJ8*0.13,0) -> 0 | AP8: 0 | AR8: 100 | AS8: 1254.0372 | AT8: =+SUM(AM8:AS8) -> 1569.1008 | AU8: =AJ8-SUM(AM8:AS8) -> 322.39925 | AV8: =AK8+AL8 -> 1104 | AW8: =IF(AJ8*0.09<1130*0.09,1130*0.09,AJ8*0.09) -> 170.235 | AX8: =AU8+AV8 -> 1426.3992 | AZ8: diazdiazjunnior@gmail.com | BB8: =+IF(RIGHT(F8,2)="N3",300,0) -> 300 | BC8: =+BB8/30*SUM(V8:Z8) -> 270 | BD8: =+R8*S8 -> 100 | BE8: =+S8*30 -> 30 | BG8: 1504.0372 | BH8: =+BG8-AS8 -> 250 | BI8: =+BC8+AX8+BD8+BE8+BF8-BH8 -> 1576.3992 | BJ8: =AJ8+AW8+AV8+BC8+BD8+BE8+BF8 -> 3565.735 | BK8: =+BJ8/(V8+S8) -> 142.6294 | BL8: =+BK8-30 -> 112.6294
A9: 15 | B9: PLANILLA | C9: 73814026 | D9: SIFUENTES PAREDES EDUARDO JAVIER | E9: 36718 | F9: Operador de Maquinaria Agricola N1 | G9: SPP INTEGRA | H9: 667161ESPUE1 | I9: BCP | J9: 19277856288012 | L9: 46146 | M9: 46143 | N9: 46172 | O9: =+TEXT(M9,"mmmm")&" - "&YEAR(M9)&MONTH(M9) -> Mayo - 20265 | P9: SI | Q9: 1200 | R9: 80 | S9: =+COUNTIFS('[1]BD Asistencia'!$E:$E,"A",'[1]BD Asistencia'!$C:$C,'Planilla Mensual'!$D9,'[1]BD Asistencia'!$D:$D,"<"&'Planilla Mensual'!L9) -> 2 | T9: =+COUNTIFS('[1]BD Asistencia'!$E:$E,"DR",'[1]BD Asistencia'!$C:$C,'Planilla Mensual'!$D9,'[1]BD Asistencia'!$D:$D,"<"&L9) -> 0 | U9: =+COUNTIFS('[1]BD Asistencia'!$H:$H,"NO REMUNERADO",'[1]BD Asistencia'!$C:$C,'Planilla Mensual'!$D9,'[1]BD Asistencia'!$D:$D,"<"&L9) -> #VALUE! | V9: =+COUNTIFS('[1]BD Asistencia'!$E:$E,"A",'[1]BD Asistencia'!$C:$C,'Planilla Mensual'!$D9,'[1]BD Asistencia'!$D:$D,">="&'Planilla Mensual'!M9,'[1]BD Asistencia'!$D:$D,"<="&'Planilla Mensual'!N9)-S9 -> 24 | W9: =+COUNTIFS('[1]BD Asistencia'!$E:$E,"V",'[1]BD Asistencia'!$C:$C,'Planilla Mensual'!$D9,'[1]BD Asistencia'!$D:$D,">="&'Planilla Mensual'!M9,'[1]BD Asistencia'!$D:$D,"<="&'Planilla Mensual'!N9) -> 0 | X9: =+COUNTIFS('[1]BD Asistencia'!$E:$E,"DR",'[1]BD Asistencia'!$C:$C,'Planilla Mensual'!$D9,'[1]BD Asistencia'!$D:$D,">="&'Planilla Mensual'!M9,'[1]BD Asistencia'!$D:$D,"<="&'Planilla Mensual'!N9)-T9 -> 3 | Y9: =+COUNTIFS('[1]BD Asistencia'!$E:$E,"h",'[1]BD Asistencia'!$C:$C,'Planilla Mensual'!$D9,'[1]BD Asistencia'!$D:$D,">="&'Planilla Mensual'!M9,'[1]BD Asistencia'!$D:$D,"<="&'Planilla Mensual'!N9) -> 0 | Z9: =+COUNTIFS('[1]BD Asistencia'!$E:$E,"h/A",'[1]BD Asistencia'!$C:$C,'Planilla Mensual'!$D9,'[1]BD Asistencia'!$D:$D,">="&'Planilla Mensual'!M9,'[1]BD Asistencia'!$D:$D,"<="&'Planilla Mensual'!N9) -> 0 | AA9: =+COUNTIFS('[1]BD Asistencia'!$H:$H,"NO REMUNERADO",'[1]BD Asistencia'!$C:$C,'Planilla Mensual'!$D9,'[1]BD Asistencia'!$D:$D,">="&'Planilla Mensual'!M9,'[1]BD Asistencia'!$D:$D,"<="&'Planilla Mensual'!N9)-U9 -> #VALUE! | AB9: =+COUNTIFS('[1]BD Asistencia'!$E:$E,"F",'[1]BD Asistencia'!$C:$C,'Planilla Mensual'!$D9,'[1]BD Asistencia'!$D:$D,">="&'Planilla Mensual'!M9,'[1]BD Asistencia'!$D:$D,"<="&'Planilla Mensual'!N9) -> 0 | AC9: =+SUM(S9:AB9) -> #VALUE! | AD9: 4.6 | AE9: =+Q9/30*SUM(V9:Z9) -> 1080 | AF9: =IF(P9="SI",113,0) -> 113 | AG9: =+(Q9/30*Z9)*2 -> 0 | AH9: 400 | AI9: =+AD9*A9 -> 69 | AJ9: =+SUM(AE9:AI9) -> 1662 | AK9: =+V9*IF(RIGHT(F9,2)="N3",16,IF(RIGHT(F9,2)="N2",8,4)) -> 96 | AL9: =V9*30 -> 720 | AM9: =IF(G9="ONP",0,AJ9*0.1) -> 166.2 | AN9: =IF(G9="ONP",0,AJ9*1.37%) -> 22.7694 | AO9: =+IF(G9="ONP",AJ9*0.13,0) -> 0 | AP9: 0 | AR9: 0 | AS9: 1026.76 | AT9: =+SUM(AM9:AS9) -> 1215.7294 | AU9: =AJ9-SUM(AM9:AS9) -> 446.27065 | AV9: =AK9+AL9 -> 816 | AW9: =IF(AJ9*0.09<1130*0.09,1130*0.09,AJ9*0.09) -> 149.58 | AX9: =AU9+AV9 -> 1262.2706 | AZ9: edujasipa@gmail.com | BB9: =+IF(RIGHT(F9,2)="N3",300,0) -> 0 | BC9: =+BB9/30*SUM(V9:Z9) -> 0 | BD9: =+R9*(S9+T9) -> 160 | BE9: =+S9*30 -> 60 | BG9: 1246.76 | BH9: =+BG9-AS9 -> 220 | BI9: =+BC9+AX9+BD9+BE9+BF9-BH9 -> 1262.2706 | BJ9: =AJ9+AW9+AV9+BC9+BD9+BE9+BF9 -> 2847.58 | BK9: =+BJ9/(V9+S9) -> 109.52231 | BL9: =+BK9-30 -> 79.522308
A10: 15 | B10: PLANILLA | C10: 80780158 | D10: TERRONES JARA LEYDER | E10: 39304 | F10: Operador de Maquinaria Agricola N1 | G10: SPP PROFUTURO | H10: 693021LTJRA4 | I10: BCP | J10: 45016550233040 | L10: 46146 | M10: 46143 | N10: 46173 | O10: =+TEXT(M10,"mmmm")&" - "&YEAR(M10)&MONTH(M10) -> Mayo - 20265 | P10: NO | Q10: 1200 | R10: 80 | S10: =+COUNTIFS('[1]BD Asistencia'!$E:$E,"A",'[1]BD Asistencia'!$C:$C,'Planilla Mensual'!$D10,'[1]BD Asistencia'!$D:$D,"<"&'Planilla Mensual'!L10) -> 1 | T10: =+COUNTIFS('[1]BD Asistencia'!$E:$E,"DR",'[1]BD Asistencia'!$C:$C,'Planilla Mensual'!$D10,'[1]BD Asistencia'!$D:$D,"<"&L10) -> 0 | U10: =+COUNTIFS('[1]BD Asistencia'!$H:$H,"NO REMUNERADO",'[1]BD Asistencia'!$C:$C,'Planilla Mensual'!$D10,'[1]BD Asistencia'!$D:$D,"<"&L10) -> #VALUE! | V10: =+COUNTIFS('[1]BD Asistencia'!$E:$E,"A",'[1]BD Asistencia'!$C:$C,'Planilla Mensual'!$D10,'[1]BD Asistencia'!$D:$D,">="&'Planilla Mensual'!M10,'[1]BD Asistencia'!$D:$D,"<="&'Planilla Mensual'!N10)-S10 -> 24 | W10: =+COUNTIFS('[1]BD Asistencia'!$E:$E,"V",'[1]BD Asistencia'!$C:$C,'Planilla Mensual'!$D10,'[1]BD Asistencia'!$D:$D,">="&'Planilla Mensual'!M10,'[1]BD Asistencia'!$D:$D,"<="&'Planilla Mensual'!N10) -> 0 | X10: =+COUNTIFS('[1]BD Asistencia'!$E:$E,"DR",'[1]BD Asistencia'!$C:$C,'Planilla Mensual'!$D10,'[1]BD Asistencia'!$D:$D,">="&'Planilla Mensual'!M10,'[1]BD Asistencia'!$D:$D,"<="&'Planilla Mensual'!N10)-T10 -> 3 | Y10: =+COUNTIFS('[1]BD Asistencia'!$E:$E,"h",'[1]BD Asistencia'!$C:$C,'Planilla Mensual'!$D10,'[1]BD Asistencia'!$D:$D,">="&'Planilla Mensual'!M10,'[1]BD Asistencia'!$D:$D,"<="&'Planilla Mensual'!N10) -> 0 | Z10: =+COUNTIFS('[1]BD Asistencia'!$E:$E,"h/A",'[1]BD Asistencia'!$C:$C,'Planilla Mensual'!$D10,'[1]BD Asistencia'!$D:$D,">="&'Planilla Mensual'!M10,'[1]BD Asistencia'!$D:$D,"<="&'Planilla Mensual'!N10) -> 1 | AA10: =+COUNTIFS('[1]BD Asistencia'!$H:$H,"NO REMUNERADO",'[1]BD Asistencia'!$C:$C,'Planilla Mensual'!$D10,'[1]BD Asistencia'!$D:$D,">="&'Planilla Mensual'!M10,'[1]BD Asistencia'!$D:$D,"<="&'Planilla Mensual'!N10)-U10 -> #VALUE! | AB10: =+COUNTIFS('[1]BD Asistencia'!$E:$E,"F",'[1]BD Asistencia'!$C:$C,'Planilla Mensual'!$D10,'[1]BD Asistencia'!$D:$D,">="&'Planilla Mensual'!M10,'[1]BD Asistencia'!$D:$D,"<="&'Planilla Mensual'!N10) -> 0 | AC10: =+SUM(S10:AB10) -> #VALUE! | AD10: 6.7 | AE10: =+Q10/30*SUM(V10:Z10) -> 1120 | AF10: =IF(P10="SI",113,0) -> 0 | AG10: =+(Q10/30*Z10)*2 -> 80 | AH10: 400 | AI10: =+AD10*A10 -> 100.5 | AJ10: =+SUM(AE10:AI10) -> 1700.5 | AK10: =+V10*IF(RIGHT(F10,2)="N3",16,IF(RIGHT(F10,2)="N2",8,4)) -> 96 | AL10: =V10*30 -> 720 | AM10: =IF(G10="ONP",0,AJ10*0.1) -> 170.05 | AN10: =IF(G10="ONP",0,AJ10*1.37%) -> 23.29685 | AO10: =+IF(G10="ONP",AJ10*0.13,0) -> 0 | AP10: 0 | AQ10: 75 | AR10: 0 | AS10: 890.6 | AT10: =+SUM(AM10:AS10) -> 1158.9469 | AU10: =AJ10-SUM(AM10:AS10) -> 541.55315 | AV10: =AK10+AL10 -> 816 | AW10: =IF(AJ10*0.09<1130*0.09,1130*0.09,AJ10*0.09) -> 153.045 | AX10: =AU10+AV10 -> 1357.5531 | AZ10: leyderterrones077@gmail.com | BB10: =+IF(RIGHT(F10,2)="N3",300,0) -> 0 | BC10: =+BB10/30*SUM(V10:Z10) -> 0 | BD10: =+R10*(S10+T10) -> 80 | BE10: =+S10*30 -> 30 | BG10: 1000.6 | BH10: =+BG10-AS10 -> 110 | BI10: =+BC10+AX10+BD10+BE10+BF10-BH10 -> 1357.5531 | BJ10: =AJ10+AW10+AV10+BC10+BD10+BE10+BF10 -> 2779.545 | BK10: =+BJ10/(V10+S10) -> 111.1818 | BL10: =+BK10-30 -> 81.1818
A11: 10 | B11: PLANILLA | C11: 73322149 | D11: CALLE HUAMAN LEODAN JOEL | E11: 35920 | F11: Operador de Maquinaria Agricola N3 | G11: SPP PRIMA | H11: 659181LCHLM9 | I11: SCOTIABANK | J11: 8330769627 | K11: 00972420833076962762 | L11: 46146 | M11: 46143 | N11: 46172 | O11: =+TEXT(M11,"mmmm")&" - "&YEAR(M11)&MONTH(M11) -> Mayo - 20265 | P11: SI | Q11: 1300 | R11: 100 | S11: =+COUNTIFS('[1]BD Asistencia'!$E:$E,"A",'[1]BD Asistencia'!$C:$C,'Planilla Mensual'!$D11,'[1]BD Asistencia'!$D:$D,"<"&'Planilla Mensual'!L11) -> 1 | T11: =+COUNTIFS('[1]BD Asistencia'!$E:$E,"DR",'[1]BD Asistencia'!$C:$C,'Planilla Mensual'!$D11,'[1]BD Asistencia'!$D:$D,"<"&L11) -> 0 | U11: =+COUNTIFS('[1]BD Asistencia'!$H:$H,"NO REMUNERADO",'[1]BD Asistencia'!$C:$C,'Planilla Mensual'!$D11,'[1]BD Asistencia'!$D:$D,"<"&L11) -> #VALUE! | V11: =+COUNTIFS('[1]BD Asistencia'!$E:$E,"A",'[1]BD Asistencia'!$C:$C,'Planilla Mensual'!$D11,'[1]BD Asistencia'!$D:$D,">="&'Planilla Mensual'!M11,'[1]BD Asistencia'!$D:$D,"<="&'Planilla Mensual'!N11)-S11 -> 24 | W11: =+COUNTIFS('[1]BD Asistencia'!$E:$E,"V",'[1]BD Asistencia'!$C:$C,'Planilla Mensual'!$D11,'[1]BD Asistencia'!$D:$D,">="&'Planilla Mensual'!M11,'[1]BD Asistencia'!$D:$D,"<="&'Planilla Mensual'!N11) -> 0 | X11: =+COUNTIFS('[1]BD Asistencia'!$E:$E,"DR",'[1]BD Asistencia'!$C:$C,'Planilla Mensual'!$D11,'[1]BD Asistencia'!$D:$D,">="&'Planilla Mensual'!M11,'[1]BD Asistencia'!$D:$D,"<="&'Planilla Mensual'!N11)-T11 -> 3 | Y11: =+COUNTIFS('[1]BD Asistencia'!$E:$E,"h",'[1]BD Asistencia'!$C:$C,'Planilla Mensual'!$D11,'[1]BD Asistencia'!$D:$D,">="&'Planilla Mensual'!M11,'[1]BD Asistencia'!$D:$D,"<="&'Planilla Mensual'!N11) -> 0 | Z11: =+COUNTIFS('[1]BD Asistencia'!$E:$E,"h/A",'[1]BD Asistencia'!$C:$C,'Planilla Mensual'!$D11,'[1]BD Asistencia'!$D:$D,">="&'Planilla Mensual'!M11,'[1]BD Asistencia'!$D:$D,"<="&'Planilla Mensual'!N11) -> 0 | AA11: =+COUNTIFS('[1]BD Asistencia'!$H:$H,"NO REMUNERADO",'[1]BD Asistencia'!$C:$C,'Planilla Mensual'!$D11,'[1]BD Asistencia'!$D:$D,">="&'Planilla Mensual'!M11,'[1]BD Asistencia'!$D:$D,"<="&'Planilla Mensual'!N11)-U11 -> #VALUE! | AB11: =+COUNTIFS('[1]BD Asistencia'!$E:$E,"F",'[1]BD Asistencia'!$C:$C,'Planilla Mensual'!$D11,'[1]BD Asistencia'!$D:$D,">="&'Planilla Mensual'!M11,'[1]BD Asistencia'!$D:$D,"<="&'Planilla Mensual'!N11) -> 0 | AC11: =+SUM(S11:AB11) -> #VALUE! | AD11: 7.3 | AE11: =+Q11/30*SUM(V11:Z11) -> 1170 | AF11: =IF(P11="SI",113,0) -> 113 | AG11: =+(Q11/30*Z11)*2 -> 0 | AH11: 400 | AI11: =+AD11*A11 -> 73 | AJ11: =+SUM(AE11:AI11) -> 1756 | AK11: =+V11*IF(RIGHT(F11,2)="N3",16,IF(RIGHT(F11,2)="N2",8,4)) -> 384 | AL11: =V11*30 -> 720 | AM11: =IF(G11="ONP",0,AJ11*0.1) -> 175.6 | AN11: =IF(G11="ONP",0,AJ11*1.37%) -> 24.0572 | AO11: =+IF(G11="ONP",AJ11*0.13,0) -> 0 | AP11: 0 | AR11: 140 | AS11: 1202.9585 | AT11: =+SUM(AM11:AS11) -> 1542.6157 | AU11: =AJ11-SUM(AM11:AS11) -> 213.38435 | AV11: =AK11+AL11 -> 1104 | AW11: =IF(AJ11*0.09<1130*0.09,1130*0.09,AJ11*0.09) -> 158.04 | AX11: =AU11+AV11 -> 1317.3843 | AZ11: Callehuamanleodanjoel@gemail.com | BB11: =+IF(RIGHT(F11,2)="N3",300,0) -> 300 | BC11: =+BB11/30*SUM(V11:Z11) -> 270 | BD11: =+R11*(S11+T11) -> 100 | BE11: 0 | BG11: 1422.9585 | BH11: =+BG11-AS11 -> 220 | BI11: =+BC11+AX11+BD11+BE11+BF11-BH11 -> 1467.3843 | BJ11: =AJ11+AW11+AV11+BC11+BD11+BE11+BF11 -> 3388.04 | BK11: =+BJ11/(V11+S11) -> 135.5216 | BL11: =+BK11-30 -> 105.5216
A12: 10 | B12: PLANILLA | C12: 76768818 | D12: MANAYAY TANTARICO JHONATAN WILFER | E12: 37200 | F12: Operador de Maquinaria Agricola N2 | G12: SPP INTEGRA | H12: 671981JMTAT4 | I12: BCP | J12: 30500970418007 | L12: 46146 | M12: 46143 | N12: 46172 | O12: =+TEXT(M12,"mmmm")&" - "&YEAR(M12)&MONTH(M12) -> Mayo - 20265 | P12: NO | Q12: 1300 | R12: 80 | S12: =+COUNTIFS('[1]BD Asistencia'!$E:$E,"A",'[1]BD Asistencia'!$C:$C,'Planilla Mensual'!$D12,'[1]BD Asistencia'!$D:$D,"<"&'Planilla Mensual'!L12) -> 1 | T12: =+COUNTIFS('[1]BD Asistencia'!$E:$E,"DR",'[1]BD Asistencia'!$C:$C,'Planilla Mensual'!$D12,'[1]BD Asistencia'!$D:$D,"<"&L12) -> 0 | U12: =+COUNTIFS('[1]BD Asistencia'!$H:$H,"NO REMUNERADO",'[1]BD Asistencia'!$C:$C,'Planilla Mensual'!$D12,'[1]BD Asistencia'!$D:$D,"<"&L12) -> #VALUE! | V12: =+COUNTIFS('[1]BD Asistencia'!$E:$E,"A",'[1]BD Asistencia'!$C:$C,'Planilla Mensual'!$D12,'[1]BD Asistencia'!$D:$D,">="&'Planilla Mensual'!M12,'[1]BD Asistencia'!$D:$D,"<="&'Planilla Mensual'!N12)-S12 -> 13 | W12: =+COUNTIFS('[1]BD Asistencia'!$E:$E,"V",'[1]BD Asistencia'!$C:$C,'Planilla Mensual'!$D12,'[1]BD Asistencia'!$D:$D,">="&'Planilla Mensual'!M12,'[1]BD Asistencia'!$D:$D,"<="&'Planilla Mensual'!N12) -> 0 | X12: =+COUNTIFS('[1]BD Asistencia'!$E:$E,"DR",'[1]BD Asistencia'!$C:$C,'Planilla Mensual'!$D12,'[1]BD Asistencia'!$D:$D,">="&'Planilla Mensual'!M12,'[1]BD Asistencia'!$D:$D,"<="&'Planilla Mensual'!N12)-T12 -> 2 | Y12: =+COUNTIFS('[1]BD Asistencia'!$E:$E,"h",'[1]BD Asistencia'!$C:$C,'Planilla Mensual'!$D12,'[1]BD Asistencia'!$D:$D,">="&'Planilla Mensual'!M12,'[1]BD Asistencia'!$D:$D,"<="&'Planilla Mensual'!N12) -> 0 | Z12: =+COUNTIFS('[1]BD Asistencia'!$E:$E,"h/A",'[1]BD Asistencia'!$C:$C,'Planilla Mensual'!$D12,'[1]BD Asistencia'!$D:$D,">="&'Planilla Mensual'!M12,'[1]BD Asistencia'!$D:$D,"<="&'Planilla Mensual'!N12) -> 0 | AA12: =+COUNTIFS('[1]BD Asistencia'!$H:$H,"NO REMUNERADO",'[1]BD Asistencia'!$C:$C,'Planilla Mensual'!$D12,'[1]BD Asistencia'!$D:$D,">="&'Planilla Mensual'!M12,'[1]BD Asistencia'!$D:$D,"<="&'Planilla Mensual'!N12)-U12 -> #VALUE! | AB12: =+COUNTIFS('[1]BD Asistencia'!$E:$E,"F",'[1]BD Asistencia'!$C:$C,'Planilla Mensual'!$D12,'[1]BD Asistencia'!$D:$D,">="&'Planilla Mensual'!M12,'[1]BD Asistencia'!$D:$D,"<="&'Planilla Mensual'!N12) -> 0 | AC12: =+SUM(S12:AB12) -> #VALUE! | AD12: 3.5 | AE12: =+Q12/30*SUM(V12:Z12) -> 650 | AF12: =IF(P12="SI",113,0) -> 0 | AG12: =+(Q12/30*Z12)*2 -> 0 | AH12: 200 | AI12: =+AD12*A12 -> 35 | AJ12: =+SUM(AE12:AI12) -> 885 | AK12: =+V12*IF(RIGHT(F12,2)="N3",16,IF(RIGHT(F12,2)="N2",8,4)) -> 104 | AL12: =V12*30 -> 390 | AM12: =IF(G12="ONP",0,AJ12*0.1) -> 88.5 | AN12: =IF(G12="ONP",0,AJ12*1.37%) -> 12.1245 | AO12: =+IF(G12="ONP",AJ12*0.13,0) -> 0 | AP12: 0 | AR12: 320 | AS12: 782.725 | AT12: =+SUM(AM12:AS12) -> 1203.3495 | AU12: =AJ12-SUM(AM12:AS12) -> -318.3495 | AV12: =AK12+AL12 -> 494 | AW12: =IF(AJ12*0.09<1130*0.09,1130*0.09,AJ12*0.09) -> 101.7 | AX12: =AU12+AV12 -> 175.6505 | AY12: 46160 | AZ12: manayayjhonatan@gmail.com | BB12: =+IF(RIGHT(F12,2)="N3",300,0) -> 0 | BC12: =+BB12/30*SUM(V12:Z12) -> 0 | BD12: =+R12*(S12+T12) -> 80 | BE12: 0 | BG12: 862.725 | BH12: =+BG12-AS12 -> 80 | BI12: =+BC12+AX12+BD12+BE12+BF12-BH12 -> 175.6505 | BJ12: =AJ12+AW12+AV12+BC12+BD12+BE12+BF12 -> 1560.7 | BK12: =+BJ12/(V12+S12) -> 111.47857 | BL12: =+BK12-30 -> 81.478571
A13: 10 | B13: PLANILLA | C13: 41758826 | D13: FARROÑAN YOVERA LUIS ALBERTO | E13: 30279 | F13: Operador de Maquinaria Agricola N2 | G13: SPP PRIMA | H13: 602771LFYRE8 | I13: BCP | J13: 30513491010070 | L13: 46146 | M13: 46143 | N13: 46172 | O13: =+TEXT(M13,"mmmm")&" - "&YEAR(M13)&MONTH(M13) -> Mayo - 20265 | P13: SI | Q13: 1300 | R13: 80 | S13: =+COUNTIFS('[1]BD Asistencia'!$E:$E,"A",'[1]BD Asistencia'!$C:$C,'Planilla Mensual'!$D13,'[1]BD Asistencia'!$D:$D,"<"&'Planilla Mensual'!L13) -> 1 | T13: =+COUNTIFS('[1]BD Asistencia'!$E:$E,"DR",'[1]BD Asistencia'!$C:$C,'Planilla Mensual'!$D13,'[1]BD Asistencia'!$D:$D,"<"&L13) -> 0 | U13: =+COUNTIFS('[1]BD Asistencia'!$H:$H,"NO REMUNERADO",'[1]BD Asistencia'!$C:$C,'Planilla Mensual'!$D13,'[1]BD Asistencia'!$D:$D,"<"&L13) -> #VALUE! | V13: =+COUNTIFS('[1]BD Asistencia'!$E:$E,"A",'[1]BD Asistencia'!$C:$C,'Planilla Mensual'!$D13,'[1]BD Asistencia'!$D:$D,">="&'Planilla Mensual'!M13,'[1]BD Asistencia'!$D:$D,"<="&'Planilla Mensual'!N13)-S13 -> 23 | W13: =+COUNTIFS('[1]BD Asistencia'!$E:$E,"V",'[1]BD Asistencia'!$C:$C,'Planilla Mensual'!$D13,'[1]BD Asistencia'!$D:$D,">="&'Planilla Mensual'!M13,'[1]BD Asistencia'!$D:$D,"<="&'Planilla Mensual'!N13) -> 0 | X13: =+COUNTIFS('[1]BD Asistencia'!$E:$E,"DR",'[1]BD Asistencia'!$C:$C,'Planilla Mensual'!$D13,'[1]BD Asistencia'!$D:$D,">="&'Planilla Mensual'!M13,'[1]BD Asistencia'!$D:$D,"<="&'Planilla Mensual'!N13)-T13 -> 3 | Y13: =+COUNTIFS('[1]BD Asistencia'!$E:$E,"h",'[1]BD Asistencia'!$C:$C,'Planilla Mensual'!$D13,'[1]BD Asistencia'!$D:$D,">="&'Planilla Mensual'!M13,'[1]BD Asistencia'!$D:$D,"<="&'Planilla Mensual'!N13) -> 0 | Z13: =+COUNTIFS('[1]BD Asistencia'!$E:$E,"h/A",'[1]BD Asistencia'!$C:$C,'Planilla Mensual'!$D13,'[1]BD Asistencia'!$D:$D,">="&'Planilla Mensual'!M13,'[1]BD Asistencia'!$D:$D,"<="&'Planilla Mensual'!N13) -> 0 | AA13: =+COUNTIFS('[1]BD Asistencia'!$H:$H,"NO REMUNERADO",'[1]BD Asistencia'!$C:$C,'Planilla Mensual'!$D13,'[1]BD Asistencia'!$D:$D,">="&'Planilla Mensual'!M13,'[1]BD Asistencia'!$D:$D,"<="&'Planilla Mensual'!N13)-U13 -> #VALUE! | AB13: =+COUNTIFS('[1]BD Asistencia'!$E:$E,"F",'[1]BD Asistencia'!$C:$C,'Planilla Mensual'!$D13,'[1]BD Asistencia'!$D:$D,">="&'Planilla Mensual'!M13,'[1]BD Asistencia'!$D:$D,"<="&'Planilla Mensual'!N13) -> 1 | AC13: =+SUM(S13:AB13) -> #VALUE! | AD13: 20.5 | AE13: =+Q13/30*SUM(V13:Z13) -> 1126.6667 | AF13: =IF(P13="SI",113,0) -> 113 | AG13: =+(Q13/30*Z13)*2 -> 0 | AH13: 400 | AI13: =+AD13*A13 -> 205 | AJ13: =+SUM(AE13:AI13) -> 1844.6667 | AK13: =+V13*IF(RIGHT(F13,2)="N3",16,IF(RIGHT(F13,2)="N2",8,4)) -> 184 | AL13: =V13*30 -> 690 | AM13: =IF(G13="ONP",0,AJ13*0.1) -> 184.46667 | AN13: =IF(G13="ONP",0,AJ13*1.37%) -> 25.271933 | AO13: =+IF(G13="ONP",AJ13*0.13,0) -> 0 | AP13: 0 | AR13: 620 | AS13: 767.53162 | AT13: =+SUM(AM13:AS13) -> 1597.2702 | AU13: =AJ13-SUM(AM13:AS13) -> 247.39645 | AV13: =AK13+AL13 -> 874 | AW13: =IF(AJ13*0.09<1130*0.09,1130*0.09,AJ13*0.09) -> 166.02 | AX13: =AU13+AV13 -> 1121.3964 | AZ13: luisfy11@hotmail.com | BB13: =+IF(RIGHT(F13,2)="N3",300,0) -> 0 | BC13: =+BB13/30*SUM(V13:Z13) -> 0 | BD13: =+R13*(S13+T13) -> 80 | BE13: =+S13*30 -> 30 | BG13: 847.53162 | BH13: =+BG13-AS13 -> 80 | BI13: =+BC13+AX13+BD13+BE13+BF13-BH13 -> 1151.3964 | BJ13: =AJ13+AW13+AV13+BC13+BD13+BE13+BF13 -> 2994.6867 | BK13: =+BJ13/(V13+S13) -> 124.77861 | BL13: =+BK13-30 -> 94.778611
A14: 10 | B14: PLANILLA | C14: 71983929 | D14: CHUICA ADANAQUE ANDERSON XAVIER | E14: 33973 | F14: Operador de Maquinaria Agricola N3 | G14: ONP | I14: BCP | J14: 47525665591096 | L14: 46146 | M14: 46143 | N14: 46172 | O14: =+TEXT(M14,"mmmm")&" - "&YEAR(M14)&MONTH(M14) -> Mayo - 20265 | P14: SI | Q14: 1300 | S14: =+COUNTIFS('[1]BD Asistencia'!$E:$E,"A",'[1]BD Asistencia'!$C:$C,'Planilla Mensual'!$D14,'[1]BD Asistencia'!$D:$D,"<"&'Planilla Mensual'!L14) -> 0 | T14: =+COUNTIFS('[1]BD Asistencia'!$E:$E,"DR",'[1]BD Asistencia'!$C:$C,'Planilla Mensual'!$D14,'[1]BD Asistencia'!$D:$D,"<"&L14) -> 0 | U14: =+COUNTIFS('[1]BD Asistencia'!$H:$H,"NO REMUNERADO",'[1]BD Asistencia'!$C:$C,'Planilla Mensual'!$D14,'[1]BD Asistencia'!$D:$D,"<"&L14) -> #VALUE! | V14: =+COUNTIFS('[1]BD Asistencia'!$E:$E,"A",'[1]BD Asistencia'!$C:$C,'Planilla Mensual'!$D14,'[1]BD Asistencia'!$D:$D,">="&'Planilla Mensual'!M14,'[1]BD Asistencia'!$D:$D,"<="&'Planilla Mensual'!N14)-S14 -> 24 | W14: =+COUNTIFS('[1]BD Asistencia'!$E:$E,"V",'[1]BD Asistencia'!$C:$C,'Planilla Mensual'!$D14,'[1]BD Asistencia'!$D:$D,">="&'Planilla Mensual'!M14,'[1]BD Asistencia'!$D:$D,"<="&'Planilla Mensual'!N14) -> 0 | X14: =+COUNTIFS('[1]BD Asistencia'!$E:$E,"DR",'[1]BD Asistencia'!$C:$C,'Planilla Mensual'!$D14,'[1]BD Asistencia'!$D:$D,">="&'Planilla Mensual'!M14,'[1]BD Asistencia'!$D:$D,"<="&'Planilla Mensual'!N14)-T14 -> 3 | Y14: =+COUNTIFS('[1]BD Asistencia'!$E:$E,"h",'[1]BD Asistencia'!$C:$C,'Planilla Mensual'!$D14,'[1]BD Asistencia'!$D:$D,">="&'Planilla Mensual'!M14,'[1]BD Asistencia'!$D:$D,"<="&'Planilla Mensual'!N14) -> 0 | Z14: =+COUNTIFS('[1]BD Asistencia'!$E:$E,"h/A",'[1]BD Asistencia'!$C:$C,'Planilla Mensual'!$D14,'[1]BD Asistencia'!$D:$D,">="&'Planilla Mensual'!M14,'[1]BD Asistencia'!$D:$D,"<="&'Planilla Mensual'!N14) -> 0 | AA14: =+COUNTIFS('[1]BD Asistencia'!$H:$H,"NO REMUNERADO",'[1]BD Asistencia'!$C:$C,'Planilla Mensual'!$D14,'[1]BD Asistencia'!$D:$D,">="&'Planilla Mensual'!M14,'[1]BD Asistencia'!$D:$D,"<="&'Planilla Mensual'!N14)-U14 -> #VALUE! | AB14: =+COUNTIFS('[1]BD Asistencia'!$E:$E,"F",'[1]BD Asistencia'!$C:$C,'Planilla Mensual'!$D14,'[1]BD Asistencia'!$D:$D,">="&'Planilla Mensual'!M14,'[1]BD Asistencia'!$D:$D,"<="&'Planilla Mensual'!N14) -> 0 | AC14: =+SUM(S14:AB14) -> #VALUE! | AD14: 10.65 | AE14: =+Q14/30*SUM(V14:Z14) -> 1170 | AF14: =IF(P14="SI",113,0) -> 113 | AG14: =+(Q14/30*Z14)*2 -> 0 | AH14: 400 | AI14: =+AD14*A14 -> 106.5 | AJ14: =+SUM(AE14:AI14) -> 1789.5 | AK14: =+V14*IF(RIGHT(F14,2)="N3",16,IF(RIGHT(F14,2)="N2",8,4)) -> 384 | AL14: =V14*30 -> 720 | AM14: =IF(G14="ONP",0,AJ14*0.1) -> 0 | AN14: =IF(G14="ONP",0,AJ14*1.37%) -> 0 | AO14: =+IF(G14="ONP",AJ14*0.13,0) -> 232.635 | AP14: 0 | AR14: =180+180+200+200 -> 760 | AS14: 916.79 | AT14: =+SUM(AM14:AS14) -> 1909.425 | AU14: =AJ14-SUM(AM14:AS14) -> -119.925 | AV14: =AK14+AL14 -> 1104 | AW14: =IF(AJ14*0.09<1130*0.09,1130*0.09,AJ14*0.09) -> 161.055 | AX14: =AU14+AV14 -> 984.075 | AZ14: Andersonxavierchuicaadanaque@gmail.com | BB14: =+IF(RIGHT(F14,2)="N3",300,0) -> 300 | BC14: =+BB14/30*SUM(V14:Z14) -> 270 | BD14: =+R14*(S14+T14) -> 0 | BE14: =+S14*30 -> 0 | BG14: 1036.79 | BH14: =+BG14-AS14 -> 120 | BI14: =+BC14+AX14+BD14+BE14+BF14-BH14 -> 1134.075 | BJ14: =AJ14+AW14+AV14+BC14+BD14+BE14+BF14 -> 3324.555 | BK14: =+BJ14/(V14+S14) -> 138.52313 | BL14: =+BK14-30 -> 108.52313
A15: 10 | B15: PLANILLA | C15: 45952951 | D15: GARCIA RAMOS SEGUNDO MIGUEL | E15: 32777 | F15: Operador de Maquinaria Agricola N3 | G15: SPP PRIMA | H15: 627751SGRCO7 | I15: BCP | J15: 47531606418032 | L15: 46146 | M15: 46143 | N15: 46172 | O15: =+TEXT(M15,"mmmm")&" - "&YEAR(M15)&MONTH(M15) -> Mayo - 20265 | P15: SI | Q15: 1300 | S15: =+COUNTIFS('[1]BD Asistencia'!$E:$E,"A",'[1]BD Asistencia'!$C:$C,'Planilla Mensual'!$D15,'[1]BD Asistencia'!$D:$D,"<"&'Planilla Mensual'!L15) -> 0 | T15: =+COUNTIFS('[1]BD Asistencia'!$E:$E,"DR",'[1]BD Asistencia'!$C:$C,'Planilla Mensual'!$D15,'[1]BD Asistencia'!$D:$D,"<"&L15) -> 0 | U15: =+COUNTIFS('[1]BD Asistencia'!$H:$H,"NO REMUNERADO",'[1]BD Asistencia'!$C:$C,'Planilla Mensual'!$D15,'[1]BD Asistencia'!$D:$D,"<"&L15) -> #VALUE! | V15: =+COUNTIFS('[1]BD Asistencia'!$E:$E,"A",'[1]BD Asistencia'!$C:$C,'Planilla Mensual'!$D15,'[1]BD Asistencia'!$D:$D,">="&'Planilla Mensual'!M15,'[1]BD Asistencia'!$D:$D,"<="&'Planilla Mensual'!N15)-S15 -> 24 | W15: =+COUNTIFS('[1]BD Asistencia'!$E:$E,"V",'[1]BD Asistencia'!$C:$C,'Planilla Mensual'!$D15,'[1]BD Asistencia'!$D:$D,">="&'Planilla Mensual'!M15,'[1]BD Asistencia'!$D:$D,"<="&'Planilla Mensual'!N15) -> 0 | X15: =+COUNTIFS('[1]BD Asistencia'!$E:$E,"DR",'[1]BD Asistencia'!$C:$C,'Planilla Mensual'!$D15,'[1]BD Asistencia'!$D:$D,">="&'Planilla Mensual'!M15,'[1]BD Asistencia'!$D:$D,"<="&'Planilla Mensual'!N15)-T15 -> 3 | Y15: =+COUNTIFS('[1]BD Asistencia'!$E:$E,"h",'[1]BD Asistencia'!$C:$C,'Planilla Mensual'!$D15,'[1]BD Asistencia'!$D:$D,">="&'Planilla Mensual'!M15,'[1]BD Asistencia'!$D:$D,"<="&'Planilla Mensual'!N15) -> 0 | Z15: =+COUNTIFS('[1]BD Asistencia'!$E:$E,"h/A",'[1]BD Asistencia'!$C:$C,'Planilla Mensual'!$D15,'[1]BD Asistencia'!$D:$D,">="&'Planilla Mensual'!M15,'[1]BD Asistencia'!$D:$D,"<="&'Planilla Mensual'!N15) -> 0 | AA15: =+COUNTIFS('[1]BD Asistencia'!$H:$H,"NO REMUNERADO",'[1]BD Asistencia'!$C:$C,'Planilla Mensual'!$D15,'[1]BD Asistencia'!$D:$D,">="&'Planilla Mensual'!M15,'[1]BD Asistencia'!$D:$D,"<="&'Planilla Mensual'!N15)-U15 -> #VALUE! | AB15: =+COUNTIFS('[1]BD Asistencia'!$E:$E,"F",'[1]BD Asistencia'!$C:$C,'Planilla Mensual'!$D15,'[1]BD Asistencia'!$D:$D,">="&'Planilla Mensual'!M15,'[1]BD Asistencia'!$D:$D,"<="&'Planilla Mensual'!N15) -> 0 | AC15: =+SUM(S15:AB15) -> #VALUE! | AD15: 11.65 | AE15: =+Q15/30*SUM(V15:Z15) -> 1170 | AF15: =IF(P15="SI",113,0) -> 113 | AG15: =+(Q15/30*Z15)*2 -> 0 | AH15: =240+400 -> 640 | AI15: =+AD15*A15 -> 116.5 | AJ15: =+SUM(AE15:AI15) -> 2039.5 | AK15: =+V15*IF(RIGHT(F15,2)="N3",16,IF(RIGHT(F15,2)="N2",8,4)) -> 384 | AL15: =V15*30 -> 720 | AM15: =IF(G15="ONP",0,AJ15*0.1) -> 203.95 | AN15: =IF(G15="ONP",0,AJ15*1.37%) -> 27.94115 | AO15: =+IF(G15="ONP",AJ15*0.13,0) -> 0 | AP15: 0 | AR15: =180+40 -> 220 | AS15: 1036.7543 | AT15: =+SUM(AM15:AS15) -> 1488.6455 | AU15: =AJ15-SUM(AM15:AS15) -> 550.8545 | AV15: =AK15+AL15 -> 1104 | AW15: =IF(AJ15*0.09<1130*0.09,1130*0.09,AJ15*0.09) -> 183.555 | AX15: =AU15+AV15 -> 1654.8545 | AZ15: garcikalet89@gmail.com | BB15: 300 | BC15: =+BB15/30*SUM(V15:Z15) -> 270 | BD15: =+R15*(S15+T15) -> 0 | BE15: =+S15*30 -> 0 | BG15: 1156.7543 | BH15: =+BG15-AS15 -> 120 | BI15: =+BC15+AX15+BD15+BE15+BF15-BH15 -> 1804.8545 | BJ15: =AJ15+AW15+AV15+BC15+BD15+BE15+BF15 -> 3597.055 | BK15: =+BJ15/(V15+S15) -> 149.87729 | BL15: =+BK15-30 -> 119.87729
A16: 10 | B16: PLANILLA | C16: 48187021 | D16: CARLOS ROQUE JUNIOR ABEL | E16: 34283 | F16: Operador de Maquinaria Agricola N3 | G16: SPP INTEGRA | H16: 342811JCRLU0 | I16: BCP | J16: 41599043973014 | L16: 46146 | M16: 46143 | N16: 46172 | O16: =+TEXT(M16,"mmmm")&" - "&YEAR(M16)&MONTH(M16) -> Mayo - 20265 | P16: SI | Q16: 1300 | S16: =+COUNTIFS('[1]BD Asistencia'!$E:$E,"A",'[1]BD Asistencia'!$C:$C,'Planilla Mensual'!$D16,'[1]BD Asistencia'!$D:$D,"<"&'Planilla Mensual'!L16) -> 0 | T16: =+COUNTIFS('[1]BD Asistencia'!$E:$E,"DR",'[1]BD Asistencia'!$C:$C,'Planilla Mensual'!$D16,'[1]BD Asistencia'!$D:$D,"<"&L16) -> 0 | U16: =+COUNTIFS('[1]BD Asistencia'!$H:$H,"NO REMUNERADO",'[1]BD Asistencia'!$C:$C,'Planilla Mensual'!$D16,'[1]BD Asistencia'!$D:$D,"<"&L16) -> #VALUE! | V16: =+COUNTIFS('[1]BD Asistencia'!$E:$E,"A",'[1]BD Asistencia'!$C:$C,'Planilla Mensual'!$D16,'[1]BD Asistencia'!$D:$D,">="&'Planilla Mensual'!M16,'[1]BD Asistencia'!$D:$D,"<="&'Planilla Mensual'!N16)-S16 -> 23 | W16: =+COUNTIFS('[1]BD Asistencia'!$E:$E,"V",'[1]BD Asistencia'!$C:$C,'Planilla Mensual'!$D16,'[1]BD Asistencia'!$D:$D,">="&'Planilla Mensual'!M16,'[1]BD Asistencia'!$D:$D,"<="&'Planilla Mensual'!N16) -> 0 | X16: =+COUNTIFS('[1]BD Asistencia'!$E:$E,"DR",'[1]BD Asistencia'!$C:$C,'Planilla Mensual'!$D16,'[1]BD Asistencia'!$D:$D,">="&'Planilla Mensual'!M16,'[1]BD Asistencia'!$D:$D,"<="&'Planilla Mensual'!N16)-T16 -> 3 | Y16: =+COUNTIFS('[1]BD Asistencia'!$E:$E,"h",'[1]BD Asistencia'!$C:$C,'Planilla Mensual'!$D16,'[1]BD Asistencia'!$D:$D,">="&'Planilla Mensual'!M16,'[1]BD Asistencia'!$D:$D,"<="&'Planilla Mensual'!N16) -> 0 | Z16: =+COUNTIFS('[1]BD Asistencia'!$E:$E,"h/A",'[1]BD Asistencia'!$C:$C,'Planilla Mensual'!$D16,'[1]BD Asistencia'!$D:$D,">="&'Planilla Mensual'!M16,'[1]BD Asistencia'!$D:$D,"<="&'Planilla Mensual'!N16) -> 0 | AA16: =+COUNTIFS('[1]BD Asistencia'!$H:$H,"NO REMUNERADO",'[1]BD Asistencia'!$C:$C,'Planilla Mensual'!$D16,'[1]BD Asistencia'!$D:$D,">="&'Planilla Mensual'!M16,'[1]BD Asistencia'!$D:$D,"<="&'Planilla Mensual'!N16)-U16 -> #VALUE! | AB16: =+COUNTIFS('[1]BD Asistencia'!$E:$E,"F",'[1]BD Asistencia'!$C:$C,'Planilla Mensual'!$D16,'[1]BD Asistencia'!$D:$D,">="&'Planilla Mensual'!M16,'[1]BD Asistencia'!$D:$D,"<="&'Planilla Mensual'!N16) -> 0 | AC16: =+SUM(S16:AB16) -> #VALUE! | AD16: 20.5 | AE16: =+Q16/30*SUM(V16:Z16) -> 1126.6667 | AF16: =IF(P16="SI",113,0) -> 113 | AG16: =+(Q16/30*Z16)*2 -> 0 | AH16: 400 | AI16: =+AD16*A16 -> 205 | AJ16: =+SUM(AE16:AI16) -> 1844.6667 | AK16: =+V16*IF(RIGHT(F16,2)="N3",16,IF(RIGHT(F16,2)="N2",8,4)) -> 368 | AL16: =V16*30 -> 690 | AM16: =IF(G16="ONP",0,AJ16*0.1) -> 184.46667 | AN16: =IF(G16="ONP",0,AJ16*1.37%) -> 25.271933 | AO16: =+IF(G16="ONP",AJ16*0.13,0) -> 0 | AP16: 0 | AR16: =180+30 -> 210 | AS16: 985.14112 | AT16: =+SUM(AM16:AS16) -> 1404.8797 | AU16: =AJ16-SUM(AM16:AS16) -> 439.78695 | AV16: =AK16+AL16 -> 1058 | AW16: =IF(AJ16*0.09<1130*0.09,1130*0.09,AJ16*0.09) -> 166.02 | AX16: =AU16+AV16 -> 1497.7869 | AZ16: carlosroquejuinorabel@gmail.com | BB16: =+IF(RIGHT(F16,2)="N3",300,0) -> 300 | BC16: =+BB16/30*SUM(V16:Z16) -> 260 | BD16: =+R16*(S16+T16) -> 0 | BE16: =+S16*30 -> 0 | BG16: 1095.1411 | BH16: =+BG16-AS16 -> 110 | BI16: =+BC16+AX16+BD16+BE16+BF16-BH16 -> 1647.7869 | BJ16: =AJ16+AW16+AV16+BC16+BD16+BE16+BF16 -> 3328.6867 | BK16: =+BJ16/(V16+S16) -> 144.72551 | BL16: =+BK16-30 -> 114.72551
A17: 10 | B17: PLANILLA | C17: 77709008 | D17: CRUZ VARGAS MARCO ANTONIO | E17: 35588 | F17: Operador de Maquinaria Agricola N3 | G17: SPP INTEGRA | H17: 655861MCVZG3 | I17: BCP | J17: 57073429072032 | L17: 46146 | M17: 46143 | N17: 46172 | O17: =+TEXT(M17,"mmmm")&" - "&YEAR(M17)&MONTH(M17) -> Mayo - 20265 | P17: SI | Q17: 1300 | S17: =+COUNTIFS('[1]BD Asistencia'!$E:$E,"A",'[1]BD Asistencia'!$C:$C,'Planilla Mensual'!$D17,'[1]BD Asistencia'!$D:$D,"<"&'Planilla Mensual'!L17) -> 1 | T17: =+COUNTIFS('[1]BD Asistencia'!$E:$E,"DR",'[1]BD Asistencia'!$C:$C,'Planilla Mensual'!$D17,'[1]BD Asistencia'!$D:$D,"<"&L17) -> 0 | U17: =+COUNTIFS('[1]BD Asistencia'!$H:$H,"NO REMUNERADO",'[1]BD Asistencia'!$C:$C,'Planilla Mensual'!$D17,'[1]BD Asistencia'!$D:$D,"<"&L17) -> #VALUE! | V17: 7 | W17: =+COUNTIFS('[1]BD Asistencia'!$E:$E,"V",'[1]BD Asistencia'!$C:$C,'Planilla Mensual'!$D17,'[1]BD Asistencia'!$D:$D,">="&'Planilla Mensual'!M17,'[1]BD Asistencia'!$D:$D,"<="&'Planilla Mensual'!N17) -> 0 | X17: 1 | Y17: =+COUNTIFS('[1]BD Asistencia'!$E:$E,"h",'[1]BD Asistencia'!$C:$C,'Planilla Mensual'!$D17,'[1]BD Asistencia'!$D:$D,">="&'Planilla Mensual'!M17,'[1]BD Asistencia'!$D:$D,"<="&'Planilla Mensual'!N17) -> 0 | Z17: =+COUNTIFS('[1]BD Asistencia'!$E:$E,"h/A",'[1]BD Asistencia'!$C:$C,'Planilla Mensual'!$D17,'[1]BD Asistencia'!$D:$D,">="&'Planilla Mensual'!M17,'[1]BD Asistencia'!$D:$D,"<="&'Planilla Mensual'!N17) -> 0 | AA17: 4 | AB17: =+COUNTIFS('[1]BD Asistencia'!$E:$E,"F",'[1]BD Asistencia'!$C:$C,'Planilla Mensual'!$D17,'[1]BD Asistencia'!$D:$D,">="&'Planilla Mensual'!M17,'[1]BD Asistencia'!$D:$D,"<="&'Planilla Mensual'!N17) -> 0 | AC17: =+SUM(S17:AB17) -> #VALUE! | AE17: =+Q17/30*SUM(V17:Z17) -> 346.66667 | AF17: =IF(P17="SI",113,0) -> 113 | AG17: =+(Q17/30*Z17)*2 -> 0 | AH17: 0 | AI17: =+AD17*A17 -> 0 | AJ17: =+SUM(AE17:AI17) -> 459.66667 | AK17: =+V17*IF(RIGHT(F17,2)="N3",16,IF(RIGHT(F17,2)="N2",8,4)) -> 112 | AL17: =V17*30 -> 210 | AM17: =IF(G17="ONP",0,AJ17*0.1) -> 45.966667 | AN17: =IF(G17="ONP",0,AJ17*1.37%) -> 6.2974333 | AO17: =+IF(G17="ONP",AJ17*0.13,0) -> 0 | AP17: 0 | AR17: =30+64 -> 94 | AS17: 585.32662 | AT17: =+SUM(AM17:AS17) -> 731.59072 | AU17: =AJ17-SUM(AM17:AS17) -> -271.92405 | AV17: =AK17+AL17 -> 322 | AW17: =IF(AJ17*0.09<1130*0.09,1130*0.09,AJ17*0.09) -> 101.7 | AX17: =AU17+AV17 -> 50.07595 | AZ17: marcocruzcasas12@gmail.com | BB17: =+IF(RIGHT(F17,2)="N3",300,0) -> 300 | BC17: =+BB17/30*SUM(V17:Z17) -> 80 | BD17: =+R17*(S17+T17) -> 0 | BE17: 0 | BG17: 665.32662 | BH17: =+BG17-AS17 -> 80 | BI17: =+BC17+AX17+BD17+BE17+BF17-BH17 -> 50.07595 | BJ17: =AJ17+AW17+AV17+BC17+BD17+BE17+BF17 -> 963.36667 | BK17: =+BJ17/(V17+S17) -> 120.42083 | BL17: =+BK17-30 -> 90.420833
A18: 10 | B18: PLANILLA | C18: 77236592 | D18: BERNA TANTARICO BENJAMIN | E18: 34712 | F18: Operador de Maquinaria Agricola N2 | G18: SPP HABITAT | H18: 647101BBTNT4 | I18: BCP | J18: 30593206658025 | L18: 46153 | M18: 46143 | N18: 46172 | O18: =+TEXT(M18,"mmmm")&" - "&YEAR(M18)&MONTH(M18) -> Mayo - 20265 | P18: NO | Q18: 1300 | R18: 80 | S18: =+COUNTIFS('[1]BD Asistencia'!$E:$E,"A",'[1]BD Asistencia'!$C:$C,'Planilla Mensual'!$D18,'[1]BD Asistencia'!$D:$D,"<"&'Planilla Mensual'!L18) -> 3 | T18: =+COUNTIFS('[1]BD Asistencia'!$E:$E,"DR",'[1]BD Asistencia'!$C:$C,'Planilla Mensual'!$D18,'[1]BD Asistencia'!$D:$D,"<"&L18) -> 0 | U18: =+COUNTIFS('[1]BD Asistencia'!$H:$H,"NO REMUNERADO",'[1]BD Asistencia'!$C:$C,'Planilla Mensual'!$D18,'[1]BD Asistencia'!$D:$D,"<"&L18) -> #VALUE! | V18: =+COUNTIFS('[1]BD Asistencia'!$E:$E,"A",'[1]BD Asistencia'!$C:$C,'Planilla Mensual'!$D18,'[1]BD Asistencia'!$D:$D,">="&'Planilla Mensual'!M18,'[1]BD Asistencia'!$D:$D,"<="&'Planilla Mensual'!N18)-S18 -> 18 | W18: =+COUNTIFS('[1]BD Asistencia'!$E:$E,"V",'[1]BD Asistencia'!$C:$C,'Planilla Mensual'!$D18,'[1]BD Asistencia'!$D:$D,">="&'Planilla Mensual'!M18,'[1]BD Asistencia'!$D:$D,"<="&'Planilla Mensual'!N18) -> 0 | X18: =+COUNTIFS('[1]BD Asistencia'!$E:$E,"DR",'[1]BD Asistencia'!$C:$C,'Planilla Mensual'!$D18,'[1]BD Asistencia'!$D:$D,">="&'Planilla Mensual'!M18,'[1]BD Asistencia'!$D:$D,"<="&'Planilla Mensual'!N18)-T18 -> 2 | Y18: =+COUNTIFS('[1]BD Asistencia'!$E:$E,"h",'[1]BD Asistencia'!$C:$C,'Planilla Mensual'!$D18,'[1]BD Asistencia'!$D:$D,">="&'Planilla Mensual'!M18,'[1]BD Asistencia'!$D:$D,"<="&'Planilla Mensual'!N18) -> 0 | Z18: =+COUNTIFS('[1]BD Asistencia'!$E:$E,"h/A",'[1]BD Asistencia'!$C:$C,'Planilla Mensual'!$D18,'[1]BD Asistencia'!$D:$D,">="&'Planilla Mensual'!M18,'[1]BD Asistencia'!$D:$D,"<="&'Planilla Mensual'!N18) -> 0 | AA18: =+COUNTIFS('[1]BD Asistencia'!$H:$H,"NO REMUNERADO",'[1]BD Asistencia'!$C:$C,'Planilla Mensual'!$D18,'[1]BD Asistencia'!$D:$D,">="&'Planilla Mensual'!M18,'[1]BD Asistencia'!$D:$D,"<="&'Planilla Mensual'!N18)-U18 -> #VALUE! | AB18: =+COUNTIFS('[1]BD Asistencia'!$E:$E,"F",'[1]BD Asistencia'!$C:$C,'Planilla Mensual'!$D18,'[1]BD Asistencia'!$D:$D,">="&'Planilla Mensual'!M18,'[1]BD Asistencia'!$D:$D,"<="&'Planilla Mensual'!N18) -> 0 | AC18: =+SUM(S18:AB18) -> #VALUE! | AD18: 10.67 | AE18: =+Q18/30*SUM(V18:Z18) -> 866.66667 | AF18: =IF(P18="SI",113,0) -> 0 | AG18: =+(Q18/30*Z18)*2 -> 0 | AH18: 300 | AI18: =+AD18*A18 -> 106.7 | AJ18: =+SUM(AE18:AI18) -> 1273.3667 | AK18: =+V18*IF(RIGHT(F18,2)="N3",16,IF(RIGHT(F18,2)="N2",8,4)) -> 144 | AL18: =V18*30 -> 540 | AM18: =IF(G18="ONP",0,AJ18*0.1) -> 127.33667 | AN18: =IF(G18="ONP",0,AJ18*1.37%) -> 17.445123 | AO18: =+IF(G18="ONP",AJ18*0.13,0) -> 0 | AP18: 0 | AR18: 600 | AS18: 392.70267 | AT18: =+SUM(AM18:AS18) -> 1137.4845 | AU18: =AJ18-SUM(AM18:AS18) -> 135.88221 | AV18: =AK18+AL18 -> 684 | AW18: =IF(AJ18*0.09<1130*0.09,1130*0.09,AJ18*0.09) -> 114.603 | AX18: =AU18+AV18 -> 819.88221 | AZ18: bbernatantarico@gmail.com | BB18: =+IF(RIGHT(F18,2)="N3",300,0) -> 0 | BC18: =+BB18/30*SUM(V18:Z18) -> 0 | BD18: =+R18*(S18+T18) -> 240 | BE18: =+S18*30 -> 90 | BG18: 472.70267 | BH18: =+BG18-AS18 -> 80 | BI18: =+BC18+AX18+BD18+BE18+BF18-BH18 -> 1069.8822 | BJ18: =AJ18+AW18+AV18+BC18+BD18+BE18+BF18 -> 2401.9697 | BK18: =+BJ18/(V18+S18) -> 114.37951 | BL18: =+BK18-30 -> 84.379508 | BN18: =+BI18/14 -> 76.420158 | BO18: =1542/21 -> 73.428571
A19: 10 | B19: PLANILLA | C19: 70828937 | D19: HERNANDEZ GOMEZ LUIS JHONATAN | E19: 36383 | F19: Operador de Maquinaria Agricola N3 | G19: SPP PRIMA | H19: 663811LHGNE7 | I19: BCP | J19: 47515071114006 | L19: 46153 | M19: 46143 | N19: 46172 | O19: =+TEXT(M19,"mmmm")&" - "&YEAR(M19)&MONTH(M19) -> Mayo - 20265 | P19: SI | Q19: 1300 | S19: =+COUNTIFS('[1]BD Asistencia'!$E:$E,"A",'[1]BD Asistencia'!$C:$C,'Planilla Mensual'!$D19,'[1]BD Asistencia'!$D:$D,"<"&'Planilla Mensual'!L19) -> 0 | T19: =+COUNTIFS('[1]BD Asistencia'!$E:$E,"DR",'[1]BD Asistencia'!$C:$C,'Planilla Mensual'!$D19,'[1]BD Asistencia'!$D:$D,"<"&L19) -> 0 | U19: =+COUNTIFS('[1]BD Asistencia'!$H:$H,"NO REMUNERADO",'[1]BD Asistencia'!$C:$C,'Planilla Mensual'!$D19,'[1]BD Asistencia'!$D:$D,"<"&L19) -> #VALUE! | V19: =+COUNTIFS('[1]BD Asistencia'!$E:$E,"A",'[1]BD Asistencia'!$C:$C,'Planilla Mensual'!$D19,'[1]BD Asistencia'!$D:$D,">="&'Planilla Mensual'!M19,'[1]BD Asistencia'!$D:$D,"<="&'Planilla Mensual'!N19)-S19 -> 18 | W19: =+COUNTIFS('[1]BD Asistencia'!$E:$E,"V",'[1]BD Asistencia'!$C:$C,'Planilla Mensual'!$D19,'[1]BD Asistencia'!$D:$D,">="&'Planilla Mensual'!M19,'[1]BD Asistencia'!$D:$D,"<="&'Planilla Mensual'!N19) -> 0 | X19: =+COUNTIFS('[1]BD Asistencia'!$E:$E,"DR",'[1]BD Asistencia'!$C:$C,'Planilla Mensual'!$D19,'[1]BD Asistencia'!$D:$D,">="&'Planilla Mensual'!M19,'[1]BD Asistencia'!$D:$D,"<="&'Planilla Mensual'!N19)-T19 -> 2 | Y19: =+COUNTIFS('[1]BD Asistencia'!$E:$E,"h",'[1]BD Asistencia'!$C:$C,'Planilla Mensual'!$D19,'[1]BD Asistencia'!$D:$D,">="&'Planilla Mensual'!M19,'[1]BD Asistencia'!$D:$D,"<="&'Planilla Mensual'!N19) -> 0 | Z19: =+COUNTIFS('[1]BD Asistencia'!$E:$E,"h/A",'[1]BD Asistencia'!$C:$C,'Planilla Mensual'!$D19,'[1]BD Asistencia'!$D:$D,">="&'Planilla Mensual'!M19,'[1]BD Asistencia'!$D:$D,"<="&'Planilla Mensual'!N19) -> 0 | AA19: =+COUNTIFS('[1]BD Asistencia'!$H:$H,"NO REMUNERADO",'[1]BD Asistencia'!$C:$C,'Planilla Mensual'!$D19,'[1]BD Asistencia'!$D:$D,">="&'Planilla Mensual'!M19,'[1]BD Asistencia'!$D:$D,"<="&'Planilla Mensual'!N19)-U19 -> #VALUE! | AB19: =+COUNTIFS('[1]BD Asistencia'!$E:$E,"F",'[1]BD Asistencia'!$C:$C,'Planilla Mensual'!$D19,'[1]BD Asistencia'!$D:$D,">="&'Planilla Mensual'!M19,'[1]BD Asistencia'!$D:$D,"<="&'Planilla Mensual'!N19) -> 0 | AC19: =+SUM(S19:AB19) -> #VALUE! | AD19: 4.35 | AE19: =+Q19/30*SUM(V19:Z19) -> 866.66667 | AF19: =IF(P19="SI",113,0) -> 113 | AG19: =+(Q19/30*Z19)*2 -> 0 | AH19: 300 | AI19: =+AD19*A19 -> 43.5 | AJ19: =+SUM(AE19:AI19) -> 1323.1667 | AK19: =+V19*IF(RIGHT(F19,2)="N3",16,IF(RIGHT(F19,2)="N2",8,4)) -> 288 | AL19: =V19*30 -> 540 | AM19: =IF(G19="ONP",0,AJ19*0.1) -> 132.31667 | AN19: =IF(G19="ONP",0,AJ19*1.37%) -> 18.127383 | AO19: =+IF(G19="ONP",AJ19*0.13,0) -> 0 | AP19: 0 | AR19: =(180+200+230)/2 -> 305 | AS19: 480.73762 | AT19: =+SUM(AM19:AS19) -> 936.18167 | AU19: =AJ19-SUM(AM19:AS19) -> 386.985 | AV19: =AK19+AL19 -> 828 | AW19: =IF(AJ19*0.09<1130*0.09,1130*0.09,AJ19*0.09) -> 119.085 | AX19: =AU19+AV19 -> 1214.985 | AZ19: jhonatanhernadezgomez@gmail.com | BB19: =+IF(RIGHT(F19,2)="N3",300,0) -> 300 | BC19: =+BB19/30*SUM(V19:Z19) -> 200 | BD19: =+R19*(S19+T19) -> 0 | BE19: =+S19*30 -> 0 | BG19: 530.73762 | BH19: =+BG19-AS19 -> 50 | BI19: =+BC19+AX19+BD19+BE19+BF19-BH19 -> 1364.985 | BJ19: =AJ19+AW19+AV19+BC19+BD19+BE19+BF19 -> 2470.2517 | BK19: =+BJ19/(V19+S19) -> 137.2362 | BL19: =+BK19-30 -> 107.2362
A20: 10 | B20: PENDIENTE | C20: 43070165 | D20: CURO PAZ FELIPE | E20: 45784 | I20: BCP | J20: 57098472871099 | L20: 46204 | M20: 46143 | N20: 46173 | O20: =+TEXT(M20,"mmmm")&" - "&YEAR(M20)&MONTH(M20) -> Mayo - 20265 | P20: SI | R20: 90 | S20: =+COUNTIFS('[1]BD Asistencia'!$E:$E,"A",'[1]BD Asistencia'!$C:$C,'Planilla Mensual'!$D20,'[1]BD Asistencia'!$D:$D,"<"&'Planilla Mensual'!L20) -> 25 | T20: =+COUNTIFS('[1]BD Asistencia'!$E:$E,"DR",'[1]BD Asistencia'!$C:$C,'Planilla Mensual'!$D20,'[1]BD Asistencia'!$D:$D,"<"&L20) -> 6 | U20: =+COUNTIFS('[1]BD Asistencia'!$H:$H,"NO REMUNERADO",'[1]BD Asistencia'!$C:$C,'Planilla Mensual'!$D20,'[1]BD Asistencia'!$D:$D,"<"&L20) -> #VALUE! | V20: =+COUNTIFS('[1]BD Asistencia'!$E:$E,"A",'[1]BD Asistencia'!$C:$C,'Planilla Mensual'!$D20,'[1]BD Asistencia'!$D:$D,">="&'Planilla Mensual'!M20,'[1]BD Asistencia'!$D:$D,"<="&'Planilla Mensual'!N20)-S20 -> 0 | W20: =+COUNTIFS('[1]BD Asistencia'!$E:$E,"V",'[1]BD Asistencia'!$C:$C,'Planilla Mensual'!$D20,'[1]BD Asistencia'!$D:$D,">="&'Planilla Mensual'!M20,'[1]BD Asistencia'!$D:$D,"<="&'Planilla Mensual'!N20) -> 0 | X20: =+COUNTIFS('[1]BD Asistencia'!$E:$E,"DR",'[1]BD Asistencia'!$C:$C,'Planilla Mensual'!$D20,'[1]BD Asistencia'!$D:$D,">="&'Planilla Mensual'!M20,'[1]BD Asistencia'!$D:$D,"<="&'Planilla Mensual'!N20)-T20 -> 0 | Y20: =+COUNTIFS('[1]BD Asistencia'!$E:$E,"h",'[1]BD Asistencia'!$C:$C,'Planilla Mensual'!$D20,'[1]BD Asistencia'!$D:$D,">="&'Planilla Mensual'!M20,'[1]BD Asistencia'!$D:$D,"<="&'Planilla Mensual'!N20) -> 0 | Z20: =+COUNTIFS('[1]BD Asistencia'!$E:$E,"h/A",'[1]BD Asistencia'!$C:$C,'Planilla Mensual'!$D20,'[1]BD Asistencia'!$D:$D,">="&'Planilla Mensual'!M20,'[1]BD Asistencia'!$D:$D,"<="&'Planilla Mensual'!N20) -> 0 | AA20: =+COUNTIFS('[1]BD Asistencia'!$H:$H,"NO REMUNERADO",'[1]BD Asistencia'!$C:$C,'Planilla Mensual'!$D20,'[1]BD Asistencia'!$D:$D,">="&'Planilla Mensual'!M20,'[1]BD Asistencia'!$D:$D,"<="&'Planilla Mensual'!N20)-U20 -> #VALUE! | AB20: =+COUNTIFS('[1]BD Asistencia'!$E:$E,"F",'[1]BD Asistencia'!$C:$C,'Planilla Mensual'!$D20,'[1]BD Asistencia'!$D:$D,">="&'Planilla Mensual'!M20,'[1]BD Asistencia'!$D:$D,"<="&'Planilla Mensual'!N20) -> 0 | AC20: =+SUM(S20:AB20) -> #VALUE! | AT20: =+SUM(AM20:AS20) -> 0 | AU20: =AJ20-SUM(AM20:AS20) -> 0 | AV20: =AK20+AL20 -> 0 | AX20: =AU20+AV20 -> 0 | BD20: =+R20*(S20+T20) -> 2790 | BF20: =+AD20*A20 -> 0 | BG20: 1350 | BH20: =+BG20-AS20 -> 1350 | BI20: =+BC20+AX20+BD20+BE20+BF20-BH20 -> 1440 | BJ20: =AJ20+AW20+AV20+BC20+BD20+BE20+BF20 -> 2790
